Workbook

Sheet Cover
B2: Power generation technology assumptions
C9: Developed to serve as input to the Central_2018 scenario
D36: Prepared by JRC C.6
D42: 43763.865
B46: © European Union 2017-2019
B48: Legal Notice
B50: The information made available is property of the Joint Research Centre of the European Commission.
B51: Neither the European Commission nor any person acting on behalf of the Commission is responsible for the use which might be made of this information.
B53: Permission to Use
B54: Reproduction of the data is authorized provided the source is appropriately acknowledged.

Sheet tech_base
A1: Type | B1: Technology | C1: Co-generation | D1: Size | E1: Typical unit size of a new power plant (kW) | F1: Technical lifetime (years) | G1: Construction time | H1: Technical availability (%) | I1: Net efficiency | J1: Default emissions factor (t of CO2 / toe input) | K1: CCS factor (t of CO2 / toe input) | L1: Default steam to electricity ratio for CHP units | M1: Own consumption | N1: Capital costs €2010/kW | O1: Fix O&M costs €2010/kW | P1: Variable O&M costs €2010/MWh | Q1: Desired range of operation | T1: Available for investment
A2: Nuclear power plants | B2: Nuclear - current | C2: Electricity only | D2: L | E2: 1250000 | F2: 50 | G2: 9 | H2: 0.92 | I2: 0.33333333 | J2: 0 | K2: 0 | L2: 0 | M2: 0.044 | N2: 4900 | O2: 98 | P2: 8.042204 | Q2: 6500 | R2: 8500 | S2: 8760 | T2: 2010
A3: =A2 -> Nuclear power plants | B3: =B2 -> Nuclear - current | C3: =C2 -> Electricity only | D3: M | E3: 600000 | F3: 50 | G3: 9 | H3: 0.92 | I3: 0.33333333 | J3: 0 | K3: 0 | L3: 0 | M3: 0.066 | N3: 5145 | O3: 102.9 | P3: 8.4443142 | Q3: 4875 | R3: 7820.726 | S3: 8270.2066 | T3: 2010
A4: =A3 -> Nuclear power plants | B4: Nuclear III | C4: Electricity only | D4: L | E4: 1250000 | F4: 60 | G4: 9 | H4: 0.94 | I4: 0.38473626 | J4: 0 | K4: 0 | L4: 0 | M4: 0.04048 | N4: 6923.9588 | O4: 121.16928 | P4: 6.0878888 | Q4: 6000 | R4: 8600 | S4: 8760 | T4: 2010
A5: =A4 -> Nuclear power plants | B5: =B4 -> Nuclear III | C5: =C4 -> Electricity only | D5: M | E5: 600000 | F5: 60 | G5: 9 | H5: 0.94 | I5: 0.38475374 | J5: 0 | K5: 0 | L5: 0 | M5: 0.0594 | N5: 7263.9512 | O5: 127.11915 | P5: 6.3868269 | Q5: 4200 | R5: 7614.605 | S5: 8156.8733 | T5: 2010
A6: =A5 -> Nuclear power plants | B6: =B5 -> Nuclear III | C6: =C5 -> Electricity only | D6: S | E6: 300000 | F6: 60 | G6: 9 | H6: 0.94 | I6: 0.38483712 | J6: 0 | K6: 0 | L6: 0 | M6: 0.060588 | N6: 7964.7537 | O6: 139.38319 | P6: 7.0030074 | Q6: 2730 | R6: 6472.5077 | S6: 7483.528 | T6: 2025
A7: =A6 -> Nuclear power plants | B7: Nuclear IV | C7: Electricity only | D7: L | E7: 1250000 | F7: 60 | G7: 9 | H7: 0.95 | I7: 0.40816327 | J7: 0 | K7: 0 | L7: 0 | M7: 0.038456 | N7: 9626.8095 | O7: 144.40214 | P7: 5.642913 | Q7: 5750 | R7: 8600 | S7: 8760 | T7: 2035
A8: =A7 -> Nuclear power plants | B8: =B7 -> Nuclear IV | C8: =C7 -> Electricity only | D8: M | E8: 600000 | F8: 60 | G8: 9 | H8: 0.95 | I8: 0.40816327 | J8: 0 | K8: 0 | L8: 0 | M8: 0.05643 | N8: 10108.15 | O8: 151.62225 | P8: 5.9250586 | Q8: 4168.75 | R8: 7718.5718 | S8: 8214.3217 | T8: 2035
A9: Coal fired power plants | B9: Integrated gasification combined cycle | C9: Electricity only | D9: L | E9: 480000 | F9: 35 | G9: 3 | H9: 0.9 | I9: 0.48781523 | J9: 3.9607128 | K9: 0 | L9: 0 | M9: 0.06 | N9: 2479.8245 | O9: 56.681704 | P9: 4.9837371 | Q9: 6700 | R9: 8380 | S9: 8760 | T9: 2010
A10: =A9 -> Coal fired power plants | B10: =B9 -> Integrated gasification combined cycle | C10: =C9 -> Electricity only | D10: M | E10: 275000 | F10: 35 | G10: 3 | H10: 0.9 | I10: 0.46462172 | J10: 3.9607128 | K10: 0 | L10: 0 | M10: 0.063 | N10: 2665.127 | O10: 60.917188 | P10: 5.356142 | Q10: 4556 | R10: 7228.5564 | S10: 8109.7205 | T10: 2010
A11: =A10 -> Coal fired power plants | B11: =B10 -> Integrated gasification combined cycle | C11: CHP | D11: L | E11: 420000 | F11: 35 | G11: 3 | H11: 0.9 | I11: 0.44346777 | J11: 3.9607128 | K11: 0 | L11: 1.32 | M11: 0.066 | N11: 2869.8105 | O11: 63.627798 | P11: 5.7585032 | Q11: 5360 | R11: 7980 | S11: 8760 | T11: 2010
A12: =A11 -> Coal fired power plants | B12: =B11 -> Integrated gasification combined cycle | C12: =C11 -> CHP | D12: M | E12: 250000 | F12: 35 | G12: 3 | H12: 0.9 | I12: 0.42238101 | J12: 3.9607128 | K12: 0 | L12: 1.32 | M12: 0.0693 | N12: 3055.0565 | O12: 67.734966 | P12: 6.1156326 | Q12: 3216 | R12: 6604.2953 | S12: 7909.2328 | T12: 2010
A13: =A12 -> Coal fired power plants | B13: =B12 -> Integrated gasification combined cycle | C13: Electricity only with CCS | D13: L | E13: 480000 | F13: 35 | G13: 3 | H13: 0.9 | I13: 0.46457607 | J13: 0.39607128 | K13: 3.5646415 | L13: 0 | M13: 0.21 | N13: 3596 | O13: 86.304 | P13: 5.831385 | Q13: 6700 | R13: 8380 | S13: 8760 | T13: 2031
A14: =A13 -> Coal fired power plants | B14: =B13 -> Integrated gasification combined cycle | C14: =C13 -> Electricity only with CCS | D14: M | E14: 275000 | F14: 35 | G14: 3 | H14: 0.9 | I14: 0.4424534 | J14: 0.39607128 | K14: 3.5646415 | L14: 0 | M14: 0.2205 | N14: 3837.8 | O14: 92.1072 | P14: 6.2234954 | Q14: 4556 | R14: 7228.5564 | S14: 8109.7205 | T14: 2031
A15: =A14 -> Coal fired power plants | B15: =B14 -> Integrated gasification combined cycle | C15: CHP with CCS | D15: L | E15: 420000 | F15: 35 | G15: 3 | H15: 0.9 | I15: 0.42234189 | J15: 0.39607128 | K15: 3.5646415 | L15: 1.4267312 | M15: 0.231 | N15: 3986 | O15: 92.79408 | P15: 6.3845957 | Q15: 5360 | R15: 7980 | S15: 8760 | T15: 2031
A16: =A15 -> Coal fired power plants | B16: =B15 -> Integrated gasification combined cycle | C16: =C15 -> CHP with CCS | D16: M | E16: 250000 | F16: 35 | G16: 3 | H16: 0.9 | I16: 0.40223037 | J16: 0.39607128 | K16: 3.5646415 | L16: 1.4333631 | M16: 0.24255 | N16: 4227.8 | O16: 98.423184 | P16: 6.7614394 | Q16: 3216 | R16: 6604.2953 | S16: 7909.2328 | T16: 2031
A17: =A16 -> Coal fired power plants | B17: Supercritical steam turbine | C17: Electricity only | D17: L | E17: 650000 | F17: 40 | G17: 4 | H17: 0.91 | I17: 0.47625327 | J17: 3.9607128 | K17: 0 | L17: 0 | M17: 0.05 | N17: 1744.0798 | O17: 39.241796 | P17: 3.5781239 | Q17: 6550 | R17: 8530 | S17: 8760 | T17: 2010
A18: =A17 -> Coal fired power plants | B18: =B17 -> Supercritical steam turbine | C18: =C17 -> Electricity only | D18: M | E18: 300000 | F18: 40 | G18: 4 | H18: 0.91 | I18: 0.45361376 | J18: 3.9607128 | K18: 0 | L18: 0 | M18: 0.0525 | N18: 1900.3897 | O18: 42.758769 | P18: 3.8988066 | Q18: 4716 | R18: 7509.0721 | S18: 8202.9602 | T18: 2010
A19: =A18 -> Coal fired power plants | B19: =B18 -> Supercritical steam turbine | C19: CHP | D19: L | E19: 550000 | F19: 40 | G19: 4 | H19: 0.91 | I19: 0.43294991 | J19: 3.9607128 | K19: 0 | L19: 0.98 | M19: 0.055 | N19: 2159.0128 | O19: 47.120455 | P19: 4.497524 | Q19: 5240 | R19: 8115 | S19: 8760 | T19: 2010
A20: =A19 -> Coal fired power plants | B20: =B19 -> Supercritical steam turbine | C20: =C19 -> CHP | D20: M | E20: 275000 | F20: 40 | G20: 4 | H20: 0.91 | I20: 0.41236714 | J20: 3.9607128 | K20: 0 | L20: 0.98 | M20: 0.05775 | N20: 2315.2298 | O20: 50.529889 | P20: 4.803703 | Q20: 3799 | R20: 7186.7545 | S20: 8214.3217 | T20: 2010
A21: =A20 -> Coal fired power plants | B21: =B20 -> Supercritical steam turbine | C21: Electricity only with CCS | D21: L | E21: 650000 | F21: 40 | G21: 4 | H21: 0.91 | I21: 0.45351474 | J21: 0.39607128 | K21: 3.5646415 | L21: 0 | M21: 0.2125 | N21: 3141 | O21: 74.206125 | P21: 7.0705232 | Q21: 6550 | R21: 8530 | S21: 8760 | T21: 2031
A22: =A21 -> Coal fired power plants | B22: =B21 -> Supercritical steam turbine | C22: =C21 -> Electricity only with CCS | D22: M | E22: 300000 | F22: 40 | G22: 4 | H22: 0.91 | I22: 0.4319188 | J22: 0.39607128 | K22: 3.5646415 | L22: 0 | M22: 0.223125 | N22: 3367.85 | O22: 79.565456 | P22: 7.581172 | Q22: 4716 | R22: 7509.0721 | S22: 8202.9602 | T22: 2031
A23: =A22 -> Coal fired power plants | B23: =B22 -> Supercritical steam turbine | C23: CHP with CCS | D23: L | E23: 550000 | F23: 40 | G23: 4 | H23: 0.91 | I23: 0.41228613 | J23: 0.39607128 | K23: 3.5646415 | L23: 1.0657384 | M23: 0.23375 | N23: 3556 | O23: 81.490185 | P23: 7.948469 | Q23: 5240 | R23: 8115 | S23: 8760 | T23: 2031
A24: =A23 -> Coal fired power plants | B24: =B23 -> Supercritical steam turbine | C24: =C23 -> CHP with CCS | D24: M | E24: 275000 | F24: 40 | G24: 4 | H24: 0.91 | I24: 0.39265345 | J24: 0.39607128 | K24: 3.5646415 | L24: 1.0710616 | M24: 0.2454375 | N24: 3782.85 | O24: 86.688736 | P24: 8.4388642 | Q24: 3799 | R24: 7186.7545 | S24: 8214.3217 | T24: 2031
A25: =A24 -> Coal fired power plants | B25: Fluidized bed combustion | C25: Electricity only | D25: L | E25: 560000 | F25: 40 | G25: 4 | H25: 0.88 | I25: 0.42557613 | J25: 3.9607128 | K25: 0 | L25: 0 | M25: 0.047 | N25: 1814.3715 | O25: 36.287431 | P25: 3.2700321 | Q25: 6000 | R25: 7800 | S25: 8350 | T25: 2010
A26: =A25 -> Coal fired power plants | B26: =B25 -> Fluidized bed combustion | C26: =C25 -> Electricity only | D26: M | E26: 260000 | F26: 40 | G26: 4 | H26: 0.88 | I26: 0.40534692 | J26: 3.9607128 | K26: 0 | L26: 0 | M26: 0.04935 | N26: 1968.0051 | O26: 39.360103 | P26: 3.5469251 | Q26: 4290 | R26: 6868.1625 | S26: 7808.1417 | T26: 2010
A27: =A26 -> Coal fired power plants | B27: =B26 -> Fluidized bed combustion | C27: =C26 -> Electricity only | D27: S | E27: 35000 | F27: 40 | G27: 3 | H27: 0.88 | I27: 0.38612565 | J27: 3.9607128 | K27: 0 | L27: 0 | M27: 0.0518175 | N27: 2232.1251 | O27: 44.642503 | P27: 4.0229472 | Q27: 2895.75 | R27: 5950.3206 | S27: 7217.8597 | T27: 2010
A28: =A27 -> Coal fired power plants | B28: =B27 -> Fluidized bed combustion | C28: CHP | D28: L | E28: 450000 | F28: 40 | G28: 4 | H28: 0.88 | I28: 0.38686052 | J28: 3.9607128 | K28: 0 | L28: 1.4 | M28: 0.0517 | N28: 2162.7518 | O28: 41.957384 | P28: 3.9205059 | Q28: 4800 | R28: 7437.5 | S28: 8350 | T28: 2010
A29: =A28 -> Coal fired power plants | B29: =B28 -> Fluidized bed combustion | C29: =C28 -> CHP | D29: M | E29: 225000 | F29: 40 | G29: 4 | H29: 0.88 | I29: 0.36845296 | J29: 3.9607128 | K29: 0 | L29: 1.4 | M29: 0.054285 | N29: 2316.7077 | O29: 44.944129 | P29: 4.1862919 | Q29: 3432 | R29: 6571.7534 | S29: 7808.1417 | T29: 2010
A30: =A29 -> Coal fired power plants | B30: =B29 -> Fluidized bed combustion | C30: =C29 -> CHP | D30: S | E30: 15000 | F30: 40 | G30: 3 | H30: 0.88 | I30: 0.35094326 | J30: 3.9607128 | K30: 0 | L30: 1.65 | M30: 0.05699925 | N30: 2628.5924 | O30: 50.994693 | P30: 4.7498768 | Q30: 2316.6 | R30: 5716.1816 | S30: 7217.8597 | T30: 2010
A31: =A30 -> Coal fired power plants | B31: =B30 -> Fluidized bed combustion | C31: Electricity only with CCS | D31: L | E31: 560000 | F31: 40 | G31: 4 | H31: 0.88 | I31: 0.40526849 | J31: 0.39607128 | K31: 3.5646415 | L31: 0 | M31: 0.22325 | N31: 3766.125 | O31: 79.088625 | P31: 7.6081131 | Q31: 6000 | R31: 7800 | S31: 8350 | T31: 2031
A32: =A31 -> Coal fired power plants | B32: =B31 -> Fluidized bed combustion | C32: =C31 -> Electricity only with CCS | D32: M | E32: 260000 | F32: 40 | G32: 4 | H32: 0.88 | I32: 0.38596999 | J32: 0.39607128 | K32: 3.5646415 | L32: 0 | M32: 0.2344125 | N32: 4211.6813 | O32: 88.445306 | P32: 8.5082007 | Q32: 4290 | R32: 6868.1625 | S32: 7808.1417 | T32: 2031
A33: =A32 -> Coal fired power plants | B33: =B32 -> Fluidized bed combustion | C33: CHP with CCS | D33: L | E33: 450000 | F33: 40 | G33: 4 | H33: 0.88 | I33: 0.3684259 | J33: 0.39607128 | K33: 3.5646415 | L33: 1.534122 | M33: 0.245575 | N33: 4114.125 | O33: 83.804726 | P33: 8.1793741 | Q33: 4800 | R33: 7437.5 | S33: 8350 | T33: 2031
A34: =A33 -> Coal fired power plants | B34: =B33 -> Fluidized bed combustion | C34: =C33 -> CHP with CCS | D34: M | E34: 225000 | F34: 40 | G34: 4 | H34: 0.88 | I34: 0.35088181 | J34: 0.39607128 | K34: 3.5646415 | L34: 1.5425397 | M34: 0.25785375 | N34: 4559.6813 | O34: 92.880707 | P34: 9.044845 | Q34: 3432 | R34: 6571.7534 | S34: 7808.1417 | T34: 2031
A35: =A34 -> Coal fired power plants | B35: Steam turbine | C35: Electricity only | D35: L | E35: 500000 | F35: 40 | G35: 4 | H35: 0.92 | I35: 0.44523198 | J35: 3.9607128 | K35: 0 | L35: 0 | M35: 0.058 | N35: 1498.2034 | O35: 24.345805 | P35: 2.1954915 | Q35: 5750 | R35: 7200 | S35: 8100 | T35: 2010
A36: =A35 -> Coal fired power plants | B36: =B35 -> Steam turbine | C36: =C35 -> Electricity only | D36: M | E36: 230000 | F36: 40 | G36: 4 | H36: 0.92 | I36: 0.42388087 | J36: 3.9607128 | K36: 0 | L36: 0 | M36: 0.0609 | N36: 1615.2077 | O36: 26.247126 | P36: 2.3669516 | Q36: 4600 | R36: 6628.5001 | S36: 7746.4552 | T36: 2010
A37: =A36 -> Coal fired power plants | B37: =B36 -> Steam turbine | C37: =C36 -> Electricity only | D37: S | E37: 65000 | F37: 40 | G37: 3 | H37: 0.92 | I37: 0.40355341 | J37: 3.9607128 | K37: 0 | L37: 0 | M37: 0.063945 | N37: 1781.6532 | O37: 28.951864 | P37: 2.6108634 | Q37: 3450 | R37: 5975.1349 | S37: 7313.3317 | T37: 2010
A38: =A37 -> Coal fired power plants | B38: =B37 -> Steam turbine | C38: =C37 -> Electricity only | D38: XS | E38: 4500 | F38: 40 | G38: 1 | H38: 0.92 | I38: 0.38426361 | J38: 3.9607128 | K38: 0 | L38: 0 | M38: 0.06714225 | N38: 2135.9549 | O38: 34.709267 | P38: 3.1300629 | Q38: 2932.5 | R38: 5642.786 | S38: 7079.4424 | T38: 2010
A39: =A38 -> Coal fired power plants | B39: =B38 -> Steam turbine | C39: CHP | D39: L | E39: 450000 | F39: 40 | G39: 4 | H39: 0.92 | I39: 0.40448435 | J39: 3.9607128 | K39: 0 | L39: 0.92 | M39: 0.0638 | N39: 1885.3236 | O39: 29.717413 | P39: 2.8192283 | Q39: 5175 | R39: 6885 | S39: 8100 | T39: 2010
A40: =A39 -> Coal fired power plants | B40: =B39 -> Steam turbine | C40: =C39 -> CHP | D40: M | E40: 210000 | F40: 40 | G40: 4 | H40: 0.92 | I40: 0.38508351 | J40: 3.9607128 | K40: 0 | L40: 0.92 | M40: 0.06699 | N40: 2001.1458 | O40: 31.54306 | P40: 2.9808301 | Q40: 4140 | R40: 6352.9728 | S40: 7746.4552 | T40: 2010
...

Sheet tech_proj
A1: Type: | B1: Technology: | C1: Co-generation: | D1: Size:
A6: =$I$7 -> Pump storage / Pump storage / Electricity only / M | J6: =J$125 -> 2010 | K6: =K$125 -> 2011 | L6: =L$125 -> 2012 | M6: =M$125 -> 2013 | N6: =N$125 -> 2014 | O6: =O$125 -> 2015 | P6: =P$125 -> 2016 | Q6: =Q$125 -> 2017 | ... AX6: =AX$125 -> 2050
A7: =$J$124 -> Efficiency | I7: =INDEX(F$126:F$397,$D$54)&" / "&INDEX(G$126:G$397,$D$54)&" / "&INDEX(H$126:H$397,$D$54)&" / "&INDEX(I$126:I$397,$D$54) -> Pump storage / Pump storage / Electricity only / M | J7: =IF(LEN(INDEX(J$126:J$397,$D$54))<=0,NA(),INDEX(J$126:J$397,$D$54)) -> 0.75 | K7: =IF(LEN(INDEX(K$126:K$397,$D$54))<=0,NA(),INDEX(K$126:K$397,$D$54)) -> 0.7500012 | L7: =IF(LEN(INDEX(L$126:L$397,$D$54))<=0,NA(),INDEX(L$126:L$397,$D$54)) -> 0.75000253 | M7: =IF(LEN(INDEX(M$126:M$397,$D$54))<=0,NA(),INDEX(M$126:M$397,$D$54)) -> 0.750004 | N7: =IF(LEN(INDEX(N$126:N$397,$D$54))<=0,NA(),INDEX(N$126:N$397,$D$54)) -> 0.75000562 | O7: =IF(LEN(INDEX(O$126:O$397,$D$54))<=0,NA(),INDEX(O$126:O$397,$D$54)) -> 0.75000741 | P7: =IF(LEN(INDEX(P$126:P$397,$D$54))<=0,NA(),INDEX(P$126:P$397,$D$54)) -> 0.75000939 | Q7: =IF(LEN(INDEX(Q$126:Q$397,$D$54))<=0,NA(),INDEX(Q$126:Q$397,$D$54)) -> 0.75001158 | ... AX7: =IF(LEN(INDEX(AX$126:AX$397,$D$54))<=0,NA(),INDEX(AX$126:AX$397,$D$54)) -> 0.75059041
A8: =$J$964 -> Capital costs €2010/kW gross | I8: =INDEX(F$966:F$1237,$D$54)&" / "&INDEX(G$966:G$1237,$D$54)&" / "&INDEX(H$966:H$1237,$D$54)&" / "&INDEX(I$966:I$1237,$D$54) -> Pump storage / Pump storage / Electricity only / M | J8: =IF(LEN(INDEX(J$966:J$1237,$D$54))<=0,NA(),INDEX(J$966:J$1237,$D$54)) -> 3851.4937 | K8: =IF(LEN(INDEX(K$966:K$1237,$D$54))<=0,NA(),INDEX(K$966:K$1237,$D$54)) -> 3851.4629 | L8: =IF(LEN(INDEX(L$966:L$1237,$D$54))<=0,NA(),INDEX(L$966:L$1237,$D$54)) -> 3851.4288 | M8: =IF(LEN(INDEX(M$966:M$1237,$D$54))<=0,NA(),INDEX(M$966:M$1237,$D$54)) -> 3851.3911 | N8: =IF(LEN(INDEX(N$966:N$1237,$D$54))<=0,NA(),INDEX(N$966:N$1237,$D$54)) -> 3851.3495 | O8: =IF(LEN(INDEX(O$966:O$1237,$D$54))<=0,NA(),INDEX(O$966:O$1237,$D$54)) -> 3851.3035 | P8: =IF(LEN(INDEX(P$966:P$1237,$D$54))<=0,NA(),INDEX(P$966:P$1237,$D$54)) -> 3851.2526 | Q8: =IF(LEN(INDEX(Q$966:Q$1237,$D$54))<=0,NA(),INDEX(Q$966:Q$1237,$D$54)) -> 3851.1965 | ... AX8: =IF(LEN(INDEX(AX$966:AX$1237,$D$54))<=0,NA(),INDEX(AX$966:AX$1237,$D$54)) -> 3836.3697
A9: =$J$1244 -> Fix O&M costs €2010/kW gross | I9: =INDEX(F$1246:F$1517,$D$54)&" / "&INDEX(G$1246:G$1517,$D$54)&" / "&INDEX(H$1246:H$1517,$D$54)&" / "&INDEX(I$1246:I$1517,$D$54) -> Pump storage / Pump storage / Electricity only / M | J9: =IF(LEN(INDEX(J$1246:J$1517,$D$54))<=0,NA(),INDEX(J$1246:J$1517,$D$54)) -> 38.514937 | K9: =IF(LEN(INDEX(K$1246:K$1517,$D$54))<=0,NA(),INDEX(K$1246:K$1517,$D$54)) -> 38.514629 | L9: =IF(LEN(INDEX(L$1246:L$1517,$D$54))<=0,NA(),INDEX(L$1246:L$1517,$D$54)) -> 38.514288 | M9: =IF(LEN(INDEX(M$1246:M$1517,$D$54))<=0,NA(),INDEX(M$1246:M$1517,$D$54)) -> 38.513911 | N9: =IF(LEN(INDEX(N$1246:N$1517,$D$54))<=0,NA(),INDEX(N$1246:N$1517,$D$54)) -> 38.513495 | O9: =IF(LEN(INDEX(O$1246:O$1517,$D$54))<=0,NA(),INDEX(O$1246:O$1517,$D$54)) -> 38.513035 | P9: =IF(LEN(INDEX(P$1246:P$1517,$D$54))<=0,NA(),INDEX(P$1246:P$1517,$D$54)) -> 38.512526 | Q9: =IF(LEN(INDEX(Q$1246:Q$1517,$D$54))<=0,NA(),INDEX(Q$1246:Q$1517,$D$54)) -> 38.511965 | ... AX9: =IF(LEN(INDEX(AX$1246:AX$1517,$D$54))<=0,NA(),INDEX(AX$1246:AX$1517,$D$54)) -> 38.363697
A10: =$J$1524 -> Variable O&M costs €2010/MWh gross | I10: =INDEX(F$1526:F$1797,$D$54)&" / "&INDEX(G$1526:G$1797,$D$54)&" / "&INDEX(H$1526:H$1797,$D$54)&" / "&INDEX(I$1526:I$1797,$D$54) -> Pump storage / Pump storage / Electricity only / M | J10: =IF(LEN(INDEX(J$1526:J$1797,$D$54))<=0,NA(),INDEX(J$1526:J$1797,$D$54)) -> 0.98157239 | K10: =IF(LEN(INDEX(K$1526:K$1797,$D$54))<=0,NA(),INDEX(K$1526:K$1797,$D$54)) -> 0.98156453 | L10: =IF(LEN(INDEX(L$1526:L$1797,$D$54))<=0,NA(),INDEX(L$1526:L$1797,$D$54)) -> 0.98155584 | M10: =IF(LEN(INDEX(M$1526:M$1797,$D$54))<=0,NA(),INDEX(M$1526:M$1797,$D$54)) -> 0.98154623 | N10: =IF(LEN(INDEX(N$1526:N$1797,$D$54))<=0,NA(),INDEX(N$1526:N$1797,$D$54)) -> 0.98153562 | O10: =IF(LEN(INDEX(O$1526:O$1797,$D$54))<=0,NA(),INDEX(O$1526:O$1797,$D$54)) -> 0.9815239 | P10: =IF(LEN(INDEX(P$1526:P$1797,$D$54))<=0,NA(),INDEX(P$1526:P$1797,$D$54)) -> 0.98151094 | Q10: =IF(LEN(INDEX(Q$1526:Q$1797,$D$54))<=0,NA(),INDEX(Q$1526:Q$1797,$D$54)) -> 0.98149663 | ... AX10: =IF(LEN(INDEX(AX$1526:AX$1797,$D$54))<=0,NA(),INDEX(AX$1526:AX$1797,$D$54)) -> 0.97771796
A12: =$J$124 -> Efficiency | J12: =J$125 -> 2010 | K12: =K$125 -> 2011 | L12: =L$125 -> 2012 | M12: =M$125 -> 2013 | N12: =N$125 -> 2014 | O12: =O$125 -> 2015 | P12: =P$125 -> 2016 | Q12: =Q$125 -> 2017 | ... AX12: =AX$125 -> 2050
A13: =INDEX(F$126:F$397,$D$55) -> Pump storage | B13: =INDEX(G$126:G$397,$D$55) -> Pump storage | C13: =INDEX(H$126:H$397,$D$55) -> Electricity only | D13: =INDEX(I$126:I$397,$D$55) -> L | I13: =A13&" / "&B13&" / "&C13&" / "&D13 -> Pump storage / Pump storage / Electricity only / L | J13: =INDEX(J$126:J$397,$D$55) -> 0.77 | K13: =INDEX(K$126:K$397,$D$55) -> 0.77000217 | L13: =INDEX(L$126:L$397,$D$55) -> 0.77000446 | M13: =INDEX(M$126:M$397,$D$55) -> 0.77000686 | N13: =INDEX(N$126:N$397,$D$55) -> 0.77000938 | O13: =INDEX(O$126:O$397,$D$55) -> 0.77001204 | P13: =INDEX(P$126:P$397,$D$55) -> 0.77001482 | Q13: =INDEX(Q$126:Q$397,$D$55) -> 0.77001775 | ... AX13: =INDEX(AX$126:AX$397,$D$55) -> 0.7702666
A14: =INDEX(F$126:F$397,$D$56) -> Pump storage | B14: =INDEX(G$126:G$397,$D$56) -> Pump storage | C14: =INDEX(H$126:H$397,$D$56) -> Electricity only | D14: =INDEX(I$126:I$397,$D$56) -> M | I14: =A14&" / "&B14&" / "&C14&" / "&D14 -> Pump storage / Pump storage / Electricity only / M | J14: =INDEX(J$126:J$397,$D$56) -> 0.75 | K14: =INDEX(K$126:K$397,$D$56) -> 0.7500012 | L14: =INDEX(L$126:L$397,$D$56) -> 0.75000253 | M14: =INDEX(M$126:M$397,$D$56) -> 0.750004 | N14: =INDEX(N$126:N$397,$D$56) -> 0.75000562 | O14: =INDEX(O$126:O$397,$D$56) -> 0.75000741 | P14: =INDEX(P$126:P$397,$D$56) -> 0.75000939 | Q14: =INDEX(Q$126:Q$397,$D$56) -> 0.75001158 | ... AX14: =INDEX(AX$126:AX$397,$D$56) -> 0.75059041
A15: =INDEX(F$126:F$397,$D$57) -> Pump storage | B15: =INDEX(G$126:G$397,$D$57) -> Pump storage | C15: =INDEX(H$126:H$397,$D$57) -> Electricity only | D15: =INDEX(I$126:I$397,$D$57) -> S | I15: =A15&" / "&B15&" / "&C15&" / "&D15 -> Pump storage / Pump storage / Electricity only / S | J15: =INDEX(J$126:J$397,$D$57) -> 0.71 | K15: =INDEX(K$126:K$397,$D$57) -> 0.71000036 | L15: =INDEX(L$126:L$397,$D$57) -> 0.71000078 | M15: =INDEX(M$126:M$397,$D$57) -> 0.71000127 | N15: =INDEX(N$126:N$397,$D$57) -> 0.71000184 | O15: =INDEX(O$126:O$397,$D$57) -> 0.7100025 | P15: =INDEX(P$126:P$397,$D$57) -> 0.71000327 | Q15: =INDEX(Q$126:Q$397,$D$57) -> 0.71000416 | ... AX15: =INDEX(AX$126:AX$397,$D$57) -> 0.71085296
A16: =INDEX(F$126:F$397,$D$58) -> Pump storage | B16: =INDEX(G$126:G$397,$D$58) -> Pump storage | C16: =INDEX(H$126:H$397,$D$58) -> Electricity only | D16: =INDEX(I$126:I$397,$D$58) -> XS | I16: =A16&" / "&B16&" / "&C16&" / "&D16 -> Pump storage / Pump storage / Electricity only / XS | J16: =INDEX(J$126:J$397,$D$58) -> 0.68 | K16: =INDEX(K$126:K$397,$D$58) -> 0.68000009 | L16: =INDEX(L$126:L$397,$D$58) -> 0.68000019 | M16: =INDEX(M$126:M$397,$D$58) -> 0.68000033 | N16: =INDEX(N$126:N$397,$D$58) -> 0.68000048 | O16: =INDEX(O$126:O$397,$D$58) -> 0.68000068 | P16: =INDEX(P$126:P$397,$D$58) -> 0.68000092 | Q16: =INDEX(Q$126:Q$397,$D$58) -> 0.68000121 | ... AX16: =INDEX(AX$126:AX$397,$D$58) -> 0.68109289
I17: min | J17: =MIN(J13:J16) -> 0.68 | K17: =MIN(K13:K16) -> 0.68000009 | L17: =MIN(L13:L16) -> 0.68000019 | M17: =MIN(M13:M16) -> 0.68000033 | N17: =MIN(N13:N16) -> 0.68000048 | O17: =MIN(O13:O16) -> 0.68000068 | P17: =MIN(P13:P16) -> 0.68000092 | Q17: =MIN(Q13:Q16) -> 0.68000121 | ... AX17: =MIN(AX13:AX16) -> 0.68109289
I18: max | J18: =MAX(J13:J16) -> 0.77 | K18: =MAX(K13:K16) -> 0.77000217 | L18: =MAX(L13:L16) -> 0.77000446 | M18: =MAX(M13:M16) -> 0.77000686 | N18: =MAX(N13:N16) -> 0.77000938 | O18: =MAX(O13:O16) -> 0.77001204 | P18: =MAX(P13:P16) -> 0.77001482 | Q18: =MAX(Q13:Q16) -> 0.77001775 | ... AX18: =MAX(AX13:AX16) -> 0.7702666
I19: diff | J19: =J18-J17 -> 0.09 | K19: =K18-K17 -> 0.090002087 | L19: =L18-L17 -> 0.090004265 | M19: =M18-M17 -> 0.090006536 | N19: =N18-N17 -> 0.0900089 | O19: =O18-O17 -> 0.090011358 | P19: =P18-P17 -> 0.090013907 | Q19: =Q18-Q17 -> 0.090016546 | ... AX19: =AX18-AX17 -> 0.089173715
A20: =$J$964 -> Capital costs €2010/kW gross | J20: =J$965 -> 2010 | K20: =K$965 -> 2011 | L20: =L$965 -> 2012 | M20: =M$965 -> 2013 | N20: =N$965 -> 2014 | O20: =O$965 -> 2015 | P20: =P$965 -> 2016 | Q20: =Q$965 -> 2017 | ... AX20: =AX$965 -> 2050
A21: =INDEX(F$966:F$1237,$D$55) -> Pump storage | B21: =INDEX(G$966:G$1237,$D$55) -> Pump storage | C21: =INDEX(H$966:H$1237,$D$55) -> Electricity only | D21: =INDEX(I$966:I$1237,$D$55) -> L | I21: =A21&" / "&B21&" / "&C21&" / "&D21 -> Pump storage / Pump storage / Electricity only / L | J21: =INDEX(J$966:J$1237,$D$55) -> 3349.125 | K21: =INDEX(K$966:K$1237,$D$55) -> 3349.0777 | L21: =INDEX(L$966:L$1237,$D$55) -> 3349.028 | M21: =INDEX(M$966:M$1237,$D$55) -> 3348.9758 | N21: =INDEX(N$966:N$1237,$D$55) -> 3348.9209 | O21: =INDEX(O$966:O$1237,$D$55) -> 3348.8632 | P21: =INDEX(P$966:P$1237,$D$55) -> 3348.8026 | Q21: =INDEX(Q$966:Q$1237,$D$55) -> 3348.7389 | ... AX21: =INDEX(AX$966:AX$1237,$D$55) -> 3343.3331
A22: =INDEX(F$966:F$1237,$D$56) -> Pump storage | B22: =INDEX(G$966:G$1237,$D$56) -> Pump storage | C22: =INDEX(H$966:H$1237,$D$56) -> Electricity only | D22: =INDEX(I$966:I$1237,$D$56) -> M | I22: =A22&" / "&B22&" / "&C22&" / "&D22 -> Pump storage / Pump storage / Electricity only / M | J22: =INDEX(J$966:J$1237,$D$56) -> 3851.4937 | K22: =INDEX(K$966:K$1237,$D$56) -> 3851.4629 | L22: =INDEX(L$966:L$1237,$D$56) -> 3851.4288 | M22: =INDEX(M$966:M$1237,$D$56) -> 3851.3911 | N22: =INDEX(N$966:N$1237,$D$56) -> 3851.3495 | O22: =INDEX(O$966:O$1237,$D$56) -> 3851.3035 | P22: =INDEX(P$966:P$1237,$D$56) -> 3851.2526 | Q22: =INDEX(Q$966:Q$1237,$D$56) -> 3851.1965 | ... AX22: =INDEX(AX$966:AX$1237,$D$56) -> 3836.3697
A23: =INDEX(F$966:F$1237,$D$57) -> Pump storage | B23: =INDEX(G$966:G$1237,$D$57) -> Pump storage | C23: =INDEX(H$966:H$1237,$D$57) -> Electricity only | D23: =INDEX(I$966:I$1237,$D$57) -> S | I23: =A23&" / "&B23&" / "&C23&" / "&D23 -> Pump storage / Pump storage / Electricity only / S | J23: =INDEX(J$966:J$1237,$D$57) -> 4814.3672 | K23: =INDEX(K$966:K$1237,$D$57) -> 4814.3549 | L23: =INDEX(L$966:L$1237,$D$57) -> 4814.3406 | M23: =INDEX(M$966:M$1237,$D$57) -> 4814.324 | N23: =INDEX(N$966:N$1237,$D$57) -> 4814.3047 | O23: =INDEX(O$966:O$1237,$D$57) -> 4814.2823 | P23: =INDEX(P$966:P$1237,$D$57) -> 4814.2563 | Q23: =INDEX(Q$966:Q$1237,$D$57) -> 4814.226 | ... AX23: =INDEX(AX$966:AX$1237,$D$57) -> 4785.5525
A24: =INDEX(F$966:F$1237,$D$58) -> Pump storage | B24: =INDEX(G$966:G$1237,$D$58) -> Pump storage | C24: =INDEX(H$966:H$1237,$D$58) -> Electricity only | D24: =INDEX(I$966:I$1237,$D$58) -> XS | I24: =A24&" / "&B24&" / "&C24&" / "&D24 -> Pump storage / Pump storage / Electricity only / XS | J24: =INDEX(J$966:J$1237,$D$58) -> 6499.3957 | K24: =INDEX(K$966:K$1237,$D$58) -> 6499.3915 | L24: =INDEX(L$966:L$1237,$D$58) -> 6499.3864 | M24: =INDEX(M$966:M$1237,$D$58) -> 6499.3802 | N24: =INDEX(N$966:N$1237,$D$58) -> 6499.3725 | O24: =INDEX(O$966:O$1237,$D$58) -> 6499.3632 | P24: =INDEX(P$966:P$1237,$D$58) -> 6499.3519 | Q24: =INDEX(Q$966:Q$1237,$D$58) -> 6499.338 | ... AX24: =INDEX(AX$966:AX$1237,$D$58) -> 6447.4179
I25: min | J25: =MIN(J21:J24) -> 3349.125 | K25: =MIN(K21:K24) -> 3349.0777 | L25: =MIN(L21:L24) -> 3349.028 | M25: =MIN(M21:M24) -> 3348.9758 | N25: =MIN(N21:N24) -> 3348.9209 | O25: =MIN(O21:O24) -> 3348.8632 | P25: =MIN(P21:P24) -> 3348.8026 | Q25: =MIN(Q21:Q24) -> 3348.7389 | ... AX25: =MIN(AX21:AX24) -> 3343.3331
I26: max | J26: =MAX(J21:J24) -> 6499.3957 | K26: =MAX(K21:K24) -> 6499.3915 | L26: =MAX(L21:L24) -> 6499.3864 | M26: =MAX(M21:M24) -> 6499.3802 | N26: =MAX(N21:N24) -> 6499.3725 | O26: =MAX(O21:O24) -> 6499.3632 | P26: =MAX(P21:P24) -> 6499.3519 | Q26: =MAX(Q21:Q24) -> 6499.338 | ... AX26: =MAX(AX21:AX24) -> 6447.4179
I27: diff | J27: =J26-J25 -> 3150.2707 | K27: =K26-K25 -> 3150.3138 | L27: =L26-L25 -> 3150.3584 | M27: =M26-M25 -> 3150.4044 | N27: =N26-N25 -> 3150.4516 | O27: =O26-O25 -> 3150.5 | P27: =P26-P25 -> 3150.5492 | Q27: =Q26-Q25 -> 3150.5991 | ... AX27: =AX26-AX25 -> 3104.0848
A28: =$J$1244 -> Fix O&M costs €2010/kW gross | J28: =J$1245 -> 2010 | K28: =K$1245 -> 2011 | L28: =L$1245 -> 2012 | M28: =M$1245 -> 2013 | N28: =N$1245 -> 2014 | O28: =O$1245 -> 2015 | P28: =P$1245 -> 2016 | Q28: =Q$1245 -> 2017 | ... AX28: =AX$1245 -> 2050
A29: =INDEX(F$1246:F$1517,$D$55) -> Pump storage | B29: =INDEX(G$1246:G$1517,$D$55) -> Pump storage | C29: =INDEX(H$1246:H$1517,$D$55) -> Electricity only | D29: =INDEX(I$1246:I$1517,$D$55) -> L | I29: =A29&" / "&B29&" / "&C29&" / "&D29 -> Pump storage / Pump storage / Electricity only / L | J29: =INDEX(J$1246:J$1517,$D$55) -> 33.49125 | K29: =INDEX(K$1246:K$1517,$D$55) -> 33.490777 | L29: =INDEX(L$1246:L$1517,$D$55) -> 33.49028 | M29: =INDEX(M$1246:M$1517,$D$55) -> 33.489758 | N29: =INDEX(N$1246:N$1517,$D$55) -> 33.489209 | O29: =INDEX(O$1246:O$1517,$D$55) -> 33.488632 | P29: =INDEX(P$1246:P$1517,$D$55) -> 33.488026 | Q29: =INDEX(Q$1246:Q$1517,$D$55) -> 33.487389 | ... AX29: =INDEX(AX$1246:AX$1517,$D$55) -> 33.433331
A30: =INDEX(F$1246:F$1517,$D$56) -> Pump storage | B30: =INDEX(G$1246:G$1517,$D$56) -> Pump storage | C30: =INDEX(H$1246:H$1517,$D$56) -> Electricity only | D30: =INDEX(I$1246:I$1517,$D$56) -> M | I30: =A30&" / "&B30&" / "&C30&" / "&D30 -> Pump storage / Pump storage / Electricity only / M | J30: =INDEX(J$1246:J$1517,$D$56) -> 38.514937 | K30: =INDEX(K$1246:K$1517,$D$56) -> 38.514629 | L30: =INDEX(L$1246:L$1517,$D$56) -> 38.514288 | M30: =INDEX(M$1246:M$1517,$D$56) -> 38.513911 | N30: =INDEX(N$1246:N$1517,$D$56) -> 38.513495 | O30: =INDEX(O$1246:O$1517,$D$56) -> 38.513035 | P30: =INDEX(P$1246:P$1517,$D$56) -> 38.512526 | Q30: =INDEX(Q$1246:Q$1517,$D$56) -> 38.511965 | ... AX30: =INDEX(AX$1246:AX$1517,$D$56) -> 38.363697
A31: =INDEX(F$1246:F$1517,$D$57) -> Pump storage | B31: =INDEX(G$1246:G$1517,$D$57) -> Pump storage | C31: =INDEX(H$1246:H$1517,$D$57) -> Electricity only | D31: =INDEX(I$1246:I$1517,$D$57) -> S | I31: =A31&" / "&B31&" / "&C31&" / "&D31 -> Pump storage / Pump storage / Electricity only / S | J31: =INDEX(J$1246:J$1517,$D$57) -> 48.143672 | K31: =INDEX(K$1246:K$1517,$D$57) -> 48.143549 | L31: =INDEX(L$1246:L$1517,$D$57) -> 48.143406 | M31: =INDEX(M$1246:M$1517,$D$57) -> 48.14324 | N31: =INDEX(N$1246:N$1517,$D$57) -> 48.143047 | O31: =INDEX(O$1246:O$1517,$D$57) -> 48.142823 | P31: =INDEX(P$1246:P$1517,$D$57) -> 48.142563 | Q31: =INDEX(Q$1246:Q$1517,$D$57) -> 48.14226 | ... AX31: =INDEX(AX$1246:AX$1517,$D$57) -> 47.855525
A32: =INDEX(F$1246:F$1517,$D$58) -> Pump storage | B32: =INDEX(G$1246:G$1517,$D$58) -> Pump storage | C32: =INDEX(H$1246:H$1517,$D$58) -> Electricity only | D32: =INDEX(I$1246:I$1517,$D$58) -> XS | I32: =A32&" / "&B32&" / "&C32&" / "&D32 -> Pump storage / Pump storage / Electricity only / XS | J32: =INDEX(J$1246:J$1517,$D$58) -> 64.993957 | K32: =INDEX(K$1246:K$1517,$D$58) -> 64.993915 | L32: =INDEX(L$1246:L$1517,$D$58) -> 64.993864 | M32: =INDEX(M$1246:M$1517,$D$58) -> 64.993802 | N32: =INDEX(N$1246:N$1517,$D$58) -> 64.993725 | O32: =INDEX(O$1246:O$1517,$D$58) -> 64.993632 | P32: =INDEX(P$1246:P$1517,$D$58) -> 64.993519 | Q32: =INDEX(Q$1246:Q$1517,$D$58) -> 64.99338 | ... AX32: =INDEX(AX$1246:AX$1517,$D$58) -> 64.474179
I33: min | J33: =MIN(J29:J32) -> 33.49125 | K33: =MIN(K29:K32) -> 33.490777 | L33: =MIN(L29:L32) -> 33.49028 | M33: =MIN(M29:M32) -> 33.489758 | N33: =MIN(N29:N32) -> 33.489209 | O33: =MIN(O29:O32) -> 33.488632 | P33: =MIN(P29:P32) -> 33.488026 | Q33: =MIN(Q29:Q32) -> 33.487389 | ... AX33: =MIN(AX29:AX32) -> 33.433331
I34: max | J34: =MAX(J29:J32) -> 64.993957 | K34: =MAX(K29:K32) -> 64.993915 | L34: =MAX(L29:L32) -> 64.993864 | M34: =MAX(M29:M32) -> 64.993802 | N34: =MAX(N29:N32) -> 64.993725 | O34: =MAX(O29:O32) -> 64.993632 | P34: =MAX(P29:P32) -> 64.993519 | Q34: =MAX(Q29:Q32) -> 64.99338 | ... AX34: =MAX(AX29:AX32) -> 64.474179
I35: diff | J35: =J34-J33 -> 31.502707 | K35: =K34-K33 -> 31.503138 | L35: =L34-L33 -> 31.503584 | M35: =M34-M33 -> 31.504044 | N35: =N34-N33 -> 31.504516 | O35: =O34-O33 -> 31.505 | P35: =P34-P33 -> 31.505492 | Q35: =Q34-Q33 -> 31.505991 | ... AX35: =AX34-AX33 -> 31.040848
A36: =$J$1524 -> Variable O&M costs €2010/MWh gross | J36: =J$1525 -> 2010 | K36: =K$1525 -> 2011 | L36: =L$1525 -> 2012 | M36: =M$1525 -> 2013 | N36: =N$1525 -> 2014 | O36: =O$1525 -> 2015 | P36: =P$1525 -> 2016 | Q36: =Q$1525 -> 2017 | ... AX36: =AX$1525 -> 2050
A37: =INDEX(F$1526:F$1797,$D$55) -> Pump storage | B37: =INDEX(G$1526:G$1797,$D$55) -> Pump storage | C37: =INDEX(H$1526:H$1797,$D$55) -> Electricity only | D37: =INDEX(I$1526:I$1797,$D$55) -> L | I37: =A37&" / "&B37&" / "&C37&" / "&D37 -> Pump storage / Pump storage / Electricity only / L | J37: =INDEX(J$1526:J$1797,$D$55) -> 0.98157239 | K37: =INDEX(K$1526:K$1797,$D$55) -> 0.98155853 | L37: =INDEX(L$1526:L$1797,$D$55) -> 0.98154397 | M37: =INDEX(M$1526:M$1797,$D$55) -> 0.98152866 | N37: =INDEX(N$1526:N$1797,$D$55) -> 0.98151258 | O37: =INDEX(O$1526:O$1797,$D$55) -> 0.98149567 | P37: =INDEX(P$1526:P$1797,$D$55) -> 0.98147791 | Q37: =INDEX(Q$1526:Q$1797,$D$55) -> 0.98145924 | ... AX37: =INDEX(AX$1526:AX$1797,$D$55) -> 0.97987488
A38: =INDEX(F$1526:F$1797,$D$56) -> Pump storage | B38: =INDEX(G$1526:G$1797,$D$56) -> Pump storage | C38: =INDEX(H$1526:H$1797,$D$56) -> Electricity only | D38: =INDEX(I$1526:I$1797,$D$56) -> M | I38: =A38&" / "&B38&" / "&C38&" / "&D38 -> Pump storage / Pump storage / Electricity only / M | J38: =INDEX(J$1526:J$1797,$D$56) -> 0.98157239 | K38: =INDEX(K$1526:K$1797,$D$56) -> 0.98156453 | L38: =INDEX(L$1526:L$1797,$D$56) -> 0.98155584 | M38: =INDEX(M$1526:M$1797,$D$56) -> 0.98154623 | N38: =INDEX(N$1526:N$1797,$D$56) -> 0.98153562 | O38: =INDEX(O$1526:O$1797,$D$56) -> 0.9815239 | P38: =INDEX(P$1526:P$1797,$D$56) -> 0.98151094 | Q38: =INDEX(Q$1526:Q$1797,$D$56) -> 0.98149663 | ... AX38: =INDEX(AX$1526:AX$1797,$D$56) -> 0.97771796
A39: =INDEX(F$1526:F$1797,$D$57) -> Pump storage | B39: =INDEX(G$1526:G$1797,$D$57) -> Pump storage | C39: =INDEX(H$1526:H$1797,$D$57) -> Electricity only | D39: =INDEX(I$1526:I$1797,$D$57) -> S | I39: =A39&" / "&B39&" / "&C39&" / "&D39 -> Pump storage / Pump storage / Electricity only / S | J39: =INDEX(J$1526:J$1797,$D$57) -> 0.98157239 | K39: =INDEX(K$1526:K$1797,$D$57) -> 0.98156988 | L39: =INDEX(L$1526:L$1797,$D$57) -> 0.98156697 | M39: =INDEX(M$1526:M$1797,$D$57) -> 0.98156358 | N39: =INDEX(N$1526:N$1797,$D$57) -> 0.98155965 | O39: =INDEX(O$1526:O$1797,$D$57) -> 0.98155508 | P39: =INDEX(P$1526:P$1797,$D$57) -> 0.98154977 | Q39: =INDEX(Q$1526:Q$1797,$D$57) -> 0.98154361 | ... AX39: =INDEX(AX$1526:AX$1797,$D$57) -> 0.97569753
A40: =INDEX(F$1526:F$1797,$D$58) -> Pump storage | B40: =INDEX(G$1526:G$1797,$D$58) -> Pump storage | C40: =INDEX(H$1526:H$1797,$D$58) -> Electricity only | D40: =INDEX(I$1526:I$1797,$D$58) -> XS | I40: =A40&" / "&B40&" / "&C40&" / "&D40 -> Pump storage / Pump storage / Electricity only / XS | J40: =INDEX(J$1526:J$1797,$D$58) -> 0.98157239 | K40: =INDEX(K$1526:K$1797,$D$58) -> 0.98157176 | L40: =INDEX(L$1526:L$1797,$D$58) -> 0.98157099 | M40: =INDEX(M$1526:M$1797,$D$58) -> 0.98157005 | N40: =INDEX(N$1526:N$1797,$D$58) -> 0.98156889 | O40: =INDEX(O$1526:O$1797,$D$58) -> 0.98156749 | P40: =INDEX(P$1526:P$1797,$D$58) -> 0.98156577 | Q40: =INDEX(Q$1526:Q$1797,$D$58) -> 0.98156367 | ... AX40: =INDEX(AX$1526:AX$1797,$D$58) -> 0.97372244
I41: min | J41: =MIN(J37:J40) -> 0.98157239 | K41: =MIN(K37:K40) -> 0.98155853 | L41: =MIN(L37:L40) -> 0.98154397 | M41: =MIN(M37:M40) -> 0.98152866 | N41: =MIN(N37:N40) -> 0.98151258 | O41: =MIN(O37:O40) -> 0.98149567 | P41: =MIN(P37:P40) -> 0.98147791 | Q41: =MIN(Q37:Q40) -> 0.98145924 | ... AX41: =MIN(AX37:AX40) -> 0.97372244
I42: max | J42: =MAX(J37:J40) -> 0.98157239 | K42: =MAX(K37:K40) -> 0.98157176 | L42: =MAX(L37:L40) -> 0.98157099 | M42: =MAX(M37:M40) -> 0.98157005 | N42: =MAX(N37:N40) -> 0.98156889 | O42: =MAX(O37:O40) -> 0.98156749 | P42: =MAX(P37:P40) -> 0.98156577 | Q42: =MAX(Q37:Q40) -> 0.98156367 | ... AX42: =MAX(AX37:AX40) -> 0.97987488
I43: diff | J43: =J42-J41 -> 0 | K43: =K42-K41 -> 1.3225797e-05 | L43: =L42-L41 -> 2.7018044e-05 | M43: =M42-M41 -> 4.1381553e-05 | N43: =N42-N41 -> 5.6316077e-05 | O43: =O42-O41 -> 7.1814873e-05 | P43: =P42-P41 -> 8.7862945e-05 | Q43: =Q42-Q41 -> 0.00010443488 | ... AX43: =AX42-AX41 -> 0.0061524452
A44: min
A45: range of values (different sizes)
...

Sheet tech_cost
A1: Plant type for comparison (left): | B1: Technology: | C1: Co-generation: | D1: Size: | T1: Parameters to calculate levelized costs
T3: Discount rate (%): | AD3: Annual operating hours: | AN3: CO2 price (€2010 / t CO2):
A5: Plant type for comparison (right): | B5: Technology: | C5: Co-generation: | D5: Size:
T6: manual (discount rate): | AN6: manual (CO2 price):
T7: 0.072 | AN7: 88
A10: =I11 -> Wind power plants / Onshore / Electricity only / L | J10: =J$625 -> 2010 | K10: =K$625 -> 2011 | L10: =L$625 -> 2012 | M10: =M$625 -> 2013 | N10: =N$625 -> 2014 | O10: =O$625 -> 2015 | P10: =P$625 -> 2016 | Q10: =Q$625 -> 2017 | ... AX10: =AX$625 -> 2050
A11: =$J$344 -> Levelized costs (€2010 / MWh net) | H11: =A11&CHAR(13)&I11 -> Levelized costs (€2010 / MWh net)_x000D_Wind power plants / Onshore / Electricity only / L | I11: =INDEX(F$346:F$617,$D$119)&" / "&INDEX(G$346:G$617,$D$119)&" / "&INDEX(H$346:H$617,$D$119)&" / "&INDEX(I$346:I$617,$D$119) -> Wind power plants / Onshore / Electricity only / L | J11: =IF(LEN(INDEX(J$346:J$617,$D$119))<=0,NA(),INDEX(J$346:J$617,$D$119)) -> 36.793908 | K11: =IF(LEN(INDEX(K$346:K$617,$D$119))<=0,NA(),INDEX(K$346:K$617,$D$119)) -> 35.005996 | L11: =IF(LEN(INDEX(L$346:L$617,$D$119))<=0,NA(),INDEX(L$346:L$617,$D$119)) -> 33.832679 | M11: =IF(LEN(INDEX(M$346:M$617,$D$119))<=0,NA(),INDEX(M$346:M$617,$D$119)) -> 33.078404 | N11: =IF(LEN(INDEX(N$346:N$617,$D$119))<=0,NA(),INDEX(N$346:N$617,$D$119)) -> 32.64737 | O11: =IF(LEN(INDEX(O$346:O$617,$D$119))<=0,NA(),INDEX(O$346:O$617,$D$119)) -> 32.324129 | P11: =IF(LEN(INDEX(P$346:P$617,$D$119))<=0,NA(),INDEX(P$346:P$617,$D$119)) -> 31.803541 | Q11: =IF(LEN(INDEX(Q$346:Q$617,$D$119))<=0,NA(),INDEX(Q$346:Q$617,$D$119)) -> 31.461905 | ... AX11: =IF(LEN(INDEX(AX$346:AX$617,$D$119))<=0,NA(),INDEX(AX$346:AX$617,$D$119)) -> 22.377192
A12: =$J$624 -> Fixed annual levelized costs | I12: =INDEX(F$626:F$897,$D$119)&" / "&INDEX(G$626:G$897,$D$119)&" / "&INDEX(H$626:H$897,$D$119)&" / "&INDEX(I$626:I$897,$D$119) -> Wind power plants / Onshore / Electricity only / L | J12: =IF(LEN(INDEX(J$626:J$897,$D$119))<=0,NA(),INDEX(J$626:J$897,$D$119)) -> 36.224154 | K12: =IF(LEN(INDEX(K$626:K$897,$D$119))<=0,NA(),INDEX(K$626:K$897,$D$119)) -> 34.463928 | L12: =IF(LEN(INDEX(L$626:L$897,$D$119))<=0,NA(),INDEX(L$626:L$897,$D$119)) -> 33.30878 | M12: =IF(LEN(INDEX(M$626:M$897,$D$119))<=0,NA(),INDEX(M$626:M$897,$D$119)) -> 32.566185 | N12: =IF(LEN(INDEX(N$626:N$897,$D$119))<=0,NA(),INDEX(N$626:N$897,$D$119)) -> 32.141826 | O12: =IF(LEN(INDEX(O$626:O$897,$D$119))<=0,NA(),INDEX(O$626:O$897,$D$119)) -> 31.82359 | P12: =IF(LEN(INDEX(P$626:P$897,$D$119))<=0,NA(),INDEX(P$626:P$897,$D$119)) -> 31.311063 | Q12: =IF(LEN(INDEX(Q$626:Q$897,$D$119))<=0,NA(),INDEX(Q$626:Q$897,$D$119)) -> 30.974718 | ... AX12: =IF(LEN(INDEX(AX$626:AX$897,$D$119))<=0,NA(),INDEX(AX$626:AX$897,$D$119)) -> 22.030682
A13: =$J$904 -> Fuel and variable costs | I13: =INDEX(F$906:F$1177,$D$119)&" / "&INDEX(G$906:G$1177,$D$119)&" / "&INDEX(H$906:H$1177,$D$119)&" / "&INDEX(I$906:I$1177,$D$119) -> Wind power plants / Onshore / Electricity only / L | J13: =IF(LEN(INDEX(J$906:J$1177,$D$119))<=0,NA(),INDEX(J$906:J$1177,$D$119)) -> 0.56975381 | K13: =IF(LEN(INDEX(K$906:K$1177,$D$119))<=0,NA(),INDEX(K$906:K$1177,$D$119)) -> 0.542068 | L13: =IF(LEN(INDEX(L$906:L$1177,$D$119))<=0,NA(),INDEX(L$906:L$1177,$D$119)) -> 0.52389918 | M13: =IF(LEN(INDEX(M$906:M$1177,$D$119))<=0,NA(),INDEX(M$906:M$1177,$D$119)) -> 0.51221923 | N13: =IF(LEN(INDEX(N$906:N$1177,$D$119))<=0,NA(),INDEX(N$906:N$1177,$D$119)) -> 0.50554467 | O13: =IF(LEN(INDEX(O$906:O$1177,$D$119))<=0,NA(),INDEX(O$906:O$1177,$D$119)) -> 0.50053927 | P13: =IF(LEN(INDEX(P$906:P$1177,$D$119))<=0,NA(),INDEX(P$906:P$1177,$D$119)) -> 0.49247797 | Q13: =IF(LEN(INDEX(Q$906:Q$1177,$D$119))<=0,NA(),INDEX(Q$906:Q$1177,$D$119)) -> 0.48718773 | ... AX13: =IF(LEN(INDEX(AX$906:AX$1177,$D$119))<=0,NA(),INDEX(AX$906:AX$1177,$D$119)) -> 0.34651092
A14: =$J$1184 -> CO2 emission related costs | I14: =INDEX(F$1186:F$1457,$D$119)&" / "&INDEX(G$1186:G$1457,$D$119)&" / "&INDEX(H$1186:H$1457,$D$119)&" / "&INDEX(I$1186:I$1457,$D$119) -> Wind power plants / Onshore / Electricity only / L | J14: =IF(LEN(INDEX(J$1186:J$1457,$D$119))<=0,NA(),INDEX(J$1186:J$1457,$D$119)) -> 0 | K14: =IF(LEN(INDEX(K$1186:K$1457,$D$119))<=0,NA(),INDEX(K$1186:K$1457,$D$119)) -> 0 | L14: =IF(LEN(INDEX(L$1186:L$1457,$D$119))<=0,NA(),INDEX(L$1186:L$1457,$D$119)) -> 0 | M14: =IF(LEN(INDEX(M$1186:M$1457,$D$119))<=0,NA(),INDEX(M$1186:M$1457,$D$119)) -> 0 | N14: =IF(LEN(INDEX(N$1186:N$1457,$D$119))<=0,NA(),INDEX(N$1186:N$1457,$D$119)) -> 0 | O14: =IF(LEN(INDEX(O$1186:O$1457,$D$119))<=0,NA(),INDEX(O$1186:O$1457,$D$119)) -> 0 | P14: =IF(LEN(INDEX(P$1186:P$1457,$D$119))<=0,NA(),INDEX(P$1186:P$1457,$D$119)) -> 0 | Q14: =IF(LEN(INDEX(Q$1186:Q$1457,$D$119))<=0,NA(),INDEX(Q$1186:Q$1457,$D$119)) -> 0 | ... AX14: =IF(LEN(INDEX(AX$1186:AX$1457,$D$119))<=0,NA(),INDEX(AX$1186:AX$1457,$D$119)) -> 0
A15: Desired operating hours - minimum | H15: ="Operating hours"&CHAR(13)&I15 -> Operating hours_x000D_Wind power plants / Onshore / Electricity only / L | I15: =INDEX(tech_proj!F$1806:F$2077,$D$119)&" / "&INDEX(tech_proj!G$1806:G$2077,$D$119)&" / "&INDEX(tech_proj!H$1806:H$2077,$D$119)&" / "&INDEX(tech_proj!I$1806:I$2077,$D$119) -> Wind power plants / Onshore / Electricity only / L | J15: =IF(LEN(INDEX(tech_proj!J$1806:J$2077,$D$119))<=0,NA(),INDEX(tech_proj!J$1806:J$2077,$D$119)) -> 1400 | K15: =IF(LEN(INDEX(tech_proj!K$1806:K$2077,$D$119))<=0,NA(),INDEX(tech_proj!K$1806:K$2077,$D$119)) -> 1400 | L15: =IF(LEN(INDEX(tech_proj!L$1806:L$2077,$D$119))<=0,NA(),INDEX(tech_proj!L$1806:L$2077,$D$119)) -> 1400 | M15: =IF(LEN(INDEX(tech_proj!M$1806:M$2077,$D$119))<=0,NA(),INDEX(tech_proj!M$1806:M$2077,$D$119)) -> 1400 | N15: =IF(LEN(INDEX(tech_proj!N$1806:N$2077,$D$119))<=0,NA(),INDEX(tech_proj!N$1806:N$2077,$D$119)) -> 1400 | O15: =IF(LEN(INDEX(tech_proj!O$1806:O$2077,$D$119))<=0,NA(),INDEX(tech_proj!O$1806:O$2077,$D$119)) -> 1400 | P15: =IF(LEN(INDEX(tech_proj!P$1806:P$2077,$D$119))<=0,NA(),INDEX(tech_proj!P$1806:P$2077,$D$119)) -> 1400 | Q15: =IF(LEN(INDEX(tech_proj!Q$1806:Q$2077,$D$119))<=0,NA(),INDEX(tech_proj!Q$1806:Q$2077,$D$119)) -> 1400 | ... AX15: =IF(LEN(INDEX(tech_proj!AX$1806:AX$2077,$D$119))<=0,NA(),INDEX(tech_proj!AX$1806:AX$2077,$D$119)) -> 1400
A16: Desired operating hours - maximum | I16: =INDEX(tech_proj!F$2366:F$2637,$D$119)&" / "&INDEX(tech_proj!G$2366:G$2637,$D$119)&" / "&INDEX(tech_proj!H$2366:H$2637,$D$119)&" / "&INDEX(tech_proj!I$2366:I$2637,$D$119) -> Wind power plants / Onshore / Electricity only / L | J16: =IF(LEN(INDEX(tech_proj!J$2366:J$2637,$D$119))<=0,NA(),INDEX(tech_proj!J$2366:J$2637,$D$119)) -> 3750 | K16: =IF(LEN(INDEX(tech_proj!K$2366:K$2637,$D$119))<=0,NA(),INDEX(tech_proj!K$2366:K$2637,$D$119)) -> 3750 | L16: =IF(LEN(INDEX(tech_proj!L$2366:L$2637,$D$119))<=0,NA(),INDEX(tech_proj!L$2366:L$2637,$D$119)) -> 3750 | M16: =IF(LEN(INDEX(tech_proj!M$2366:M$2637,$D$119))<=0,NA(),INDEX(tech_proj!M$2366:M$2637,$D$119)) -> 3750 | N16: =IF(LEN(INDEX(tech_proj!N$2366:N$2637,$D$119))<=0,NA(),INDEX(tech_proj!N$2366:N$2637,$D$119)) -> 3750 | O16: =IF(LEN(INDEX(tech_proj!O$2366:O$2637,$D$119))<=0,NA(),INDEX(tech_proj!O$2366:O$2637,$D$119)) -> 3750 | P16: =IF(LEN(INDEX(tech_proj!P$2366:P$2637,$D$119))<=0,NA(),INDEX(tech_proj!P$2366:P$2637,$D$119)) -> 3750 | Q16: =IF(LEN(INDEX(tech_proj!Q$2366:Q$2637,$D$119))<=0,NA(),INDEX(tech_proj!Q$2366:Q$2637,$D$119)) -> 3750 | ... AX16: =IF(LEN(INDEX(tech_proj!AX$2366:AX$2637,$D$119))<=0,NA(),INDEX(tech_proj!AX$2366:AX$2637,$D$119)) -> 3750
A18: =I19 -> Wind power plants / Onshore / Electricity only / M | J18: =J$625 -> 2010 | K18: =K$625 -> 2011 | L18: =L$625 -> 2012 | M18: =M$625 -> 2013 | N18: =N$625 -> 2014 | O18: =O$625 -> 2015 | P18: =P$625 -> 2016 | Q18: =Q$625 -> 2017 | ... AX18: =AX$625 -> 2050
A19: =$J$344 -> Levelized costs (€2010 / MWh net) | H19: =A19&CHAR(13)&I19 -> Levelized costs (€2010 / MWh net)_x000D_Wind power plants / Onshore / Electricity only / M | I19: =INDEX(F$346:F$617,$D$139)&" / "&INDEX(G$346:G$617,$D$139)&" / "&INDEX(H$346:H$617,$D$139)&" / "&INDEX(I$346:I$617,$D$139) -> Wind power plants / Onshore / Electricity only / M | J19: =IF(LEN(INDEX(J$346:J$617,$D$139))<=0,NA(),INDEX(J$346:J$617,$D$139)) -> 39.949821 | K19: =IF(LEN(INDEX(K$346:K$617,$D$139))<=0,NA(),INDEX(K$346:K$617,$D$139)) -> 38.96766 | L19: =IF(LEN(INDEX(L$346:L$617,$D$139))<=0,NA(),INDEX(L$346:L$617,$D$139)) -> 38.28014 | M19: =IF(LEN(INDEX(M$346:M$617,$D$139))<=0,NA(),INDEX(M$346:M$617,$D$139)) -> 37.779057 | N19: =IF(LEN(INDEX(N$346:N$617,$D$139))<=0,NA(),INDEX(N$346:N$617,$D$139)) -> 37.264124 | O19: =IF(LEN(INDEX(O$346:O$617,$D$139))<=0,NA(),INDEX(O$346:O$617,$D$139)) -> 36.529874 | P19: =IF(LEN(INDEX(P$346:P$617,$D$139))<=0,NA(),INDEX(P$346:P$617,$D$139)) -> 35.85617 | Q19: =IF(LEN(INDEX(Q$346:Q$617,$D$139))<=0,NA(),INDEX(Q$346:Q$617,$D$139)) -> 35.423876 | ... AX19: =IF(LEN(INDEX(AX$346:AX$617,$D$139))<=0,NA(),INDEX(AX$346:AX$617,$D$139)) -> 25.611284
A20: =$J$624 -> Fixed annual levelized costs | I20: =INDEX(F$626:F$897,$D$139)&" / "&INDEX(G$626:G$897,$D$139)&" / "&INDEX(H$626:H$897,$D$139)&" / "&INDEX(I$626:I$897,$D$139) -> Wind power plants / Onshore / Electricity only / M | J20: =IF(LEN(INDEX(J$626:J$897,$D$139))<=0,NA(),INDEX(J$626:J$897,$D$139)) -> 39.354636 | K20: =IF(LEN(INDEX(K$626:K$897,$D$139))<=0,NA(),INDEX(K$626:K$897,$D$139)) -> 38.387108 | L20: =IF(LEN(INDEX(L$626:L$897,$D$139))<=0,NA(),INDEX(L$626:L$897,$D$139)) -> 37.709831 | M20: =IF(LEN(INDEX(M$626:M$897,$D$139))<=0,NA(),INDEX(M$626:M$897,$D$139)) -> 37.216213 | N20: =IF(LEN(INDEX(N$626:N$897,$D$139))<=0,NA(),INDEX(N$626:N$897,$D$139)) -> 36.708952 | O20: =IF(LEN(INDEX(O$626:O$897,$D$139))<=0,NA(),INDEX(O$626:O$897,$D$139)) -> 35.985641 | P20: =IF(LEN(INDEX(P$626:P$897,$D$139))<=0,NA(),INDEX(P$626:P$897,$D$139)) -> 35.321974 | Q20: =IF(LEN(INDEX(Q$626:Q$897,$D$139))<=0,NA(),INDEX(Q$626:Q$897,$D$139)) -> 34.896121 | ... AX20: =IF(LEN(INDEX(AX$626:AX$897,$D$139))<=0,NA(),INDEX(AX$626:AX$897,$D$139)) -> 25.229719
A21: =$J$904 -> Fuel and variable costs | I21: =INDEX(F$906:F$1177,$D$139)&" / "&INDEX(G$906:G$1177,$D$139)&" / "&INDEX(H$906:H$1177,$D$139)&" / "&INDEX(I$906:I$1177,$D$139) -> Wind power plants / Onshore / Electricity only / M | J21: =IF(LEN(INDEX(J$906:J$1177,$D$139))<=0,NA(),INDEX(J$906:J$1177,$D$139)) -> 0.59518442 | K21: =IF(LEN(INDEX(K$906:K$1177,$D$139))<=0,NA(),INDEX(K$906:K$1177,$D$139)) -> 0.5805519 | L21: =IF(LEN(INDEX(L$906:L$1177,$D$139))<=0,NA(),INDEX(L$906:L$1177,$D$139)) -> 0.57030901 | M21: =IF(LEN(INDEX(M$906:M$1177,$D$139))<=0,NA(),INDEX(M$906:M$1177,$D$139)) -> 0.56284373 | N21: =IF(LEN(INDEX(N$906:N$1177,$D$139))<=0,NA(),INDEX(N$906:N$1177,$D$139)) -> 0.55517211 | O21: =IF(LEN(INDEX(O$906:O$1177,$D$139))<=0,NA(),INDEX(O$906:O$1177,$D$139)) -> 0.54423302 | P21: =IF(LEN(INDEX(P$906:P$1177,$D$139))<=0,NA(),INDEX(P$906:P$1177,$D$139)) -> 0.53419598 | Q21: =IF(LEN(INDEX(Q$906:Q$1177,$D$139))<=0,NA(),INDEX(Q$906:Q$1177,$D$139)) -> 0.52775554 | ... AX21: =IF(LEN(INDEX(AX$906:AX$1177,$D$139))<=0,NA(),INDEX(AX$906:AX$1177,$D$139)) -> 0.3815646
A22: =$J$1184 -> CO2 emission related costs | I22: =INDEX(F$1186:F$1457,$D$139)&" / "&INDEX(G$1186:G$1457,$D$139)&" / "&INDEX(H$1186:H$1457,$D$139)&" / "&INDEX(I$1186:I$1457,$D$139) -> Wind power plants / Onshore / Electricity only / M | J22: =IF(LEN(INDEX(J$1186:J$1457,$D$139))<=0,NA(),INDEX(J$1186:J$1457,$D$139)) -> 0 | K22: =IF(LEN(INDEX(K$1186:K$1457,$D$139))<=0,NA(),INDEX(K$1186:K$1457,$D$139)) -> 0 | L22: =IF(LEN(INDEX(L$1186:L$1457,$D$139))<=0,NA(),INDEX(L$1186:L$1457,$D$139)) -> 0 | M22: =IF(LEN(INDEX(M$1186:M$1457,$D$139))<=0,NA(),INDEX(M$1186:M$1457,$D$139)) -> 0 | N22: =IF(LEN(INDEX(N$1186:N$1457,$D$139))<=0,NA(),INDEX(N$1186:N$1457,$D$139)) -> 0 | O22: =IF(LEN(INDEX(O$1186:O$1457,$D$139))<=0,NA(),INDEX(O$1186:O$1457,$D$139)) -> 0 | P22: =IF(LEN(INDEX(P$1186:P$1457,$D$139))<=0,NA(),INDEX(P$1186:P$1457,$D$139)) -> 0 | Q22: =IF(LEN(INDEX(Q$1186:Q$1457,$D$139))<=0,NA(),INDEX(Q$1186:Q$1457,$D$139)) -> 0 | ... AX22: =IF(LEN(INDEX(AX$1186:AX$1457,$D$139))<=0,NA(),INDEX(AX$1186:AX$1457,$D$139)) -> 0
A23: Desired operating hours - minimum | H23: ="Operating hours"&CHAR(13)&I23 -> Operating hours_x000D_Wind power plants / Onshore / Electricity only / M | I23: =INDEX(tech_proj!F$1806:F$2077,$D$139)&" / "&INDEX(tech_proj!G$1806:G$2077,$D$139)&" / "&INDEX(tech_proj!H$1806:H$2077,$D$139)&" / "&INDEX(tech_proj!I$1806:I$2077,$D$139) -> Wind power plants / Onshore / Electricity only / M | J23: =IF(LEN(INDEX(tech_proj!J$1806:J$2077,$D$139))<=0,NA(),INDEX(tech_proj!J$1806:J$2077,$D$139)) -> 1400 | K23: =IF(LEN(INDEX(tech_proj!K$1806:K$2077,$D$139))<=0,NA(),INDEX(tech_proj!K$1806:K$2077,$D$139)) -> 1400 | L23: =IF(LEN(INDEX(tech_proj!L$1806:L$2077,$D$139))<=0,NA(),INDEX(tech_proj!L$1806:L$2077,$D$139)) -> 1400 | M23: =IF(LEN(INDEX(tech_proj!M$1806:M$2077,$D$139))<=0,NA(),INDEX(tech_proj!M$1806:M$2077,$D$139)) -> 1400 | N23: =IF(LEN(INDEX(tech_proj!N$1806:N$2077,$D$139))<=0,NA(),INDEX(tech_proj!N$1806:N$2077,$D$139)) -> 1400 | O23: =IF(LEN(INDEX(tech_proj!O$1806:O$2077,$D$139))<=0,NA(),INDEX(tech_proj!O$1806:O$2077,$D$139)) -> 1400 | P23: =IF(LEN(INDEX(tech_proj!P$1806:P$2077,$D$139))<=0,NA(),INDEX(tech_proj!P$1806:P$2077,$D$139)) -> 1400 | Q23: =IF(LEN(INDEX(tech_proj!Q$1806:Q$2077,$D$139))<=0,NA(),INDEX(tech_proj!Q$1806:Q$2077,$D$139)) -> 1400 | ... AX23: =IF(LEN(INDEX(tech_proj!AX$1806:AX$2077,$D$139))<=0,NA(),INDEX(tech_proj!AX$1806:AX$2077,$D$139)) -> 1400
A24: Desired operating hours - maximum | I24: =INDEX(tech_proj!F$2366:F$2637,$D$139)&" / "&INDEX(tech_proj!G$2366:G$2637,$D$139)&" / "&INDEX(tech_proj!H$2366:H$2637,$D$139)&" / "&INDEX(tech_proj!I$2366:I$2637,$D$139) -> Wind power plants / Onshore / Electricity only / M | J24: =IF(LEN(INDEX(tech_proj!J$2366:J$2637,$D$139))<=0,NA(),INDEX(tech_proj!J$2366:J$2637,$D$139)) -> 3375 | K24: =IF(LEN(INDEX(tech_proj!K$2366:K$2637,$D$139))<=0,NA(),INDEX(tech_proj!K$2366:K$2637,$D$139)) -> 3375 | L24: =IF(LEN(INDEX(tech_proj!L$2366:L$2637,$D$139))<=0,NA(),INDEX(tech_proj!L$2366:L$2637,$D$139)) -> 3375 | M24: =IF(LEN(INDEX(tech_proj!M$2366:M$2637,$D$139))<=0,NA(),INDEX(tech_proj!M$2366:M$2637,$D$139)) -> 3375 | N24: =IF(LEN(INDEX(tech_proj!N$2366:N$2637,$D$139))<=0,NA(),INDEX(tech_proj!N$2366:N$2637,$D$139)) -> 3375 | O24: =IF(LEN(INDEX(tech_proj!O$2366:O$2637,$D$139))<=0,NA(),INDEX(tech_proj!O$2366:O$2637,$D$139)) -> 3375 | P24: =IF(LEN(INDEX(tech_proj!P$2366:P$2637,$D$139))<=0,NA(),INDEX(tech_proj!P$2366:P$2637,$D$139)) -> 3375 | Q24: =IF(LEN(INDEX(tech_proj!Q$2366:Q$2637,$D$139))<=0,NA(),INDEX(tech_proj!Q$2366:Q$2637,$D$139)) -> 3375 | ... AX24: =IF(LEN(INDEX(tech_proj!AX$2366:AX$2637,$D$139))<=0,NA(),INDEX(tech_proj!AX$2366:AX$2637,$D$139)) -> 3375
A26: ="LEFT "&$J$344 -> LEFT Levelized costs (€2010 / MWh net) | J26: =J$345 -> 2010 | K26: =K$345 -> 2011 | L26: =L$345 -> 2012 | M26: =M$345 -> 2013 | N26: =N$345 -> 2014 | O26: =O$345 -> 2015 | P26: =P$345 -> 2016 | Q26: =Q$345 -> 2017 | ... AX26: =AX$345 -> 2050
A27: =INDEX(F$346:F$617,$D$120) -> Wind power plants | B27: =INDEX(G$346:G$617,$D$120) -> Onshore | C27: =INDEX(H$346:H$617,$D$120) -> Electricity only | D27: =INDEX(I$346:I$617,$D$120) -> L | I27: =A27&" / "&B27&" / "&C27&" / "&D27 -> Wind power plants / Onshore / Electricity only / L | J27: =INDEX(J$346:J$617,$D$120) -> 36.793908 | K27: =INDEX(K$346:K$617,$D$120) -> 35.005996 | L27: =INDEX(L$346:L$617,$D$120) -> 33.832679 | M27: =INDEX(M$346:M$617,$D$120) -> 33.078404 | N27: =INDEX(N$346:N$617,$D$120) -> 32.64737 | O27: =INDEX(O$346:O$617,$D$120) -> 32.324129 | P27: =INDEX(P$346:P$617,$D$120) -> 31.803541 | Q27: =INDEX(Q$346:Q$617,$D$120) -> 31.461905 | ... AX27: =INDEX(AX$346:AX$617,$D$120) -> 22.377192
A28: =INDEX(F$346:F$617,$D$121) -> Wind power plants | B28: =INDEX(G$346:G$617,$D$121) -> Onshore | C28: =INDEX(H$346:H$617,$D$121) -> Electricity only | D28: =INDEX(I$346:I$617,$D$121) -> M | I28: =A28&" / "&B28&" / "&C28&" / "&D28 -> Wind power plants / Onshore / Electricity only / M | J28: =INDEX(J$346:J$617,$D$121) -> 39.949821 | K28: =INDEX(K$346:K$617,$D$121) -> 38.96766 | L28: =INDEX(L$346:L$617,$D$121) -> 38.28014 | M28: =INDEX(M$346:M$617,$D$121) -> 37.779057 | N28: =INDEX(N$346:N$617,$D$121) -> 37.264124 | O28: =INDEX(O$346:O$617,$D$121) -> 36.529874 | P28: =INDEX(P$346:P$617,$D$121) -> 35.85617 | Q28: =INDEX(Q$346:Q$617,$D$121) -> 35.423876 | ... AX28: =INDEX(AX$346:AX$617,$D$121) -> 25.611284
A29: =INDEX(F$346:F$617,$D$122) -> Wind power plants | B29: =INDEX(G$346:G$617,$D$122) -> Onshore | C29: =INDEX(H$346:H$617,$D$122) -> Electricity only | D29: =INDEX(I$346:I$617,$D$122) -> S | I29: =A29&" / "&B29&" / "&C29&" / "&D29 -> Wind power plants / Onshore / Electricity only / S | J29: =INDEX(J$346:J$617,$D$122) -> 43.08282 | K29: =INDEX(K$346:K$617,$D$122) -> 42.409645 | L29: =INDEX(L$346:L$617,$D$122) -> 41.989748 | M29: =INDEX(M$346:M$617,$D$122) -> 41.574008 | N29: =INDEX(N$346:N$617,$D$122) -> 41.162384 | O29: =INDEX(O$346:O$617,$D$122) -> 40.754836 | P29: =INDEX(P$346:P$617,$D$122) -> 40.097093 | Q29: =INDEX(Q$346:Q$617,$D$122) -> 39.472238 | ... AX29: =INDEX(AX$346:AX$617,$D$122) -> 28.465507
A30: =INDEX(F$346:F$617,$D$123) -> Wind power plants | B30: =INDEX(G$346:G$617,$D$123) -> Onshore | C30: =INDEX(H$346:H$617,$D$123) -> Electricity only | D30: =INDEX(I$346:I$617,$D$123) -> XS | I30: =A30&" / "&B30&" / "&C30&" / "&D30 -> Wind power plants / Onshore / Electricity only / XS | J30: =INDEX(J$346:J$617,$D$123) -> 51.610007 | K30: =INDEX(K$346:K$617,$D$123) -> 51.132755 | L30: =INDEX(L$346:L$617,$D$123) -> 50.726939 | M30: =INDEX(M$346:M$617,$D$123) -> 50.324344 | N30: =INDEX(N$346:N$617,$D$123) -> 49.924945 | O30: =INDEX(O$346:O$617,$D$123) -> 49.528715 | P30: =INDEX(P$346:P$617,$D$123) -> 49.145397 | Q30: =INDEX(Q$346:Q$617,$D$123) -> 48.658809 | ... AX30: =INDEX(AX$346:AX$617,$D$123) -> 39.020179
I31: min | J31: =MIN(J27:J30) -> 36.793908 | K31: =MIN(K27:K30) -> 35.005996 | L31: =MIN(L27:L30) -> 33.832679 | M31: =MIN(M27:M30) -> 33.078404 | N31: =MIN(N27:N30) -> 32.64737 | O31: =MIN(O27:O30) -> 32.324129 | P31: =MIN(P27:P30) -> 31.803541 | Q31: =MIN(Q27:Q30) -> 31.461905 | ... AX31: =MIN(AX27:AX30) -> 22.377192
I32: max | J32: =MAX(J27:J30) -> 51.610007 | K32: =MAX(K27:K30) -> 51.132755 | L32: =MAX(L27:L30) -> 50.726939 | M32: =MAX(M27:M30) -> 50.324344 | N32: =MAX(N27:N30) -> 49.924945 | O32: =MAX(O27:O30) -> 49.528715 | P32: =MAX(P27:P30) -> 49.145397 | Q32: =MAX(Q27:Q30) -> 48.658809 | ... AX32: =MAX(AX27:AX30) -> 39.020179
I33: diff | J33: =J32-J31 -> 14.816099 | K33: =K32-K31 -> 16.126758 | L33: =L32-L31 -> 16.89426 | M33: =M32-M31 -> 17.24594 | N33: =N32-N31 -> 17.277574 | O33: =O32-O31 -> 17.204586 | P33: =P32-P31 -> 17.341855 | Q33: =Q32-Q31 -> 17.196903 | ... AX33: =AX32-AX31 -> 16.642986
A34: ="LEFT "&$J$624 -> LEFT Fixed annual levelized costs | J34: =J$625 -> 2010 | K34: =K$625 -> 2011 | L34: =L$625 -> 2012 | M34: =M$625 -> 2013 | N34: =N$625 -> 2014 | O34: =O$625 -> 2015 | P34: =P$625 -> 2016 | Q34: =Q$625 -> 2017 | ... AX34: =AX$625 -> 2050
A35: =INDEX(F$626:F$897,$D$120) -> Wind power plants | B35: =INDEX(G$626:G$897,$D$120) -> Onshore | C35: =INDEX(H$626:H$897,$D$120) -> Electricity only | D35: =INDEX(I$626:I$897,$D$120) -> L | I35: =A35&" / "&B35&" / "&C35&" / "&D35 -> Wind power plants / Onshore / Electricity only / L | J35: =INDEX(J$626:J$897,$D$120) -> 36.224154 | K35: =INDEX(K$626:K$897,$D$120) -> 34.463928 | L35: =INDEX(L$626:L$897,$D$120) -> 33.30878 | M35: =INDEX(M$626:M$897,$D$120) -> 32.566185 | N35: =INDEX(N$626:N$897,$D$120) -> 32.141826 | O35: =INDEX(O$626:O$897,$D$120) -> 31.82359 | P35: =INDEX(P$626:P$897,$D$120) -> 31.311063 | Q35: =INDEX(Q$626:Q$897,$D$120) -> 30.974718 | ... AX35: =INDEX(AX$626:AX$897,$D$120) -> 22.030682
A36: =INDEX(F$626:F$897,$D$121) -> Wind power plants | B36: =INDEX(G$626:G$897,$D$121) -> Onshore | C36: =INDEX(H$626:H$897,$D$121) -> Electricity only | D36: =INDEX(I$626:I$897,$D$121) -> M | I36: =A36&" / "&B36&" / "&C36&" / "&D36 -> Wind power plants / Onshore / Electricity only / M | J36: =INDEX(J$626:J$897,$D$121) -> 39.354636 | K36: =INDEX(K$626:K$897,$D$121) -> 38.387108 | L36: =INDEX(L$626:L$897,$D$121) -> 37.709831 | M36: =INDEX(M$626:M$897,$D$121) -> 37.216213 | N36: =INDEX(N$626:N$897,$D$121) -> 36.708952 | O36: =INDEX(O$626:O$897,$D$121) -> 35.985641 | P36: =INDEX(P$626:P$897,$D$121) -> 35.321974 | Q36: =INDEX(Q$626:Q$897,$D$121) -> 34.896121 | ... AX36: =INDEX(AX$626:AX$897,$D$121) -> 25.229719
A37: =INDEX(F$626:F$897,$D$122) -> Wind power plants | B37: =INDEX(G$626:G$897,$D$122) -> Onshore | C37: =INDEX(H$626:H$897,$D$122) -> Electricity only | D37: =INDEX(I$626:I$897,$D$122) -> S | I37: =A37&" / "&B37&" / "&C37&" / "&D37 -> Wind power plants / Onshore / Electricity only / S | J37: =INDEX(J$626:J$897,$D$122) -> 42.485119 | K37: =INDEX(K$626:K$897,$D$122) -> 41.821284 | L37: =INDEX(L$626:L$897,$D$122) -> 41.407211 | M37: =INDEX(M$626:M$897,$D$122) -> 40.997239 | N37: =INDEX(N$626:N$897,$D$122) -> 40.591326 | O37: =INDEX(O$626:O$897,$D$122) -> 40.189431 | P37: =INDEX(P$626:P$897,$D$122) -> 39.540814 | Q37: =INDEX(Q$626:Q$897,$D$122) -> 38.924628 | ... AX37: =INDEX(AX$626:AX$897,$D$122) -> 28.070596
A38: =INDEX(F$626:F$897,$D$123) -> Wind power plants | B38: =INDEX(G$626:G$897,$D$123) -> Onshore | C38: =INDEX(H$626:H$897,$D$123) -> Electricity only | D38: =INDEX(I$626:I$897,$D$123) -> XS | I38: =A38&" / "&B38&" / "&C38&" / "&D38 -> Wind power plants / Onshore / Electricity only / XS | J38: =INDEX(J$626:J$897,$D$123) -> 51.011956 | K38: =INDEX(K$626:K$897,$D$123) -> 50.540234 | L38: =INDEX(L$626:L$897,$D$123) -> 50.139121 | M38: =INDEX(M$626:M$897,$D$123) -> 49.741192 | N38: =INDEX(N$626:N$897,$D$123) -> 49.346421 | O38: =INDEX(O$626:O$897,$D$123) -> 48.954782 | P38: =INDEX(P$626:P$897,$D$123) -> 48.575906 | Q38: =INDEX(Q$626:Q$897,$D$123) -> 48.094956 | ... AX38: =INDEX(AX$626:AX$897,$D$123) -> 38.568018
I39: min | J39: =MIN(J35:J38) -> 36.224154 | K39: =MIN(K35:K38) -> 34.463928 | L39: =MIN(L35:L38) -> 33.30878 | M39: =MIN(M35:M38) -> 32.566185 | N39: =MIN(N35:N38) -> 32.141826 | O39: =MIN(O35:O38) -> 31.82359 | P39: =MIN(P35:P38) -> 31.311063 | Q39: =MIN(Q35:Q38) -> 30.974718 | ... AX39: =MIN(AX35:AX38) -> 22.030682
I40: max | J40: =MAX(J35:J38) -> 51.011956 | K40: =MAX(K35:K38) -> 50.540234 | L40: =MAX(L35:L38) -> 50.139121 | M40: =MAX(M35:M38) -> 49.741192 | N40: =MAX(N35:N38) -> 49.346421 | O40: =MAX(O35:O38) -> 48.954782 | P40: =MAX(P35:P38) -> 48.575906 | Q40: =MAX(Q35:Q38) -> 48.094956 | ... AX40: =MAX(AX35:AX38) -> 38.568018
I41: diff | J41: =J40-J39 -> 14.787803 | K41: =K40-K39 -> 16.076306 | L41: =L40-L39 -> 16.830341 | M41: =M40-M39 -> 17.175007 | N41: =N40-N39 -> 17.204595 | O41: =O40-O39 -> 17.131192 | P41: =P40-P39 -> 17.264842 | Q41: =Q40-Q39 -> 17.120239 | ... AX41: =AX40-AX39 -> 16.537336
A42: ="LEFT "&$J$904 -> LEFT Fuel and variable costs | J42: =J$905 -> 2010 | K42: =K$905 -> 2011 | L42: =L$905 -> 2012 | M42: =M$905 -> 2013 | N42: =N$905 -> 2014 | O42: =O$905 -> 2015 | P42: =P$905 -> 2016 | Q42: =Q$905 -> 2017 | ... AX42: =AX$905 -> 2050
A43: =INDEX(F$906:F$1177,$D$120) -> Wind power plants | B43: =INDEX(G$906:G$1177,$D$120) -> Onshore | C43: =INDEX(H$906:H$1177,$D$120) -> Electricity only | D43: =INDEX(I$906:I$1177,$D$120) -> L | I43: =A43&" / "&B43&" / "&C43&" / "&D43 -> Wind power plants / Onshore / Electricity only / L | J43: =INDEX(J$906:J$1177,$D$120) -> 0.56975381 | K43: =INDEX(K$906:K$1177,$D$120) -> 0.542068 | L43: =INDEX(L$906:L$1177,$D$120) -> 0.52389918 | M43: =INDEX(M$906:M$1177,$D$120) -> 0.51221923 | N43: =INDEX(N$906:N$1177,$D$120) -> 0.50554467 | O43: =INDEX(O$906:O$1177,$D$120) -> 0.50053927 | P43: =INDEX(P$906:P$1177,$D$120) -> 0.49247797 | Q43: =INDEX(Q$906:Q$1177,$D$120) -> 0.48718773 | ... AX43: =INDEX(AX$906:AX$1177,$D$120) -> 0.34651092
A44: =INDEX(F$906:F$1177,$D$121) -> Wind power plants | B44: =INDEX(G$906:G$1177,$D$121) -> Onshore | C44: =INDEX(H$906:H$1177,$D$121) -> Electricity only | D44: =INDEX(I$906:I$1177,$D$121) -> M | I44: =A44&" / "&B44&" / "&C44&" / "&D44 -> Wind power plants / Onshore / Electricity only / M | J44: =INDEX(J$906:J$1177,$D$121) -> 0.59518442 | K44: =INDEX(K$906:K$1177,$D$121) -> 0.5805519 | L44: =INDEX(L$906:L$1177,$D$121) -> 0.57030901 | M44: =INDEX(M$906:M$1177,$D$121) -> 0.56284373 | N44: =INDEX(N$906:N$1177,$D$121) -> 0.55517211 | O44: =INDEX(O$906:O$1177,$D$121) -> 0.54423302 | P44: =INDEX(P$906:P$1177,$D$121) -> 0.53419598 | Q44: =INDEX(Q$906:Q$1177,$D$121) -> 0.52775554 | ... AX44: =INDEX(AX$906:AX$1177,$D$121) -> 0.3815646
