Workbook

Sheet Context
B15: AIDRES - EU industrial plants database (NUTS3)
B17: The AIDRES database (Advancing industrial decarbonization by assessing the future use of renewable energies in industrial processes), is a spatially explicit database covering 2030 and 2050 demands for renewable energy carriers (electricity, gases, liquid fuels and heat) representing future pathways for 6 energy intensive energy industrial sectors (steel, cement, glass, refinery, chemical and fertiliser) in the European Union. This geographical database at the level of plant location and aggregated at NUTS3 granularity combines information on the type of installations, industrial parameters and current, 2030 and 2050 energy and feedstock demands, production rates, GHG emissions and related cost parameters for a mixture of the selected future technology pathways.
B22: Consult key results of the AIDRES project through the Energy and Industry Geographt lab (EIGL - JRC)
B23: [link to EIGL]
B25: Download open access full database (SQL) and reports describing the AIDRES database:
B26: [link to JRC open database catalogue]
B28: Full project report describing AIDRES methodology and results:
B29: [link to DG ENER website]
B31: Rights and licensing
B32: This data is licensed under Creative Commons (https://creativecommons.org/licenses/by/4.0/). This data can be reused under the terms of the CC BY 4.0 licence. You are free to share, copy and redistribute the datasets. You are also free to adapt, remix, transform, and build upon the datasets for any purpose, even commercially. Under the following terms: 1.you must give appropriate credit: AIDRES database, Energyville | VITO, 2023 prepared for the European Commission, DG ENER, under service contract N° ENER/2020/OP/0011/C2/SER/2019-569/SI2.840687 - Following copyright notice: © European Union, 1995-2023 - A link to the material: LINK TO ENER SITE 2.you must indicate if changes were made. 3.you may not apply legal terms or technological measures that legally restrict others from doing anything the license permits.

Sheet Main assumptions

Sheet Glossary
A13: Group | B13: Sheet | C13: Description
A14: Feedstock and energy inputs | B14: Total energy & feedstock inputs | C14: Sum of all individual energy and feedstock parameters
B15: Electricity [PJ/y] | C15: Electricity annual energy consumptionin PJ pear y
B16: Alternative fuel mixture [PJ/y] | C16: Alternative fuel mixture annual energy consumption
B17: Biomass [PJ/y] | C17: Biomass annual energy consumption
B18: Biomass waste [PJ/y] | C18: Biomass waste annual energy consumption
B19: Coal [PJ/y] | C19: Coal annual energy consumption
B20: Coke [PJ/y] | C20: Coke annual energy consumption
B21: Crude oil [PJ/y] | C21: Crude oil annual energy consumption
B22: Hydrogen [PJ/y] | C22: Hydrogen annual energy consumption
B23: Methanol [PJ/y] | C23: Methanol annual energy consumption
B24: Naphtha [PJ/y] | C24: Naphtha annual energy consumption
B25: Natural gas [PJ/y] | C25: Natural gas annual energy consumption
B26: Plastic mix [PJ/y] | C26: Plastic mix annual energy consumption
A29: Product flow
B30: product_flow [kt/y] | C30: Annual production
A32: Emissions
B33: Direct emission [ktCO2/y] | C33: Direct annual CO2 emissions at the plant
B34: Total emission [ktCO2/y] | C34: Direct at the plant and indirect upstream annual CO2 emissions
B35: Captured CO2 [ktCO2/y] | C35: Captured CO2 at the plant annually (production process and fumes)
B36: Direct emission reduction [%] | C36: Direct emission reduction
B37: Total emission reduction [%] | C37: Total emission reduction
A39: Costs
B40: totex [mEUR/y] | C40: Annualized total expenditure (TOTEX)
B41: opex var [mEUR/y] | C41: Annual operation expenditure from the energy consuption
B42: CO2 allowance [mEUR/y] | C42: Annual CO2 allowance
B43: opex cst [mEUR/y] | C43: Annual constant operation expenditure (OPEX)
B44: opex [mEUR/y] | C44: Annual operation expenditure (OPEX)
B45: opex ccs storage [mEUR/y] | C45: Annual carbon storage operation expenditure
B46: opex ccs transport [mEUR/y] | C46: Annual carbon transport operation expenditure
B47: opex ccs [mEUR/y] | C47: Annual carbon transport and storage expenditure
B48: capex [mEUR/y] | C48: Annual capital expenditure (CAPEX)

Sheet Total energy & feedstock inputs
F12: 2018 | M12: 2030 | T12: 2050
A13: NUTS ID | B13: NUTS LEVEL | C13: Country code | D13: NUTS region name (Latin) | E13: NUTS_NAME | F13: All sectors (PJ/y) | G13: Steel (PJ/y) | H13: Cement (PJ/y) | I13: Glass (PJ/y) | J13: Refineries (PJ/y) | K13: Fertilisers (PJ/y) | L13: Chemical (PJ/y) | M13: All sectors (PJ/y) | N13: Steel (PJ/y) | O13: Cement (PJ/y) | P13: Glass (PJ/y) | Q13: Refineries (PJ/y) | R13: Fertilisers (PJ/y) | S13: Chemical (PJ/y) | T13: All sectors (PJ/y) | U13: Steel (PJ/y) | V13: Cement (PJ/y) | W13: Glass (PJ/y) | X13: Refineries (PJ/y) | Y13: Fertilisers (PJ/y) | Z13: Chemical (PJ/y)
A14: AT121 | B14: 3 | C14: AT | D14: Mostviertel-Eisenwurzen | E14: Mostviertel-Eisenwurzen | F14: 1.1221212 | I14: 1.1221212 | M14: 1.118078 | P14: 1.118078 | T14: 1.0934878 | W14: 1.0934878
A15: AT122 | B15: 3 | C15: AT | D15: Niederösterreich-Süd | E15: Niederösterreich-Süd | F15: 1.1777767 | H15: 1.1777767 | M15: 1.2330791 | O15: 1.2330791 | T15: 1.569413 | V15: 1.569413
A16: AT124 | B16: 3 | C16: AT | D16: Waldviertel | E16: Waldviertel | F16: 0.44779015 | L16: 0.44779015 | M16: 0.45016337 | S16: 0.45016337 | T16: 0.45554936 | Z16: 0.45554936
A17: AT127 | B17: 3 | C17: AT | D17: Wiener Umland/Südteil | E17: Wiener Umland/Südteil | F17: 513.74884 | H17: 2.4435252 | J17: 432.47472 | L17: 78.830596 | M17: 457.86021 | O17: 2.5582607 | Q17: 371.68234 | S17: 83.619606 | T17: 233.2226 | V17: 3.2560502 | X17: 135.497 | Z17: 94.469547
A18: AT213 | B18: 3 | C18: AT | D18: Unterkärnten | E18: Unterkärnten | F18: 1.7672346 | H18: 1.7672346 | M18: 1.8502149 | O18: 1.8502149 | T18: 2.3548783 | V18: 2.3548783
A19: AT221 | B19: 3 | C19: AT | D19: Graz | E19: Graz | F19: 0.60668147 | G19: 0.60668147 | M19: 0.60668147 | N19: 0.60668147 | T19: 0.60668147 | U19: 0.60668147
A20: AT223 | B20: 3 | C20: AT | D20: Östliche Obersteiermark | E20: Östliche Obersteiermark | F20: 25.781885 | G20: 25.781885 | M20: 23.102472 | N20: 23.102472 | T20: 19.516591 | U20: 19.516591
A21: AT225 | B21: 3 | C21: AT | D21: West- und Südsteiermark | E21: West- und Südsteiermark | F21: 2.2857082 | H21: 1.311029 | I21: 0.97467924 | M21: 2.3437555 | O21: 1.3725882 | P21: 0.97116729 | T21: 2.6967827 | V21: 1.7469745 | W21: 0.9498082
A22: AT312 | B22: 3 | C22: AT | D22: Linz-Wels | E22: Linz-Wels | F22: 107.53083 | G22: 95.480476 | K22: 11.639763 | L22: 0.41058815 | M22: 97.040076 | N22: 85.240678 | R22: 11.386456 | S22: 0.4129417 | T22: 82.767879 | U22: 71.536676 | Y22: 10.81292 | Z22: 0.41828276
A23: AT314 | B23: 3 | C23: AT | D23: Steyr-Kirchdorf | E23: Steyr-Kirchdorf | F23: 2.1851098 | H23: 0.90765151 | I23: 1.2774583 | M23: 2.2231256 | O23: 0.95027021 | P23: 1.2728554 | T23: 2.4543265 | V23: 1.2094653 | W23: 1.2448612
A24: AT315 | B24: 3 | C24: AT | D24: Traunviertel | E24: Traunviertel | F24: 1.3248425 | H24: 1.3248425 | M24: 1.3870503 | O24: 1.3870503 | T24: 1.7653813 | V24: 1.7653813
A25: AT323 | B25: 3 | C25: AT | D25: Salzburg und Umgebung | E25: Salzburg und Umgebung | F25: 1.2545387 | H25: 1.2545387 | M25: 1.3134455 | O25: 1.3134455 | T25: 1.6717 | V25: 1.6717
A26: AT331 | B26: 3 | C26: AT | D26: Außerfern | E26: Außerfern | F26: 0.86572066 | H26: 0.86572066 | M26: 0.90637049 | O26: 0.90637049 | T26: 1.1535915 | V26: 1.1535915
A27: BE211 | B27: 3 | C27: BE | D27: Arr. Antwerpen | E27: Arr. Antwerpen | F27: 1963.5174 | J27: 1734.3574 | K27: 16.784084 | L27: 212.37594 | M27: 1728.6025 | Q27: 1490.5611 | R27: 16.418827 | S27: 221.62253 | T27: 801.54961 | X27: 543.38489 | Y27: 15.59181 | Z27: 242.57291
A28: BE213 | B28: 3 | C28: BE | D28: Arr. Turnhout | E28: Arr. Turnhout | F28: 15.893854 | I28: 1.0587338 | L28: 14.835121 | M28: 15.971672 | P28: 1.0553694 | S28: 14.916302 | T28: 16.135436 | W28: 1.0348963 | Z28: 15.100539
A29: BE224 | B29: 3 | C29: BE | D29: Arr. Hasselt | E29: Arr. Hasselt | F29: 2.9626429 | G29: 1.8834146 | L29: 1.0792283 | M29: 2.9674864 | N29: 1.8834146 | S29: 1.0840719 | T29: 2.9784802 | U29: 1.8834146 | Z29: 1.0950656
A30: BE233 | B30: 3 | C30: BE | D30: Arr. Eeklo | E30: Arr. Eeklo | F30: 2.7014047 | L30: 2.7014047 | M30: 2.8414003 | S30: 2.8414003 | T30: 3.1585824 | Z30: 3.1585824
A31: BE234 | B31: 3 | C31: BE | D31: Arr. Gent | E31: Arr. Gent | F31: 104.3071 | G31: 103.36118 | L31: 0.945921 | M31: 93.227563 | N31: 92.27622 | S31: 0.95134315 | T31: 78.404773 | U31: 77.441125 | Z31: 0.96364799
A32: BE236 | B32: 3 | C32: BE | D32: Arr. Sint-Niklaas | E32: Arr. Sint-Niklaas | F32: 10.526831 | L32: 10.526831 | M32: 10.586785 | S32: 10.586785 | T32: 10.722844 | Z32: 10.722844
A33: BE255 | B33: 3 | C33: BE | D33: Arr. Oostende | E33: Arr. Oostende | F33: 0.41058815 | L33: 0.41058815 | M33: 0.4129417 | S33: 0.4129417 | T33: 0.41828276 | Z33: 0.41828276
A34: BE323 | B34: 3 | C34: BE | D34: Arr. Mons | E34: Arr. Mons | F34: 15.881779 | H34: 3.6049001 | I34: 1.1834319 | K34: 8.3920422 | L34: 2.7014047 | M34: 16.004149 | O34: 3.7741678 | P34: 1.1791678 | R34: 8.2094134 | S34: 2.8414003 | T34: 16.911329 | V34: 4.8036074 | W34: 1.1532341 | Y34: 7.795905 | Z34: 3.1585824
A35: BE328 | B35: 3 | C35: BE | D35: Arr. Tournai-Mouscron | E35: Arr. Tournai-Mouscron | F35: 6.8621567 | H35: 6.8621567 | M35: 7.1843687 | O35: 7.1843687 | T35: 9.1439724 | V35: 9.1439724
A36: BE32B | B36: 3 | C36: BE | D36: Arr. Charleroi | E36: Arr. Charleroi | F36: 3.4529267 | G36: 3.4529267 | M36: 3.4529267 | N36: 3.4529267 | T36: 3.4529267 | U36: 3.4529267
A37: BE32C | B37: 3 | C37: BE | D37: Arr. Soignies | E37: Arr. Soignies | F37: 4.3110007 | I37: 0.29083642 | L37: 4.0201642 | M37: 4.3329969 | P37: 0.28978848 | S37: 4.0432084 | T37: 4.3789191 | W37: 0.28341511 | Z37: 4.095504
A38: BE32D | B38: 3 | C38: BE | D38: Arr. Thuin | E38: Arr. Thuin | F38: 0.43965186 | I38: 0.43965186 | M38: 0.43806771 | P38: 0.43806771 | T38: 0.42843319 | W38: 0.42843319
A39: BE332 | B39: 3 | C39: BE | D39: Arr. Liège | E39: Arr. Liège | F39: 4.0590791 | H39: 4.0590791 | M39: 4.2496728 | O39: 4.2496728 | T39: 5.4088108 | V39: 5.4088108
A40: BE335 | B40: 3 | C40: BE | D40: Arr. Verviers — communes francophones | E40: Arr. Verviers — communes francophones | F40: 1.4061998 | I40: 1.4061998 | M40: 1.3972033 | P40: 1.3972033 | T40: 1.3426362 | W40: 1.3426362
A41: BE352 | B41: 3 | C41: BE | D41: Arr. Namur | E41: Arr. Namur | F41: 5.6391499 | I41: 4.7478624 | L41: 0.8912875 | M41: 5.6245335 | P41: 4.7327747 | S41: 0.8917588 | T41: 5.533799 | W41: 4.6409637 | Z41: 0.89283524
A42: BG313 | B42: 3 | C42: BG | D42: Vratsa | E42: Враца | F42: 1.6245685 | H42: 1.6245685 | M42: 1.7008499 | O42: 1.7008499 | T42: 2.1647727 | V42: 2.1647727
A43: BG314 | B43: 3 | C43: BG | D43: Pleven | E43: Плевен | F43: 0.73153058 | I43: 0.73153058 | M43: 0.72889474 | P43: 0.72889474 | T43: 0.712864 | W43: 0.712864
A44: BG315 | B44: 3 | C44: BG | D44: Lovech | E44: Ловеч | F44: 1.9623408 | H44: 1.9623408 | M44: 2.0544824 | O44: 2.0544824 | T44: 2.6148616 | V44: 2.6148616
A45: BG331 | B45: 3 | C45: BG | D45: Varna | E45: Варна | F45: 11.361808 | H45: 2.8648654 | K45: 8.4969427 | M45: 11.311416 | O45: 2.9993849 | R45: 8.312031 | T45: 11.710849 | V45: 3.8174952 | Y45: 7.8933538
A46: BG333 | B46: 3 | C46: BG | D46: Shumen | E46: Шумен | F46: 0.44089872 | I46: 0.44089872 | M46: 0.43931008 | P46: 0.43931008 | T46: 0.42964824 | W46: 0.42964824
A47: BG334 | B47: 3 | C47: BG | D47: Targovishte | E47: Търговище | F47: 4.4075012 | I47: 4.4075012 | M47: 4.3931095 | P47: 4.3931095 | T47: 4.3055446 | W47: 4.3055446
A48: BG341 | B48: 3 | C48: BG | D48: Burgas | E48: Бургас | F48: 436.93322 | J48: 436.93322 | M48: 375.51412 | Q48: 375.51412 | T48: 136.89388 | X48: 136.89388
A49: BG411 | B49: 3 | C49: BG | D49: Sofia (stolitsa) | E49: София (столица) | F49: 0.71838978 | I49: 0.71838978 | M49: 0.71580129 | P49: 0.71580129 | T49: 0.70005852 | W49: 0.70005852
A50: BG414 | B50: 3 | C50: BG | D50: Pernik | E50: Перник | F50: 1.3211908 | G50: 1.3211908 | M50: 1.3211908 | N50: 1.3211908 | T50: 1.3211908 | U50: 1.3211908
A51: BG421 | B51: 3 | C51: BG | D51: Plovdiv | E51: Пловдив | F51: 2.2189787 | I51: 2.2189787 | M51: 2.2109833 | P51: 2.2109833 | T51: 2.1623567 | W51: 2.1623567
...

Sheet Electricity (PJ per y)
F12: 2018 | M12: 2030 | T12: 2050
A13: NUTS ID | B13: NUTS LEVEL | C13: Country code | D13: NUTS region name (Latin) | E13: NUTS_NAME | F13: All sectors (PJ/y) | G13: Steel (PJ/y) | H13: Cement (PJ/y) | I13: Glass (PJ/y) | J13: Refineries (PJ/y) | K13: Fertilisers (PJ/y) | L13: Chemical (PJ/y) | M13: All sectors (PJ/y) | N13: Steel (PJ/y) | O13: Cement (PJ/y) | P13: Glass (PJ/y) | Q13: Refineries (PJ/y) | R13: Fertilisers (PJ/y) | S13: Chemical (PJ/y) | T13: All sectors (PJ/y) | U13: Steel (PJ/y) | V13: Cement (PJ/y) | W13: Glass (PJ/y) | X13: Refineries (PJ/y) | Y13: Fertilisers (PJ/y) | Z13: Chemical (PJ/y)
A14: AT121 | B14: 3 | C14: AT | D14: Mostviertel-Eisenwurzen | E14: Mostviertel-Eisenwurzen | F14: 0.20566984 | I14: 0.20566984 | M14: 0.24734312 | P14: 0.24734312 | T14: 0.50079813 | W14: 0.50079813
A15: AT122 | B15: 3 | C15: AT | D15: Niederösterreich-Süd | E15: Niederösterreich-Süd | F15: 0.12979009 | H15: 0.12979009 | M15: 0.14563243 | O15: 0.14563243 | T15: 0.24198074 | V15: 0.24198074
A16: AT124 | B16: 3 | C16: AT | D16: Waldviertel | E16: Waldviertel | F16: 0.079474115 | L16: 0.079474115 | M16: 0.11260432 | S16: 0.11260432 | T16: 0.18766951 | Z16: 0.18766951
A17: AT127 | B17: 3 | C17: AT | D17: Wiener Umland/Südteil | E17: Wiener Umland/Südteil | F17: 2.588142 | H17: 0.26927459 | J17: 0.88812599 | L17: 1.4307414 | M17: 17.810308 | O17: 0.30214259 | Q17: 6.5743016 | S17: 10.933864 | T17: 45.813702 | V17: 0.50203577 | X17: 12.856985 | Z17: 32.454682
A18: AT213 | B18: 3 | C18: AT | D18: Unterkärnten | E18: Unterkärnten | F18: 0.19474789 | H18: 0.19474789 | M18: 0.21851906 | O18: 0.21851906 | T18: 0.36308812 | V18: 0.36308812
A19: AT221 | B19: 3 | C19: AT | D19: Graz | E19: Graz | F19: 0.45838203 | G19: 0.45838203 | M19: 0.45838203 | N19: 0.45838203 | T19: 0.45838203 | U19: 0.45838203
A20: AT223 | B20: 3 | C20: AT | D20: Östliche Obersteiermark | E20: Östliche Obersteiermark | F20: 1.4528744 | G20: 1.4528744 | M20: 1.9546246 | N20: 1.9546246 | T20: 4.0467298 | U20: 4.0467298
A21: AT225 | B21: 3 | C21: AT | D21: West- und Südsteiermark | E21: West- und Südsteiermark | F21: 0.32312008 | H21: 0.14447438 | I21: 0.1786457 | M21: 0.3769524 | O21: 0.16210911 | P21: 0.21484329 | T21: 0.70435355 | V21: 0.26935816 | W21: 0.43499539
A22: AT312 | B22: 3 | C22: AT | D22: Linz-Wels | E22: Linz-Wels | F22: 4.0999599 | G22: 3.2486777 | K22: 0.79502779 | L22: 0.056254407 | M22: 6.1764168 | N22: 5.1661943 | R22: 0.92215271 | S22: 0.088069791 | T22: 14.531823 | U22: 13.161501 | Y22: 1.2101646 | Z22: 0.16015725
A23: AT314 | B23: 3 | C23: AT | D23: Steyr-Kirchdorf | E23: Steyr-Kirchdorf | F23: 0.33416356 | H23: 0.1000225 | I23: 0.23414106 | M23: 0.39381462 | O23: 0.11223137 | P23: 0.28158325 | T23: 0.75660649 | V23: 0.18648203 | W23: 0.57012446
A24: AT315 | B24: 3 | C24: AT | D24: Traunviertel | E24: Traunviertel | F24: 0.14599662 | H24: 0.14599662 | M24: 0.16381715 | O24: 0.16381715 | T24: 0.27219622 | V24: 0.27219622
A25: AT323 | B25: 3 | C25: AT | D25: Salzburg und Umgebung | E25: Salzburg und Umgebung | F25: 0.1382492 | H25: 0.1382492 | M25: 0.15512408 | O25: 0.15512408 | T25: 0.25775193 | V25: 0.25775193
A26: AT331 | B26: 3 | C26: AT | D26: Außerfern | E26: Außerfern | F26: 0.095401749 | H26: 0.095401749 | M26: 0.10704661 | O26: 0.10704661 | T26: 0.1778671 | V26: 0.1778671
A27: BE211 | B27: 3 | C27: BE | D27: Arr. Antwerpen | E27: Arr. Antwerpen | F27: 18.042426 | J27: 3.5616599 | K27: 1.1463991 | L27: 13.334367 | M27: 63.643471 | Q27: 26.364983 | R27: 1.3297083 | S27: 35.94878 | T27: 140.47284 | X27: 51.560485 | Y27: 1.7450103 | Z27: 87.167349
A28: BE213 | B28: 3 | C28: BE | D28: Arr. Turnhout | E28: Arr. Turnhout | F28: 2.5283383 | I28: 0.13486539 | L28: 2.3934729 | M28: 3.6868289 | P28: 0.17504669 | S28: 3.5117822 | T28: 6.4650555 | W28: 0.41943044 | Z28: 6.045625
A29: BE224 | B29: 3 | C29: BE | D29: Arr. Hasselt | E29: Arr. Hasselt | F29: 1.6965983 | G29: 1.4230258 | L29: 0.27357252 | M29: 1.7693494 | N29: 1.4230258 | S29: 0.34632356 | T29: 1.9341794 | U29: 1.4230258 | Z29: 0.51115355
A30: BE233 | B30: 3 | C30: BE | D30: Arr. Eeklo | E30: Arr. Eeklo | F30: 0.11832492 | L30: 0.11832492 | M30: 0.42373055 | S30: 0.42373055 | T30: 1.1153909 | Z30: 1.1153909
A31: BE234 | B31: 3 | C31: BE | D31: Arr. Gent | E31: Arr. Gent | F31: 3.646415 | G31: 3.516815 | L31: 0.1296 | M31: 5.7954953 | N31: 5.5925984 | S31: 0.2028969 | T31: 14.61679 | U31: 14.247816 | Z31: 0.36897339
A32: BE236 | B32: 3 | C32: BE | D32: Arr. Sint-Niklaas | E32: Arr. Sint-Niklaas | F32: 1.4785194 | L32: 1.4785194 | M32: 2.2910799 | S32: 2.2910799 | T32: 4.1321805 | Z32: 4.1321805
A33: BE255 | B33: 3 | C33: BE | D33: Arr. Oostende | E33: Arr. Oostende | F33: 0.056254407 | L33: 0.056254407 | M33: 0.088069791 | S33: 0.088069791 | T33: 0.16015725 | Z33: 0.16015725
A34: BE323 | B34: 3 | C34: BE | D34: Arr. Mons | E34: Arr. Mons | F34: 1.305689 | H34: 0.39725721 | I34: 0.21690728 | K34: 0.57319956 | L34: 0.11832492 | M34: 1.7951892 | O34: 0.44574693 | P34: 0.26085752 | R34: 0.66485416 | S34: 0.42373055 | T34: 3.2567036 | V34: 0.74064667 | W34: 0.52816087 | Y34: 0.87250515 | Z34: 1.1153909
A35: BE328 | B35: 3 | C35: BE | D35: Arr. Tournai-Mouscron | E35: Arr. Tournai-Mouscron | F35: 0.75620438 | H35: 0.75620438 | M35: 0.84850765 | O35: 0.84850765 | T35: 1.4098681 | V35: 1.4098681
A36: BE32B | B36: 3 | C36: BE | D36: Arr. Charleroi | E36: Arr. Charleroi | F36: 2.6088807 | G36: 2.6088807 | M36: 2.6088807 | N36: 2.6088807 | T36: 2.6088807 | U36: 2.6088807
A37: BE32C | B37: 3 | C37: BE | D37: Arr. Soignies | E37: Arr. Soignies | F37: 0.60410644 | I37: 0.053306436 | L37: 0.5508 | M37: 0.92641935 | P37: 0.064107505 | S37: 0.86231184 | T37: 1.697936 | W37: 0.12979912 | Z37: 1.5681369
A38: BE32D | B38: 3 | C38: BE | D38: Arr. Thuin | E38: Arr. Thuin | F38: 0.080582319 | I38: 0.080582319 | M38: 0.096910089 | P38: 0.096910089 | T38: 0.19621484 | W38: 0.19621484
A39: BE332 | B39: 3 | C39: BE | D39: Arr. Liège | E39: Arr. Liège | F39: 0.44730739 | H39: 0.44730739 | M39: 0.5019063 | O39: 0.5019063 | T39: 0.83396027 | V39: 0.83396027
A40: BE335 | B40: 3 | C40: BE | D40: Arr. Verviers — communes francophones | E40: Arr. Verviers — communes francophones | F40: 0.32154913 | I40: 0.32154913 | M40: 0.35688706 | P40: 0.35688706 | T40: 0.57169824 | W40: 0.57169824
A41: BE352 | B41: 3 | C41: BE | D41: Arr. Namur | E41: Arr. Namur | F41: 1.1610991 | I41: 0.60480009 | L41: 0.556299 | M41: 1.3727916 | P41: 0.78499202 | S41: 0.58779957 | T41: 2.5400644 | W41: 1.8809241 | Z41: 0.65914025
A42: BG313 | B42: 3 | C42: BG | D42: Vratsa | E42: Враца | F42: 0.17902619 | H42: 0.17902619 | M42: 0.20087836 | O42: 0.20087836 | T42: 0.33377659 | V42: 0.33377659
A43: BG314 | B43: 3 | C43: BG | D43: Pleven | E43: Плевен | F43: 0.1340798 | I43: 0.1340798 | M43: 0.16124734 | P43: 0.16124734 | T43: 0.32647913 | W43: 0.32647913
A44: BG315 | B44: 3 | C44: BG | D44: Lovech | E44: Ловеч | F44: 0.21624845 | H44: 0.21624845 | M44: 0.24264401 | O44: 0.24264401 | T44: 0.40317379 | V44: 0.40317379
A45: BG331 | B45: 3 | C45: BG | D45: Varna | E45: Варна | F45: 0.89607052 | H45: 0.31570596 | K45: 0.58036455 | M45: 1.0274063 | O45: 0.35424143 | R45: 0.67316483 | T45: 1.4720139 | V45: 0.58860246 | Y45: 0.88341147
A46: BG333 | B46: 3 | C46: BG | D46: Shumen | E46: Шумен | F46: 0.080810853 | I46: 0.080810853 | M46: 0.097184929 | P46: 0.097184929 | T46: 0.19677131 | W46: 0.19677131
A47: BG334 | B47: 3 | C47: BG | D47: Targovishte | E47: Търговище | F47: 0.61211758 | I47: 0.61211758 | M47: 0.77865394 | P47: 0.77865394 | T47: 1.7915301 | W47: 1.7915301
A48: BG341 | B48: 3 | C48: BG | D48: Burgas | E48: Бургас | F48: 0.89728192 | J48: 0.89728192 | M48: 6.6420779 | Q48: 6.6420779 | T48: 12.989531 | X48: 12.989531
A49: BG411 | B49: 3 | C49: BG | D49: Sofia (stolitsa) | E49: София (столица) | F49: 0.13167126 | I49: 0.13167126 | M49: 0.15835079 | P49: 0.15835079 | T49: 0.32061445 | W49: 0.32061445
A50: BG414 | B50: 3 | C50: BG | D50: Pernik | E50: Перник | F50: 0.9982341 | G50: 0.9982341 | M50: 0.9982341 | N50: 0.9982341 | T50: 0.9982341 | U50: 0.9982341
A51: BG421 | B51: 3 | C51: BG | D51: Plovdiv | E51: Пловдив | F51: 0.40670919 | I51: 0.40670919 | M51: 0.48911752 | P51: 0.48911752 | T51: 0.99032119 | W51: 0.99032119
...

Sheet Hydrogen (PJ per y)
F12: 2018 | M12: 2030 | T12: 2050
A13: NUTS ID | B13: NUTS LEVEL | C13: Country code | D13: NUTS region name (Latin) | E13: NUTS_NAME | F13: All sectors (PJ/y) | G13: Steel (PJ/y) | H13: Cement (PJ/y) | I13: Glass (PJ/y) | J13: Refineries (PJ/y) | K13: Fertilisers (PJ/y) | L13: Chemical (PJ/y) | M13: All sectors (PJ/y) | N13: Steel (PJ/y) | O13: Cement (PJ/y) | P13: Glass (PJ/y) | Q13: Refineries (PJ/y) | R13: Fertilisers (PJ/y) | S13: Chemical (PJ/y) | T13: All sectors (PJ/y) | U13: Steel (PJ/y) | V13: Cement (PJ/y) | W13: Glass (PJ/y) | X13: Refineries (PJ/y) | Y13: Fertilisers (PJ/y) | Z13: Chemical (PJ/y)
A14: AT121 | B14: 3 | C14: AT | D14: Mostviertel-Eisenwurzen | E14: Mostviertel-Eisenwurzen | F14: 0.008446715 | I14: 0.008446715 | M14: 0.059577989 | P14: 0.059577989 | T14: 0.37055546 | W14: 0.37055546
A15: AT122 | B15: 3 | C15: AT | D15: Niederösterreich-Süd | E15: Niederösterreich-Süd | F15: 0 | H15: 0 | M15: 0 | O15: 0 | T15: 0 | V15: 0
A16: AT124 | B16: 3 | C16: AT | D16: Waldviertel | E16: Waldviertel | F16: 0.00028158 | L16: 0.00028158 | M16: 0.038183538 | S16: 0.038183538 | T16: 0.12405894 | Z16: 0.12405894
A17: AT127 | B17: 3 | C17: AT | D17: Wiener Umland/Südteil | E17: Wiener Umland/Südteil | F17: 0.00028158 | H17: 0 | J17: 0 | L17: 0.00028158 | M17: 1.1906385 | O17: 0 | Q17: 0.32403534 | S17: 0.86660313 | T17: 3.2395763 | V17: 0 | X17: 0.41071599 | Z17: 2.8288603
A18: AT213 | B18: 3 | C18: AT | D18: Unterkärnten | E18: Unterkärnten | F18: 0 | H18: 0 | M18: 0 | O18: 0 | T18: 0 | V18: 0
A19: AT221 | B19: 3 | C19: AT | D19: Graz | E19: Graz | F19: 0 | G19: 0 | M19: 0 | N19: 0 | T19: 0 | U19: 0
A20: AT223 | B20: 3 | C20: AT | D20: Östliche Obersteiermark | E20: Östliche Obersteiermark | F20: 0 | G20: 0 | M20: 0.36946785 | N20: 0.36946785 | T20: 8.5999848 | U20: 8.5999848
A21: AT225 | B21: 3 | C21: AT | D21: West- und Südsteiermark | E21: West- und Südsteiermark | F21: 0.007336853 | H21: 0 | I21: 0.007336853 | M21: 0.051749695 | O21: 0 | P21: 0.051749695 | T21: 0.32186605 | V21: 0 | W21: 0.32186605
A22: AT312 | B22: 3 | C22: AT | D22: Linz-Wels | E22: Linz-Wels | F22: 0 | G22: 0 | K22: 0 | L22: 0 | M22: 3.3410438 | N22: 1.411979 | R22: 1.8926883 | S22: 0.036376502 | T22: 39.165332 | U22: 32.866184 | Y22: 6.1803508 | Z22: 0.11879741
A23: AT314 | B23: 3 | C23: AT | D23: Steyr-Kirchdorf | E23: Steyr-Kirchdorf | F23: 0.009616008 | H23: 0 | I23: 0.009616008 | M23: 0.06782547 | O23: 0 | P23: 0.06782547 | T23: 0.42185208 | V23: 0 | W23: 0.42185208
A24: AT315 | B24: 3 | C24: AT | D24: Traunviertel | E24: Traunviertel | F24: 0 | H24: 0 | M24: 0 | O24: 0 | T24: 0 | V24: 0
A25: AT323 | B25: 3 | C25: AT | D25: Salzburg und Umgebung | E25: Salzburg und Umgebung | F25: 0 | H25: 0 | M25: 0 | O25: 0 | T25: 0 | V25: 0
A26: AT331 | B26: 3 | C26: AT | D26: Außerfern | E26: Außerfern | F26: 0 | H26: 0 | M26: 0 | O26: 0 | T26: 0 | V26: 0
A27: BE211 | B27: 3 | C27: BE | D27: Arr. Antwerpen | E27: Arr. Antwerpen | F27: 0.025697213 | J27: 0 | K27: 0 | L27: 0.025697213 | M27: 11.36171 | Q27: 1.2994819 | R27: 2.7291828 | S27: 7.3330452 | T27: 34.447426 | X27: 1.6470982 | Y27: 8.9118253 | Z27: 23.888503
A28: BE213 | B28: 3 | C28: BE | D28: Arr. Turnhout | E28: Arr. Turnhout | F28: 0.013032831 | I28: 0.007425022 | L28: 0.005607809 | M28: 1.3408095 | P28: 0.056128498 | S28: 1.284681 | T28: 4.53508 | W28: 0.35234581 | Z28: 4.1827342
A29: BE224 | B29: 3 | C29: BE | D29: Arr. Hasselt | E29: Arr. Hasselt | F29: 0.00195318 | G29: 0 | L29: 0.00195318 | M29: 0.085287524 | N29: 0 | S29: 0.085287524 | T29: 0.27409146 | U29: 0 | Z29: 0.27409146
A30: BE233 | B30: 3 | C30: BE | D30: Arr. Eeklo | E30: Arr. Eeklo | F30: 0.00028158 | L30: 0.00028158 | M30: 0.062001752 | S30: 0.062001752 | T30: 0.20182573 | Z30: 0.20182573
A31: BE234 | B31: 3 | C31: BE | D31: Arr. Gent | E31: Arr. Gent | F31: 0 | G31: 0 | L31: 0 | M31: 1.612325 | N31: 1.5285201 | S31: 0.083804896 | T31: 35.85256 | U31: 35.578872 | Z31: 0.27368778
A32: BE236 | B32: 3 | C32: BE | D32: Arr. Sint-Niklaas | E32: Arr. Sint-Niklaas | F32: 0.000563159 | L32: 0.000563159 | M32: 0.92965817 | S32: 0.92965817 | T32: 3.0347731 | Z32: 3.0347731
A33: BE255 | B33: 3 | C33: BE | D33: Arr. Oostende | E33: Arr. Oostende | F33: 0 | L33: 0 | M33: 0.036376502 | S33: 0.036376502 | T33: 0.11879741 | Z33: 0.11879741
A34: BE323 | B34: 3 | C34: BE | D34: Arr. Mons | E34: Arr. Mons | F34: 0.009189809 | H34: 0 | I34: 0.008908229 | K34: 0 | L34: 0.00028158 | M34: 1.4894264 | O34: 0 | P34: 0.062833226 | R34: 1.3645914 | S34: 0.062001752 | T34: 5.0485403 | V34: 0 | W34: 0.39080197 | Y34: 4.4559126 | Z34: 0.20182573
A35: BE328 | B35: 3 | C35: BE | D35: Arr. Tournai-Mouscron | E35: Arr. Tournai-Mouscron | F35: 0 | H35: 0 | M35: 0 | O35: 0 | T35: 0 | V35: 0
A36: BE32B | B36: 3 | C36: BE | D36: Arr. Charleroi | E36: Arr. Charleroi | F36: 0 | G36: 0 | M36: 0 | N36: 0 | T36: 0 | U36: 0
A37: BE32C | B37: 3 | C37: BE | D37: Arr. Soignies | E37: Arr. Soignies | F37: 0.002189258 | I37: 0.002189258 | L37: 0 | M37: 0.3716125 | P37: 0.015441692 | S37: 0.35617081 | T37: 1.2592153 | W37: 0.096042234 | Z37: 1.1631731
A38: BE32D | B38: 3 | C38: BE | D38: Arr. Thuin | E38: Arr. Thuin | F38: 0.003309459 | I38: 0.003309459 | M38: 0.02334291 | P38: 0.02334291 | T38: 0.14518521 | W38: 0.14518521
A39: BE332 | B39: 3 | C39: BE | D39: Arr. Liège | E39: Arr. Liège | F39: 0 | H39: 0 | M39: 0 | O39: 0 | T39: 0 | V39: 0
A40: BE335 | B40: 3 | C40: BE | D40: Arr. Verviers — communes francophones | E40: Arr. Verviers — communes francophones | F40: 0.006550075 | I40: 0.006550075 | M40: 0.07130858 | P40: 0.07130858 | T40: 0.46486522 | W40: 0.46486522
A41: BE352 | B41: 3 | C41: BE | D41: Arr. Namur | E41: Arr. Namur | F41: 0.040043403 | I41: 0.033297303 | L41: 0.0067461 | M41: 0.29499974 | P41: 0.25170668 | S41: 0.043293058 | T41: 1.706141 | W41: 1.580085 | Z41: 0.12605603
A42: BG313 | B42: 3 | C42: BG | D42: Vratsa | E42: Враца | F42: 0 | H42: 0 | M42: 0 | O42: 0 | T42: 0 | V42: 0
A43: BG314 | B43: 3 | C43: BG | D43: Pleven | E43: Плевен | F43: 0.005506563 | I43: 0.005506563 | M43: 0.038839941 | P43: 0.038839941 | T43: 0.24157164 | W43: 0.24157164
A44: BG315 | B44: 3 | C44: BG | D44: Lovech | E44: Ловеч | F44: 0 | H44: 0 | M44: 0 | O44: 0 | T44: 0 | V44: 0
A45: BG331 | B45: 3 | C45: BG | D45: Varna | E45: Варна | F45: 0 | H45: 0 | K45: 0 | M45: 1.3816488 | O45: 0 | R45: 1.3816488 | T45: 4.5116115 | V45: 0 | Y45: 4.5116115
A46: BG333 | B46: 3 | C46: BG | D46: Shumen | E46: Шумен | F46: 0.003318845 | I46: 0.003318845 | M46: 0.023409111 | P46: 0.023409111 | T46: 0.14559696 | W46: 0.14559696
A47: BG334 | B47: 3 | C47: BG | D47: Targovishte | E47: Търговище | F47: 0.03137654 | I47: 0.03137654 | M47: 0.23373444 | P47: 0.23373444 | T47: 1.464482 | W47: 1.464482
A48: BG341 | B48: 3 | C48: BG | D48: Burgas | E48: Бургас | F48: 0 | J48: 0 | M48: 0.32737591 | Q48: 0.32737591 | T48: 0.41495018 | X48: 0.41495018
A49: BG411 | B49: 3 | C49: BG | D49: Sofia (stolitsa) | E49: София (столица) | F49: 0.005407646 | I49: 0.005407646 | M49: 0.038142243 | P49: 0.038142243 | T49: 0.23723218 | W49: 0.23723218
A50: BG414 | B50: 3 | C50: BG | D50: Pernik | E50: Перник | F50: 0 | G50: 0 | M50: 0 | N50: 0 | T50: 0 | U50: 0
A51: BG421 | B51: 3 | C51: BG | D51: Plovdiv | E51: Пловдив | F51: 0.01670326 | I51: 0.01670326 | M51: 0.11781463 | P51: 0.11781463 | T51: 0.73276816 | W51: 0.73276816
...

Sheet Natural gas (PJ per y)
F12: 2018 | M12: 2030 | T12: 2050
A13: NUTS ID | B13: NUTS LEVEL | C13: Country code | D13: NUTS region name (Latin) | E13: NUTS_NAME | F13: All sectors (PJ/y) | G13: Steel (PJ/y) | H13: Cement (PJ/y) | I13: Glass (PJ/y) | J13: Refineries (PJ/y) | K13: Fertilisers (PJ/y) | L13: Chemical (PJ/y) | M13: All sectors (PJ/y) | N13: Steel (PJ/y) | O13: Cement (PJ/y) | P13: Glass (PJ/y) | Q13: Refineries (PJ/y) | R13: Fertilisers (PJ/y) | S13: Chemical (PJ/y) | T13: All sectors (PJ/y) | U13: Steel (PJ/y) | V13: Cement (PJ/y) | W13: Glass (PJ/y) | X13: Refineries (PJ/y) | Y13: Fertilisers (PJ/y) | Z13: Chemical (PJ/y)
A14: AT121 | B14: 3 | C14: AT | D14: Mostviertel-Eisenwurzen | E14: Mostviertel-Eisenwurzen | F14: 0.90800462 | I14: 0.90800462 | M14: 0.81115685 | P14: 0.81115685 | T14: 0.22213425 | W14: 0.22213425
A15: AT122 | B15: 3 | C15: AT | D15: Niederösterreich-Süd | E15: Niederösterreich-Süd | F15: 0 | H15: 0 | M15: 0.002117016 | O15: 0.002117016 | T15: 0.014993034 | V15: 0.014993034
A16: AT124 | B16: 3 | C16: AT | D16: Waldviertel | E16: Waldviertel | F16: 0.36803446 | L16: 0.36803446 | M16: 0.29937551 | S16: 0.29937551 | T16: 0.14382092 | Z16: 0.14382092
A17: AT127 | B17: 3 | C17: AT | D17: Wiener Umland/Südteil | E17: Wiener Umland/Südteil | F17: 15.898821 | H17: 0 | J17: 15.530787 | L17: 0.36803446 | M17: 11.582432 | O17: 0.004392159 | Q17: 11.195718 | S17: 0.38232177 | T17: 2.3965457 | V17: 0.031105943 | X17: 1.9508471 | Z17: 0.41459259
A18: AT213 | B18: 3 | C18: AT | D18: Unterkärnten | E18: Unterkärnten | F18: 0 | H18: 0 | M18: 0.003176548 | O18: 0.003176548 | T18: 0.0224968 | V18: 0.0224968
A19: AT221 | B19: 3 | C19: AT | D19: Graz | E19: Graz | F19: 0.057827974 | G19: 0.057827974 | M19: 0.057827974 | N19: 0.057827974 | T19: 0.057827974 | U19: 0.057827974
A20: AT223 | B20: 3 | C20: AT | D20: Östliche Obersteiermark | E20: Östliche Obersteiermark | F20: 0.076047746 | G20: 0.076047746 | M20: 2.1231535 | N20: 2.1231535 | T20: 1.7912979 | U20: 1.7912979
A21: AT225 | B21: 3 | C21: AT | D21: West- und Südsteiermark | E21: West- und Südsteiermark | F21: 0.78869669 | H21: 0 | I21: 0.78869669 | M21: 0.70693083 | O21: 0.002356533 | P21: 0.7045743 | T21: 0.20963609 | V21: 0.016689328 | W21: 0.19294676
A22: AT312 | B22: 3 | C22: AT | D22: Linz-Wels | E22: Linz-Wels | F22: 11.199068 | G22: 0 | K22: 10.844735 | L22: 0.35433375 | M22: 16.445953 | N22: 7.8233339 | R22: 8.3341239 | S22: 0.28849541 | T22: 9.3412203 | U22: 6.5550961 | Y22: 2.646796 | Z22: 0.13932811
A23: AT314 | B23: 3 | C23: AT | D23: Steyr-Kirchdorf | E23: Steyr-Kirchdorf | F23: 1.0337012 | H23: 0 | I23: 1.0337012 | M23: 0.92507814 | O23: 0.001631475 | P23: 0.92344666 | T23: 0.26443902 | V23: 0.011554355 | W23: 0.25288467
A24: AT315 | B24: 3 | C24: AT | D24: Traunviertel | E24: Traunviertel | F24: 0 | H24: 0 | M24: 0.002381362 | O24: 0.002381362 | T24: 0.016865173 | V24: 0.016865173
A25: AT323 | B25: 3 | C25: AT | D25: Salzburg und Umgebung | E25: Salzburg und Umgebung | F25: 0 | H25: 0 | M25: 0.002254994 | O25: 0.002254994 | T25: 0.01597021 | V25: 0.01597021
A26: AT331 | B26: 3 | C26: AT | D26: Außerfern | E26: Außerfern | F26: 0 | H26: 0 | M26: 0.001556105 | O26: 0.001556105 | T26: 0.011020577 | V26: 0.011020577
A27: BE211 | B27: 3 | C27: BE | D27: Arr. Antwerpen | E27: Arr. Antwerpen | F27: 134.02329 | J27: 62.283258 | K27: 15.637685 | L27: 56.102345 | M27: 102.72261 | Q27: 44.898291 | R27: 12.017482 | S27: 45.806833 | T27: 34.120887 | X27: 7.8235003 | Y27: 3.8165768 | Z27: 22.48081
A28: BE213 | B28: 3 | C28: BE | D28: Arr. Turnhout | E28: Arr. Turnhout | F28: 13.352483 | I28: 0.91644342 | L28: 12.43604 | M28: 10.944033 | P28: 0.82419422 | S28: 10.119839 | T28: 5.1353003 | W28: 0.26312007 | Z28: 4.8721803
A29: BE224 | B29: 3 | C29: BE | D29: Arr. Hasselt | E29: Arr. Hasselt | F29: 0.98322688 | G29: 0.17952427 | L29: 0.80370261 | M29: 0.83198504 | N29: 0.17952427 | S29: 0.65246077 | T29: 0.4893449 | U29: 0.17952427 | Z29: 0.30982063
A30: BE233 | B30: 3 | C30: BE | D30: Arr. Eeklo | E30: Arr. Eeklo | F30: 0.36803446 | L30: 0.36803446 | M30: 0.30176033 | S30: 0.30176033 | T30: 0.15160598 | Z30: 0.15160598
A31: BE234 | B31: 3 | C31: BE | D31: Arr. Gent | E31: Arr. Gent | F31: 0.816321 | G31: 0 | L31: 0.816321 | M31: 9.1336927 | N31: 8.4690513 | S31: 0.66464135 | T31: 7.4171233 | U31: 7.0961365 | Z31: 0.32098682
A32: BE236 | B32: 3 | C32: BE | D32: Arr. Sint-Niklaas | E32: Arr. Sint-Niklaas | F32: 9.0477485 | L32: 9.0477485 | M32: 7.3660471 | S32: 7.3660471 | T32: 3.5558899 | Z32: 3.5558899
A33: BE255 | B33: 3 | C33: BE | D33: Arr. Oostende | E33: Arr. Oostende | F33: 0.35433375 | L33: 0.35433375 | M33: 0.28849541 | S33: 0.28849541 | T33: 0.13932811 | Z33: 0.13932811
A34: BE323 | B34: 3 | C34: BE | D34: Arr. Mons | E34: Arr. Mons | F34: 9.1444935 | H34: 0 | I34: 0.95761642 | K34: 7.8188426 | L34: 0.36803446 | M34: 7.1724582 | O34: 0.006479694 | P34: 0.85547705 | R34: 6.0087411 | S34: 0.30176033 | T34: 2.3400559 | V34: 0.045890183 | W34: 0.23427128 | Y34: 1.9082884 | Z34: 0.15160598
A35: BE328 | B35: 3 | C35: BE | D35: Arr. Tournai-Mouscron | E35: Arr. Tournai-Mouscron | F35: 0 | H35: 0 | M35: 0.01233451 | O35: 0.01233451 | T35: 0.087354883 | V35: 0.087354883
A36: BE32B | B36: 3 | C36: BE | D36: Arr. Charleroi | E36: Arr. Charleroi | F36: 0.32912783 | G36: 0.32912783 | M36: 0.32912783 | N36: 0.32912783 | T36: 0.32912783 | U36: 0.32912783
A37: BE32C | B37: 3 | C37: BE | D37: Arr. Soignies | E37: Arr. Soignies | F37: 3.704705 | I37: 0.23534073 | L37: 3.4693642 | M37: 3.034965 | P37: 0.21023929 | S37: 2.8247257 | T37: 1.4217677 | W37: 0.057573756 | Z37: 1.364194
A38: BE32D | B38: 3 | C38: BE | D38: Arr. Thuin | E38: Arr. Thuin | F38: 0.35576008 | I38: 0.35576008 | M38: 0.31781471 | P38: 0.31781471 | T38: 0.087033146 | W38: 0.087033146
A39: BE332 | B39: 3 | C39: BE | D39: Arr. Liège | E39: Arr. Liège | F39: 0 | H39: 0 | M39: 0.007296066 | O39: 0.007296066 | T39: 0.051671857 | V39: 0.051671857
A40: BE335 | B40: 3 | C40: BE | D40: Arr. Verviers — communes francophones | E40: Arr. Verviers — communes francophones | F40: 1.0781006 | I40: 1.0781006 | M40: 0.96900764 | P40: 0.96900764 | T40: 0.30607277 | W40: 0.30607277
A41: BE352 | B41: 3 | C41: BE | D41: Arr. Namur | E41: Arr. Namur | F41: 4.4380074 | I41: 4.109765 | L41: 0.3282424 | M41: 3.9567422 | P41: 3.696076 | S41: 0.26066618 | T41: 1.2875936 | W41: 1.1799546 | Z41: 0.10763897
A42: BG313 | B42: 3 | C42: BG | D42: Vratsa | E42: Враца | F42: 0 | H42: 0 | M42: 0.00292011 | O42: 0.00292011 | T42: 0.020680669 | V42: 0.020680669
A43: BG314 | B43: 3 | C43: BG | D43: Pleven | E43: Плевен | F43: 0.59194422 | I43: 0.59194422 | M43: 0.52880745 | P43: 0.52880745 | T43: 0.14481324 | W43: 0.14481324
A44: BG315 | B44: 3 | C44: BG | D44: Lovech | E44: Ловеч | F44: 0 | H44: 0 | M44: 0.003527246 | O44: 0.003527246 | T44: 0.024980493 | V44: 0.024980493
A45: BG331 | B45: 3 | C45: BG | D45: Varna | E45: Варна | F45: 7.9165782 | H45: 0 | K45: 7.9165782 | M45: 6.0889999 | O45: 0.005149505 | R45: 6.0838504 | T45: 1.9686116 | V45: 0.036469582 | Y45: 1.932142
A46: BG333 | B46: 3 | C46: BG | D46: Shumen | E46: Шумен | F46: 0.35676903 | I46: 0.35676903 | M46: 0.31871604 | P46: 0.31871604 | T46: 0.087279974 | W46: 0.087279974
A47: BG334 | B47: 3 | C47: BG | D47: Targovishte | E47: Търговище | F47: 3.7640071 | I47: 3.7640071 | M47: 3.3807211 | P47: 3.3807211 | T47: 1.0495325 | W47: 1.0495325
A48: BG341 | B48: 3 | C48: BG | D48: Burgas | E48: Бургас | F48: 15.690898 | J48: 15.690898 | M48: 11.311137 | Q48: 11.311137 | T48: 1.9709589 | X48: 1.9709589
A49: BG411 | B49: 3 | C49: BG | D49: Sofia (stolitsa) | E49: София (столица) | F49: 0.58131087 | I49: 0.58131087 | M49: 0.51930826 | P49: 0.51930826 | T49: 0.14221189 | W49: 0.14221189
A50: BG414 | B50: 3 | C50: BG | D50: Pernik | E50: Перник | F50: 0.12593394 | G50: 0.12593394 | M50: 0.12593394 | N50: 0.12593394 | T50: 0.12593394 | U50: 0.12593394
A51: BG421 | B51: 3 | C51: BG | D51: Plovdiv | E51: Пловдив | F51: 1.7955662 | I51: 1.7955662 | M51: 1.6040512 | P51: 1.6040512 | T51: 0.43926733 | W51: 0.43926733
...

Sheet Crude oil (PJ per y)
F12: 2018 | M12: 2030 | T12: 2050
A13: NUTS ID | B13: NUTS LEVEL | C13: Country code | D13: NUTS region name (Latin) | E13: NUTS_NAME | F13: All sectors (PJ/y) | G13: Steel (PJ/y) | H13: Cement (PJ/y) | I13: Glass (PJ/y) | J13: Refineries (PJ/y) | K13: Fertilisers (PJ/y) | L13: Chemical (PJ/y) | M13: All sectors (PJ/y) | N13: Steel (PJ/y) | O13: Cement (PJ/y) | P13: Glass (PJ/y) | Q13: Refineries (PJ/y) | R13: Fertilisers (PJ/y) | S13: Chemical (PJ/y) | T13: All sectors (PJ/y) | U13: Steel (PJ/y) | V13: Cement (PJ/y) | W13: Glass (PJ/y) | X13: Refineries (PJ/y) | Y13: Fertilisers (PJ/y) | Z13: Chemical (PJ/y)
A14: AT121 | B14: 3 | C14: AT | D14: Mostviertel-Eisenwurzen | E14: Mostviertel-Eisenwurzen | F14: 0 | I14: 0 | M14: 0 | P14: 0 | T14: 0 | W14: 0
A15: AT122 | B15: 3 | C15: AT | D15: Niederösterreich-Süd | E15: Niederösterreich-Süd | F15: 0 | H15: 0 | M15: 0 | O15: 0 | T15: 0 | V15: 0
A16: AT124 | B16: 3 | C16: AT | D16: Waldviertel | E16: Waldviertel | F16: 0 | L16: 0 | M16: 0 | S16: 0 | T16: 0 | Z16: 0
A17: AT127 | B17: 3 | C17: AT | D17: Wiener Umland/Südteil | E17: Wiener Umland/Südteil | F17: 416.0558 | H17: 0 | J17: 416.0558 | L17: 0 | M17: 313.39509 | O17: 0 | Q17: 313.39509 | S17: 0 | T17: 69.337106 | V17: 0 | X17: 69.337106 | Z17: 0
A18: AT213 | B18: 3 | C18: AT | D18: Unterkärnten | E18: Unterkärnten | F18: 0 | H18: 0 | M18: 0 | O18: 0 | T18: 0 | V18: 0
A19: AT221 | B19: 3 | C19: AT | D19: Graz | E19: Graz | F19: 0 | G19: 0 | M19: 0 | N19: 0 | T19: 0 | U19: 0
A20: AT223 | B20: 3 | C20: AT | D20: Östliche Obersteiermark | E20: Östliche Obersteiermark | F20: 0 | G20: 0 | M20: 0 | N20: 0 | T20: 0 | U20: 0
A21: AT225 | B21: 3 | C21: AT | D21: West- und Südsteiermark | E21: West- und Südsteiermark | F21: 0 | H21: 0 | I21: 0 | M21: 0 | O21: 0 | P21: 0 | T21: 0 | V21: 0 | W21: 0
A22: AT312 | B22: 3 | C22: AT | D22: Linz-Wels | E22: Linz-Wels | F22: 0 | G22: 0 | K22: 0 | L22: 0 | M22: 0 | N22: 0 | R22: 0 | S22: 0 | T22: 0 | U22: 0 | Y22: 0 | Z22: 0
A23: AT314 | B23: 3 | C23: AT | D23: Steyr-Kirchdorf | E23: Steyr-Kirchdorf | F23: 0 | H23: 0 | I23: 0 | M23: 0 | O23: 0 | P23: 0 | T23: 0 | V23: 0 | W23: 0
A24: AT315 | B24: 3 | C24: AT | D24: Traunviertel | E24: Traunviertel | F24: 0 | H24: 0 | M24: 0 | O24: 0 | T24: 0 | V24: 0
A25: AT323 | B25: 3 | C25: AT | D25: Salzburg und Umgebung | E25: Salzburg und Umgebung | F25: 0 | H25: 0 | M25: 0 | O25: 0 | T25: 0 | V25: 0
A26: AT331 | B26: 3 | C26: AT | D26: Außerfern | E26: Außerfern | F26: 0 | H26: 0 | M26: 0 | O26: 0 | T26: 0 | V26: 0
A27: BE211 | B27: 3 | C27: BE | D27: Arr. Antwerpen | E27: Arr. Antwerpen | F27: 1668.5124 | J27: 1668.5124 | K27: 0 | L27: 0 | M27: 1256.8112 | Q27: 1256.8112 | R27: 0 | S27: 0 | T27: 278.06324 | X27: 278.06324 | Y27: 0 | Z27: 0
A28: BE213 | B28: 3 | C28: BE | D28: Arr. Turnhout | E28: Arr. Turnhout | F28: 0 | I28: 0 | L28: 0 | M28: 0 | P28: 0 | S28: 0 | T28: 0 | W28: 0 | Z28: 0
A29: BE224 | B29: 3 | C29: BE | D29: Arr. Hasselt | E29: Arr. Hasselt | F29: 0 | G29: 0 | L29: 0 | M29: 0 | N29: 0 | S29: 0 | T29: 0 | U29: 0 | Z29: 0
A30: BE233 | B30: 3 | C30: BE | D30: Arr. Eeklo | E30: Arr. Eeklo | F30: 0 | L30: 0 | M30: 0 | S30: 0 | T30: 0 | Z30: 0
A31: BE234 | B31: 3 | C31: BE | D31: Arr. Gent | E31: Arr. Gent | F31: 0 | G31: 0 | L31: 0 | M31: 0 | N31: 0 | S31: 0 | T31: 0 | U31: 0 | Z31: 0
A32: BE236 | B32: 3 | C32: BE | D32: Arr. Sint-Niklaas | E32: Arr. Sint-Niklaas | F32: 0 | L32: 0 | M32: 0 | S32: 0 | T32: 0 | Z32: 0
A33: BE255 | B33: 3 | C33: BE | D33: Arr. Oostende | E33: Arr. Oostende | F33: 0 | L33: 0 | M33: 0 | S33: 0 | T33: 0 | Z33: 0
A34: BE323 | B34: 3 | C34: BE | D34: Arr. Mons | E34: Arr. Mons | F34: 0 | H34: 0 | I34: 0 | K34: 0 | L34: 0 | M34: 0 | O34: 0 | P34: 0 | R34: 0 | S34: 0 | T34: 0 | V34: 0 | W34: 0 | Y34: 0 | Z34: 0
A35: BE328 | B35: 3 | C35: BE | D35: Arr. Tournai-Mouscron | E35: Arr. Tournai-Mouscron | F35: 0 | H35: 0 | M35: 0 | O35: 0 | T35: 0 | V35: 0
A36: BE32B | B36: 3 | C36: BE | D36: Arr. Charleroi | E36: Arr. Charleroi | F36: 0 | G36: 0 | M36: 0 | N36: 0 | T36: 0 | U36: 0
A37: BE32C | B37: 3 | C37: BE | D37: Arr. Soignies | E37: Arr. Soignies | F37: 0 | I37: 0 | L37: 0 | M37: 0 | P37: 0 | S37: 0 | T37: 0 | W37: 0 | Z37: 0
A38: BE32D | B38: 3 | C38: BE | D38: Arr. Thuin | E38: Arr. Thuin | F38: 0 | I38: 0 | M38: 0 | P38: 0 | T38: 0 | W38: 0
A39: BE332 | B39: 3 | C39: BE | D39: Arr. Liège | E39: Arr. Liège | F39: 0 | H39: 0 | M39: 0 | O39: 0 | T39: 0 | V39: 0
A40: BE335 | B40: 3 | C40: BE | D40: Arr. Verviers — communes francophones | E40: Arr. Verviers — communes francophones | F40: 0 | I40: 0 | M40: 0 | P40: 0 | T40: 0 | W40: 0
A41: BE352 | B41: 3 | C41: BE | D41: Arr. Namur | E41: Arr. Namur | F41: 0 | I41: 0 | L41: 0 | M41: 0 | P41: 0 | S41: 0 | T41: 0 | W41: 0 | Z41: 0
A42: BG313 | B42: 3 | C42: BG | D42: Vratsa | E42: Враца | F42: 0 | H42: 0 | M42: 0 | O42: 0 | T42: 0 | V42: 0
A43: BG314 | B43: 3 | C43: BG | D43: Pleven | E43: Плевен | F43: 0 | I43: 0 | M43: 0 | P43: 0 | T43: 0 | W43: 0
A44: BG315 | B44: 3 | C44: BG | D44: Lovech | E44: Ловеч | F44: 0 | H44: 0 | M44: 0 | O44: 0 | T44: 0 | V44: 0
A45: BG331 | B45: 3 | C45: BG | D45: Varna | E45: Варна | F45: 0 | H45: 0 | K45: 0 | M45: 0 | O45: 0 | R45: 0 | T45: 0 | V45: 0 | Y45: 0
A46: BG333 | B46: 3 | C46: BG | D46: Shumen | E46: Шумен | F46: 0 | I46: 0 | M46: 0 | P46: 0 | T46: 0 | W46: 0
A47: BG334 | B47: 3 | C47: BG | D47: Targovishte | E47: Търговище | F47: 0 | I47: 0 | M47: 0 | P47: 0 | T47: 0 | W47: 0
A48: BG341 | B48: 3 | C48: BG | D48: Burgas | E48: Бургас | F48: 420.34504 | J48: 420.34504 | M48: 316.62597 | Q48: 316.62597 | T48: 70.051921 | X48: 70.051921
A49: BG411 | B49: 3 | C49: BG | D49: Sofia (stolitsa) | E49: София (столица) | F49: 0 | I49: 0 | M49: 0 | P49: 0 | T49: 0 | W49: 0
A50: BG414 | B50: 3 | C50: BG | D50: Pernik | E50: Перник | F50: 0 | G50: 0 | M50: 0 | N50: 0 | T50: 0 | U50: 0
A51: BG421 | B51: 3 | C51: BG | D51: Plovdiv | E51: Пловдив | F51: 0 | I51: 0 | M51: 0 | P51: 0 | T51: 0 | W51: 0
...

Sheet Alternative fuel mix (PJ per y)
F12: 2018 | M12: 2030 | T12: 2050
A13: NUTS ID | B13: NUTS LEVEL | C13: Country code | D13: NUTS region name (Latin) | E13: NUTS_NAME | F13: All sectors (PJ/y) | G13: Steel (PJ/y) | H13: Cement (PJ/y) | I13: Glass (PJ/y) | J13: Refineries (PJ/y) | K13: Fertilisers (PJ/y) | L13: Chemical (PJ/y) | M13: All sectors (PJ/y) | N13: Steel (PJ/y) | O13: Cement (PJ/y) | P13: Glass (PJ/y) | Q13: Refineries (PJ/y) | R13: Fertilisers (PJ/y) | S13: Chemical (PJ/y) | T13: All sectors (PJ/y) | U13: Steel (PJ/y) | V13: Cement (PJ/y) | W13: Glass (PJ/y) | X13: Refineries (PJ/y) | Y13: Fertilisers (PJ/y) | Z13: Chemical (PJ/y)
A14: AT121 | B14: 3 | C14: AT | D14: Mostviertel-Eisenwurzen | E14: Mostviertel-Eisenwurzen | F14: 0 | I14: 0 | M14: 0 | P14: 0 | T14: 0 | W14: 0
A15: AT122 | B15: 3 | C15: AT | D15: Niederösterreich-Süd | E15: Niederösterreich-Süd | F15: 0.33195414 | H15: 0.33195414 | M15: 0.35246523 | O15: 0.35246523 | T15: 0.47719769 | V15: 0.47719769
A16: AT124 | B16: 3 | C16: AT | D16: Waldviertel | E16: Waldviertel | F16: 0 | L16: 0 | M16: 0 | S16: 0 | T16: 0 | Z16: 0
A17: AT127 | B17: 3 | C17: AT | D17: Wiener Umland/Südteil | E17: Wiener Umland/Südteil | F17: 0.68870295 | H17: 0.68870295 | J17: 0 | L17: 0 | M17: 0.73125715 | O17: 0.73125715 | Q17: 0 | S17: 0 | T17: 0.99003872 | V17: 0.99003872 | X17: 0 | Z17: 0
A18: AT213 | B18: 3 | C18: AT | D18: Unterkärnten | E18: Unterkärnten | F18: 0.49809172 | H18: 0.49809172 | M18: 0.52886826 | O18: 0.52886826 | T18: 0.71602727 | V18: 0.71602727
A19: AT221 | B19: 3 | C19: AT | D19: Graz | E19: Graz | F19: 0 | G19: 0 | M19: 0 | N19: 0 | T19: 0 | U19: 0
A20: AT223 | B20: 3 | C20: AT | D20: Östliche Obersteiermark | E20: Östliche Obersteiermark | F20: 0 | G20: 0 | M20: 0 | N20: 0 | T20: 0 | U20: 0
A21: AT225 | B21: 3 | C21: AT | D21: West- und Südsteiermark | E21: West- und Südsteiermark | F21: 0.36951104 | H21: 0.36951104 | I21: 0 | M21: 0.39234272 | O21: 0.39234272 | P21: 0 | T21: 0.53118726 | V21: 0.53118726 | W21: 0
A22: AT312 | B22: 3 | C22: AT | D22: Linz-Wels | E22: Linz-Wels | F22: 0 | G22: 0 | K22: 0 | L22: 0 | M22: 0 | N22: 0 | R22: 0 | S22: 0 | T22: 0 | U22: 0 | Y22: 0 | Z22: 0
A23: AT314 | B23: 3 | C23: AT | D23: Steyr-Kirchdorf | E23: Steyr-Kirchdorf | F23: 0.25581986 | H23: 0.25581986 | I23: 0 | M23: 0.27162669 | O23: 0.27162669 | P23: 0 | T23: 0.36775154 | V23: 0.36775154 | W23: 0
A24: AT315 | B24: 3 | C24: AT | D24: Traunviertel | E24: Traunviertel | F24: 0.37340435 | H24: 0.37340435 | M24: 0.39647659 | O24: 0.39647659 | T24: 0.53678405 | V24: 0.53678405
A25: AT323 | B25: 3 | C25: AT | D25: Salzburg und Umgebung | E25: Salzburg und Umgebung | F25: 0.35358937 | H25: 0.35358937 | M25: 0.37543728 | O25: 0.37543728 | T25: 0.50829922 | V25: 0.50829922
A26: AT331 | B26: 3 | C26: AT | D26: Außerfern | E26: Außerfern | F26: 0.24400173 | H26: 0.24400173 | M26: 0.25907833 | O26: 0.25907833 | T26: 0.35076249 | V26: 0.35076249
A27: BE211 | B27: 3 | C27: BE | D27: Arr. Antwerpen | E27: Arr. Antwerpen | F27: 0 | J27: 0 | K27: 0 | L27: 0 | M27: 0 | Q27: 0 | R27: 0 | S27: 0 | T27: 0 | X27: 0 | Y27: 0 | Z27: 0
A28: BE213 | B28: 3 | C28: BE | D28: Arr. Turnhout | E28: Arr. Turnhout | F28: 0 | I28: 0 | L28: 0 | M28: 0 | P28: 0 | S28: 0 | T28: 0 | W28: 0 | Z28: 0
A29: BE224 | B29: 3 | C29: BE | D29: Arr. Hasselt | E29: Arr. Hasselt | F29: 0 | G29: 0 | L29: 0 | M29: 0 | N29: 0 | S29: 0 | T29: 0 | U29: 0 | Z29: 0
A30: BE233 | B30: 3 | C30: BE | D30: Arr. Eeklo | E30: Arr. Eeklo | F30: 0 | L30: 0 | M30: 0 | S30: 0 | T30: 0 | Z30: 0
A31: BE234 | B31: 3 | C31: BE | D31: Arr. Gent | E31: Arr. Gent | F31: 0 | G31: 0 | L31: 0 | M31: 0 | N31: 0 | S31: 0 | T31: 0 | U31: 0 | Z31: 0
A32: BE236 | B32: 3 | C32: BE | D32: Arr. Sint-Niklaas | E32: Arr. Sint-Niklaas | F32: 0 | L32: 0 | M32: 0 | S32: 0 | T32: 0 | Z32: 0
A33: BE255 | B33: 3 | C33: BE | D33: Arr. Oostende | E33: Arr. Oostende | F33: 0 | L33: 0 | M33: 0 | S33: 0 | T33: 0 | Z33: 0
A34: BE323 | B34: 3 | C34: BE | D34: Arr. Mons | E34: Arr. Mons | F34: 1.0160343 | H34: 1.0160343 | I34: 0 | K34: 0 | L34: 0 | M34: 1.0788139 | O34: 1.0788139 | P34: 0 | R34: 0 | S34: 0 | T34: 1.4605909 | V34: 1.4605909 | W34: 0 | Y34: 0 | Z34: 0
A35: BE328 | B35: 3 | C35: BE | D35: Arr. Tournai-Mouscron | E35: Arr. Tournai-Mouscron | F35: 1.9340859 | H35: 1.9340859 | M35: 2.053591 | O35: 2.053591 | T35: 2.7803278 | V35: 2.7803278
A36: BE32B | B36: 3 | C36: BE | D36: Arr. Charleroi | E36: Arr. Charleroi | F36: 0 | G36: 0 | M36: 0 | N36: 0 | T36: 0 | U36: 0
A37: BE32C | B37: 3 | C37: BE | D37: Arr. Soignies | E37: Arr. Soignies | F37: 0 | I37: 0 | L37: 0 | M37: 0 | P37: 0 | S37: 0 | T37: 0 | W37: 0 | Z37: 0
A38: BE32D | B38: 3 | C38: BE | D38: Arr. Thuin | E38: Arr. Thuin | F38: 0 | I38: 0 | M38: 0 | P38: 0 | T38: 0 | W38: 0
A39: BE332 | B39: 3 | C39: BE | D39: Arr. Liège | E39: Arr. Liège | F39: 1.1440438 | H39: 1.1440438 | M39: 1.214733 | O39: 1.214733 | T39: 1.6446098 | V39: 1.6446098
A40: BE335 | B40: 3 | C40: BE | D40: Arr. Verviers — communes francophones | E40: Arr. Verviers — communes francophones | F40: 0 | I40: 0 | M40: 0 | P40: 0 | T40: 0 | W40: 0
A41: BE352 | B41: 3 | C41: BE | D41: Arr. Namur | E41: Arr. Namur | F41: 0 | I41: 0 | L41: 0 | M41: 0 | P41: 0 | S41: 0 | T41: 0 | W41: 0 | Z41: 0
A42: BG313 | B42: 3 | C42: BG | D42: Vratsa | E42: Враца | F42: 0.45788156 | H42: 0.45788156 | M42: 0.48617356 | O42: 0.48617356 | T42: 0.65822351 | V42: 0.65822351
A43: BG314 | B43: 3 | C43: BG | D43: Pleven | E43: Плевен | F43: 0 | I43: 0 | M43: 0 | P43: 0 | T43: 0 | W43: 0
A44: BG315 | B44: 3 | C44: BG | D44: Lovech | E44: Ловеч | F44: 0.55308206 | H44: 0.55308206 | M44: 0.5872564 | O44: 0.5872564 | T44: 0.79507813 | V44: 0.79507813
A45: BG331 | B45: 3 | C45: BG | D45: Varna | E45: Варна | F45: 0.80745691 | H45: 0.80745691 | K45: 0 | M45: 0.85734879 | O45: 0.85734879 | R45: 0 | T45: 1.1607524 | V45: 1.1607524 | Y45: 0
A46: BG333 | B46: 3 | C46: BG | D46: Shumen | E46: Шумен | F46: 0 | I46: 0 | M46: 0 | P46: 0 | T46: 0 | W46: 0
A47: BG334 | B47: 3 | C47: BG | D47: Targovishte | E47: Търговище | F47: 0 | I47: 0 | M47: 0 | P47: 0 | T47: 0 | W47: 0
A48: BG341 | B48: 3 | C48: BG | D48: Burgas | E48: Бургас | F48: 0 | J48: 0 | M48: 0 | Q48: 0 | T48: 0 | X48: 0
A49: BG411 | B49: 3 | C49: BG | D49: Sofia (stolitsa) | E49: София (столица) | F49: 0 | I49: 0 | M49: 0 | P49: 0 | T49: 0 | W49: 0
A50: BG414 | B50: 3 | C50: BG | D50: Pernik | E50: Перник | F50: 0 | G50: 0 | M50: 0 | N50: 0 | T50: 0 | U50: 0
A51: BG421 | B51: 3 | C51: BG | D51: Plovdiv | E51: Пловдив | F51: 0 | I51: 0 | M51: 0 | P51: 0 | T51: 0 | W51: 0
...

Sheet Biomass (PJ per y)
F12: 2018 | M12: 2030 | T12: 2050
A13: NUTS ID | B13: NUTS LEVEL | C13: Country code | D13: NUTS region name (Latin) | E13: NUTS_NAME | F13: All sectors (PJ/y) | G13: Steel (PJ/y) | H13: Cement (PJ/y) | I13: Glass (PJ/y) | J13: Refineries (PJ/y) | K13: Fertilisers (PJ/y) | L13: Chemical (PJ/y) | M13: All sectors (PJ/y) | N13: Steel (PJ/y) | O13: Cement (PJ/y) | P13: Glass (PJ/y) | Q13: Refineries (PJ/y) | R13: Fertilisers (PJ/y) | S13: Chemical (PJ/y) | T13: All sectors (PJ/y) | U13: Steel (PJ/y) | V13: Cement (PJ/y) | W13: Glass (PJ/y) | X13: Refineries (PJ/y) | Y13: Fertilisers (PJ/y) | Z13: Chemical (PJ/y)
A14: AT121 | B14: 3 | C14: AT | D14: Mostviertel-Eisenwurzen | E14: Mostviertel-Eisenwurzen | F14: 0 | I14: 0 | M14: 0 | P14: 0 | T14: 0 | W14: 0
A15: AT122 | B15: 3 | C15: AT | D15: Niederösterreich-Süd | E15: Niederösterreich-Süd | F15: 0 | H15: 0 | M15: 0 | O15: 0 | T15: 0 | V15: 0
A16: AT124 | B16: 3 | C16: AT | D16: Waldviertel | E16: Waldviertel | F16: 0 | L16: 0 | M16: 0 | S16: 0 | T16: 0 | Z16: 0
A17: AT127 | B17: 3 | C17: AT | D17: Wiener Umland/Südteil | E17: Wiener Umland/Südteil | F17: 0 | H17: 0 | J17: 0 | L17: 0 | M17: 48.929524 | O17: 0 | Q17: 40.193194 | S17: 8.7363299 | T17: 79.465586 | V17: 0 | X17: 50.941349 | Z17: 28.524237
A18: AT213 | B18: 3 | C18: AT | D18: Unterkärnten | E18: Unterkärnten | F18: 0 | H18: 0 | M18: 0 | O18: 0 | T18: 0 | V18: 0
A19: AT221 | B19: 3 | C19: AT | D19: Graz | E19: Graz | F19: 0 | G19: 0 | M19: 0 | N19: 0 | T19: 0 | U19: 0
A20: AT223 | B20: 3 | C20: AT | D20: Östliche Obersteiermark | E20: Östliche Obersteiermark | F20: 0 | G20: 0 | M20: 0 | N20: 0 | T20: 0 | U20: 0
A21: AT225 | B21: 3 | C21: AT | D21: West- und Südsteiermark | E21: West- und Südsteiermark | F21: 0 | H21: 0 | I21: 0 | M21: 0 | O21: 0 | P21: 0 | T21: 0 | V21: 0 | W21: 0
A22: AT312 | B22: 3 | C22: AT | D22: Linz-Wels | E22: Linz-Wels | F22: 0 | G22: 0 | K22: 0 | L22: 0 | M22: 0.23749138 | N22: 0 | R22: 0.23749138 | S22: 0 | T22: 0.77560869 | U22: 0 | Y22: 0.77560869 | Z22: 0
A23: AT314 | B23: 3 | C23: AT | D23: Steyr-Kirchdorf | E23: Steyr-Kirchdorf | F23: 0 | H23: 0 | I23: 0 | M23: 0 | O23: 0 | P23: 0 | T23: 0 | V23: 0 | W23: 0
A24: AT315 | B24: 3 | C24: AT | D24: Traunviertel | E24: Traunviertel | F24: 0 | H24: 0 | M24: 0 | O24: 0 | T24: 0 | V24: 0
A25: AT323 | B25: 3 | C25: AT | D25: Salzburg und Umgebung | E25: Salzburg und Umgebung | F25: 0 | H25: 0 | M25: 0 | O25: 0 | T25: 0 | V25: 0
A26: AT331 | B26: 3 | C26: AT | D26: Außerfern | E26: Außerfern | F26: 0 | H26: 0 | M26: 0 | O26: 0 | T26: 0 | V26: 0
A27: BE211 | B27: 3 | C27: BE | D27: Arr. Antwerpen | E27: Arr. Antwerpen | F27: 0 | J27: 0 | K27: 0 | L27: 0 | M27: 177.73776 | Q27: 161.18714 | R27: 0.34245333 | S27: 16.208163 | T27: 258.32884 | X27: 204.29056 | Y27: 1.1183975 | Z27: 52.919877
A28: BE213 | B28: 3 | C28: BE | D28: Arr. Turnhout | E28: Arr. Turnhout | F28: 0 | I28: 0 | L28: 0 | M28: 0 | P28: 0 | S28: 0 | T28: 0 | W28: 0 | Z28: 0
A29: BE224 | B29: 3 | C29: BE | D29: Arr. Hasselt | E29: Arr. Hasselt | F29: 0 | G29: 0 | L29: 0 | M29: 0 | N29: 0 | S29: 0 | T29: 0 | U29: 0 | Z29: 0
A30: BE233 | B30: 3 | C30: BE | D30: Arr. Eeklo | E30: Arr. Eeklo | F30: 0 | L30: 0 | M30: 0.25118162 | S30: 0.25118162 | T30: 0.82011144 | Z30: 0.82011144
A31: BE234 | B31: 3 | C31: BE | D31: Arr. Gent | E31: Arr. Gent | F31: 0 | G31: 0 | L31: 0 | M31: 0 | N31: 0 | S31: 0 | T31: 0 | U31: 0 | Z31: 0
A32: BE236 | B32: 3 | C32: BE | D32: Arr. Sint-Niklaas | E32: Arr. Sint-Niklaas | F32: 0 | L32: 0 | M32: 0 | S32: 0 | T32: 0 | Z32: 0
A33: BE255 | B33: 3 | C33: BE | D33: Arr. Oostende | E33: Arr. Oostende | F33: 0 | L33: 0 | M33: 0 | S33: 0 | T33: 0 | Z33: 0
A34: BE323 | B34: 3 | C34: BE | D34: Arr. Mons | E34: Arr. Mons | F34: 0 | H34: 0 | I34: 0 | K34: 0 | L34: 0 | M34: 0.42240828 | O34: 0 | P34: 0 | R34: 0.17122666 | S34: 0.25118162 | T34: 1.3793102 | V34: 0 | W34: 0 | Y34: 0.55919877 | Z34: 0.82011144
A35: BE328 | B35: 3 | C35: BE | D35: Arr. Tournai-Mouscron | E35: Arr. Tournai-Mouscron | F35: 0 | H35: 0 | M35: 0 | O35: 0 | T35: 0 | V35: 0
A36: BE32B | B36: 3 | C36: BE | D36: Arr. Charleroi | E36: Arr. Charleroi | F36: 0 | G36: 0 | M36: 0 | N36: 0 | T36: 0 | U36: 0
A37: BE32C | B37: 3 | C37: BE | D37: Arr. Soignies | E37: Arr. Soignies | F37: 0 | I37: 0 | L37: 0 | M37: 0 | P37: 0 | S37: 0 | T37: 0 | W37: 0 | Z37: 0
A38: BE32D | B38: 3 | C38: BE | D38: Arr. Thuin | E38: Arr. Thuin | F38: 0 | I38: 0 | M38: 0 | P38: 0 | T38: 0 | W38: 0
A39: BE332 | B39: 3 | C39: BE | D39: Arr. Liège | E39: Arr. Liège | F39: 0 | H39: 0 | M39: 0 | O39: 0 | T39: 0 | V39: 0
A40: BE335 | B40: 3 | C40: BE | D40: Arr. Verviers — communes francophones | E40: Arr. Verviers — communes francophones | F40: 0 | I40: 0 | M40: 0 | P40: 0 | T40: 0 | W40: 0
A41: BE352 | B41: 3 | C41: BE | D41: Arr. Namur | E41: Arr. Namur | F41: 0 | I41: 0 | L41: 0 | M41: 0 | P41: 0 | S41: 0 | T41: 0 | W41: 0 | Z41: 0
A42: BG313 | B42: 3 | C42: BG | D42: Vratsa | E42: Враца | F42: 0 | H42: 0 | M42: 0 | O42: 0 | T42: 0 | V42: 0
A43: BG314 | B43: 3 | C43: BG | D43: Pleven | E43: Плевен | F43: 0 | I43: 0 | M43: 0 | P43: 0 | T43: 0 | W43: 0
A44: BG315 | B44: 3 | C44: BG | D44: Lovech | E44: Ловеч | F44: 0 | H44: 0 | M44: 0 | O44: 0 | T44: 0 | V44: 0
A45: BG331 | B45: 3 | C45: BG | D45: Varna | E45: Варна | F45: 0 | H45: 0 | K45: 0 | M45: 0.173367 | O45: 0 | R45: 0.173367 | T45: 0.56618875 | V45: 0 | Y45: 0.56618875
A46: BG333 | B46: 3 | C46: BG | D46: Shumen | E46: Шумен | F46: 0 | I46: 0 | M46: 0 | P46: 0 | T46: 0 | W46: 0
A47: BG334 | B47: 3 | C47: BG | D47: Targovishte | E47: Търговище | F47: 0 | I47: 0 | M47: 0 | P47: 0 | T47: 0 | W47: 0
A48: BG341 | B48: 3 | C48: BG | D48: Burgas | E48: Бургас | F48: 0 | J48: 0 | M48: 40.607557 | Q48: 40.607557 | T48: 51.466517 | X48: 51.466517
A49: BG411 | B49: 3 | C49: BG | D49: Sofia (stolitsa) | E49: София (столица) | F49: 0 | I49: 0 | M49: 0 | P49: 0 | T49: 0 | W49: 0
A50: BG414 | B50: 3 | C50: BG | D50: Pernik | E50: Перник | F50: 0 | G50: 0 | M50: 0 | N50: 0 | T50: 0 | U50: 0
A51: BG421 | B51: 3 | C51: BG | D51: Plovdiv | E51: Пловдив | F51: 0 | I51: 0 | M51: 0 | P51: 0 | T51: 0 | W51: 0
...

Sheet Biomass waste (PJ per y)
F12: 2018 | M12: 2030 | T12: 2050
A13: NUTS ID | B13: NUTS LEVEL | C13: Country code | D13: NUTS region name (Latin) | E13: NUTS_NAME | F13: All sectors (PJ/y) | G13: Steel (PJ/y) | H13: Cement (PJ/y) | I13: Glass (PJ/y) | J13: Refineries (PJ/y) | K13: Fertilisers (PJ/y) | L13: Chemical (PJ/y) | M13: All sectors (PJ/y) | N13: Steel (PJ/y) | O13: Cement (PJ/y) | P13: Glass (PJ/y) | Q13: Refineries (PJ/y) | R13: Fertilisers (PJ/y) | S13: Chemical (PJ/y) | T13: All sectors (PJ/y) | U13: Steel (PJ/y) | V13: Cement (PJ/y) | W13: Glass (PJ/y) | X13: Refineries (PJ/y) | Y13: Fertilisers (PJ/y) | Z13: Chemical (PJ/y)
A14: AT121 | B14: 3 | C14: AT | D14: Mostviertel-Eisenwurzen | E14: Mostviertel-Eisenwurzen | F14: 0 | I14: 0 | M14: 0 | P14: 0 | T14: 0 | W14: 0
A15: AT122 | B15: 3 | C15: AT | D15: Niederösterreich-Süd | E15: Niederösterreich-Süd | F15: 0.19912983 | H15: 0.19912983 | M15: 0.27195413 | O15: 0.27195413 | T15: 0.71484749 | V15: 0.71484749
A16: AT124 | B16: 3 | C16: AT | D16: Waldviertel | E16: Waldviertel | F16: 0 | L16: 0 | M16: 0 | S16: 0 | T16: 0 | Z16: 0
A17: AT127 | B17: 3 | C17: AT | D17: Wiener Umland/Südteil | E17: Wiener Umland/Südteil | F17: 0.41313327 | H17: 0.41313327 | J17: 0 | L17: 0 | M17: 0.56422134 | O17: 0.56422134 | Q17: 0 | S17: 0 | T17: 1.4830891 | V17: 1.4830891 | X17: 0 | Z17: 0
A18: AT213 | B18: 3 | C18: AT | D18: Unterkärnten | E18: Unterkärnten | F18: 0.29879103 | H18: 0.29879103 | M18: 0.40806269 | O18: 0.40806269 | T18: 1.0726169 | V18: 1.0726169
A19: AT221 | B19: 3 | C19: AT | D19: Graz | E19: Graz | F19: 0 | G19: 0 | M19: 0 | N19: 0 | T19: 0 | U19: 0
A20: AT223 | B20: 3 | C20: AT | D20: Östliche Obersteiermark | E20: Östliche Obersteiermark | F20: 0 | G20: 0 | M20: 0 | N20: 0 | T20: 0 | U20: 0
A21: AT225 | B21: 3 | C21: AT | D21: West- und Südsteiermark | E21: West- und Südsteiermark | F21: 0.22165914 | H21: 0.22165914 | I21: 0 | M21: 0.30272269 | O21: 0.30272269 | P21: 0 | T21: 0.79572448 | V21: 0.79572448 | W21: 0
A22: AT312 | B22: 3 | C22: AT | D22: Linz-Wels | E22: Linz-Wels | F22: 0 | G22: 0 | K22: 0 | L22: 0 | M22: 0 | N22: 0 | R22: 0 | S22: 0 | T22: 0 | U22: 0 | Y22: 0 | Z22: 0
A23: AT314 | B23: 3 | C23: AT | D23: Steyr-Kirchdorf | E23: Steyr-Kirchdorf | F23: 0.15345904 | H23: 0.15345904 | I23: 0 | M23: 0.20958096 | O23: 0.20958096 | P23: 0 | T23: 0.55089594 | V23: 0.55089594 | W23: 0
A24: AT315 | B24: 3 | C24: AT | D24: Traunviertel | E24: Traunviertel | F24: 0.22399462 | H24: 0.22399462 | M24: 0.30591229 | O24: 0.30591229 | T24: 0.80410854 | V24: 0.80410854
A25: AT323 | B25: 3 | C25: AT | D25: Salzburg und Umgebung | E25: Salzburg und Umgebung | F25: 0.21210819 | H25: 0.21210819 | M25: 0.28967884 | O25: 0.28967884 | T25: 0.76143794 | V25: 0.76143794
A26: AT331 | B26: 3 | C26: AT | D26: Außerfern | E26: Außerfern | F26: 0.14636968 | H26: 0.14636968 | M26: 0.19989893 | O26: 0.19989893 | T26: 0.52544615 | V26: 0.52544615
A27: BE211 | B27: 3 | C27: BE | D27: Arr. Antwerpen | E27: Arr. Antwerpen | F27: 0 | J27: 0 | K27: 0 | L27: 0 | M27: 0 | Q27: 0 | R27: 0 | S27: 0 | T27: 0 | X27: 0 | Y27: 0 | Z27: 0
A28: BE213 | B28: 3 | C28: BE | D28: Arr. Turnhout | E28: Arr. Turnhout | F28: 0 | I28: 0 | L28: 0 | M28: 0 | P28: 0 | S28: 0 | T28: 0 | W28: 0 | Z28: 0
A29: BE224 | B29: 3 | C29: BE | D29: Arr. Hasselt | E29: Arr. Hasselt | F29: 0 | G29: 0 | L29: 0 | M29: 0 | N29: 0 | S29: 0 | T29: 0 | U29: 0 | Z29: 0
A30: BE233 | B30: 3 | C30: BE | D30: Arr. Eeklo | E30: Arr. Eeklo | F30: 0 | L30: 0 | M30: 0 | S30: 0 | T30: 0 | Z30: 0
A31: BE234 | B31: 3 | C31: BE | D31: Arr. Gent | E31: Arr. Gent | F31: 0 | G31: 0 | L31: 0 | M31: 0 | N31: 0 | S31: 0 | T31: 0 | U31: 0 | Z31: 0
A32: BE236 | B32: 3 | C32: BE | D32: Arr. Sint-Niklaas | E32: Arr. Sint-Niklaas | F32: 0 | L32: 0 | M32: 0 | S32: 0 | T32: 0 | Z32: 0
A33: BE255 | B33: 3 | C33: BE | D33: Arr. Oostende | E33: Arr. Oostende | F33: 0 | L33: 0 | M33: 0 | S33: 0 | T33: 0 | Z33: 0
A34: BE323 | B34: 3 | C34: BE | D34: Arr. Mons | E34: Arr. Mons | F34: 0.60949 | H34: 0.60949 | I34: 0 | K34: 0 | L34: 0 | M34: 0.83238821 | O34: 0.83238821 | P34: 0 | R34: 0 | S34: 0 | T34: 2.1879816 | V34: 2.1879816 | W34: 0 | Y34: 0 | Z34: 0
A35: BE328 | B35: 3 | C35: BE | D35: Arr. Tournai-Mouscron | E35: Arr. Tournai-Mouscron | F35: 1.160203 | H35: 1.160203 | M35: 1.5845039 | O35: 1.5845039 | T35: 4.1649622 | V35: 4.1649622
A36: BE32B | B36: 3 | C36: BE | D36: Arr. Charleroi | E36: Arr. Charleroi | F36: 0 | G36: 0 | M36: 0 | N36: 0 | T36: 0 | U36: 0
A37: BE32C | B37: 3 | C37: BE | D37: Arr. Soignies | E37: Arr. Soignies | F37: 0 | I37: 0 | L37: 0 | M37: 0 | P37: 0 | S37: 0 | T37: 0 | W37: 0 | Z37: 0
A38: BE32D | B38: 3 | C38: BE | D38: Arr. Thuin | E38: Arr. Thuin | F38: 0 | I38: 0 | M38: 0 | P38: 0 | T38: 0 | W38: 0
