Workbook
Name rng_VBA_Formats: OFFSET([5]VBA!$K$21, 0, 0, [5]VBA!$C$19)
Name rng_VBA_LineStyles: OFFSET([5]VBA!$L$21, 0, 0, [5]VBA!$C$19)
Name rng_VBA_Names: OFFSET([5]VBA!$B$21:$I$21, 0, 0, [5]VBA!$C$19)

Sheet COVER
C4: Dataset | E4: 1H 2022 LCOE Update - Charts
C8: Date | E8: 44742
C10: Contact | E10: Amar Vasdev Tifenn Brandily
E11: Bloomberg Terminal: press <Help> key twice
E12: support.bnef@bloomberg.net
C14: Description | E14: This spreadsheet contains data and charts from the 1H 2022 LCOE update.
C16: Contents
C17: Global LCOE benchmarks | E17: Global LCOE benchmarks
C18: Key messages -->
C19: Global LCOEs by tech | E19: Global LCOEs by technology
C20: Turbine prices | E20: Regional onshore wind turbine prices by signing date (USD)
C21: Global wind LCOE benchmarks | E21: Global onshore and offshore wind LCOE benchmarks with and without China, 1H 2021-2022
C22: PV cost inflation | E22: PV cost inflation
C23: Onshore wind cost inflation | E23: Onshore wind cost inflation
C24: Battery costs | E24: Energy storage project costs 2021, based on usable capacity
C25: Storage LCOE | E25: Storage LCOE 1H 2021 versus 1H 2022
C26: Coal & gas cost inflation | E26: Coal & gas cost inflation
C27: Key long-term trends ->
C28: PV mono vs multi panels | E28: Mono vs multi share
C29: PV bifacial vs monofacial | E29: Share of bifacial module among all silicon PV
C30: Project size, Utility-scale PV | E30: Project size, Utility-scale PV
C31: Turbine size, Onshore wind | E31: Turbine size, Onshore wind
C32: Project size, Onshore wind | E32: Project size, Onshore wind
C33: Onshore wind capacity factors | E33: Onshore wind capacity factors, global
C34: Turbine Size, Offshore wind | E34: Turbine size, offshore wind
C35: Project size, Offshore wind | E35: Project size, Offshore wind
C36: Battery storage characteristics | E36: Battery storage project characteristics, global
C37: APAC spotlight -->
C38: Central bank base rates | E38: Central bank base rates
C39: PV module imports, India | E39: PV module imports, India
C40: Onshore wind in Vietnam | E40: Onshore wind in Vietnam
C41: Dollar exchange rate | E41: Dollar exchange rate
C42: Appendix ->
C43: Carbon Prices | E43: Carbon price forecast
C44: Coal Prices | E44: Coal price forecasts
C45: Oil Prices | E45: Brent price forecasts
C46: Gas prices | E46: Natural gas prices forecasts. 1H 2022
C47: PV Capex | E47: PV capex forecasts 2021-50, select countries
C48: PV module price | E48: PV module price
C49: Onshore wind capex | E49: Onshore wind capex
...

Sheet Global LCOE benchmarks
F1: Global LCOE benchmarks
A3: Dataset | B3: Global LCOE benchmarks
A4: Units | B4: $/MWh, nominal
A5: Source | B5: BloombergNEF
A6: Subject to terms and conditions
B41: LCOE
B42: $/MWh, nominal
B43: Technology | C43: 2009 | D43: 2010 | F43: 2011 | H43: 2012 | J43: 2013 | L43: 2014 | N43: 2015 | P43: 2016 | R43: 2017 | T43: 2018 | V43: 2019 | X43: 2020 | Z43: 2021 | AB43: 2022
C44: 2H | D44: 1H | E44: 2H | F44: 1H | G44: 2H | H44: 1H | I44: 2H | J44: 1H | K44: 2H | L44: 1H | M44: 2H | N44: 1H | O44: 2H | P44: 1H | Q44: 2H | R44: 1H | S44: 2H | T44: 1H | U44: 2H | V44: 1H | W44: 2H | X44: 1H | Y44: 2H | Z44: 1H | AA44: 2H | AB44: 1H
B45: Onshore wind | C45: 92.935 | D45: 85.74 | E45: 87.815 | F45: 85.795 | G45: 78.45 | H45: 78.185 | I45: 82.43 | J45: 79.72 | K45: #N/A | L45: 81.8 | M45: 81.96 | N45: 85.482938 | O45: 82.522439 | P45: 81.155008 | Q45: 68.197511 | R45: 67.500013 | S45: #N/A | T45: 55.578615 | U45: 52.298475 | V45: 50.623614 | W45: 48.20022 | X45: 46.044489 | Y45: 42.324922 | Z45: 43.044772 | AA45: 45.229307 | AB45: 45.921197
B46: Offshore wind | C46: 159.82 | D46: 176.96 | E46: 180.29 | F46: 186.685 | G46: 213.71 | H46: 226.835 | I46: 219.12 | J46: 215.415 | K46: #N/A | L46: 212 | M46: 203.08 | N46: 175.66629 | O46: 174.12551 | P46: 160.80905 | Q46: 126.20742 | R46: 123.87 | S46: #N/A | T46: 117.53773 | U46: 114.8365 | V46: 91.141152 | W46: 79.975058 | X46: 83.99342 | Y46: 86.603173 | Z46: 89.630816 | AA46: 91.607388 | AB46: 86.466617
B47: Fixed-axis PV | C47: 303.6 | D47: 303.925 | E47: 278.09 | F47: 239.825 | G47: 198.685 | H47: 176.185 | I47: 164.145 | J47: 136.2 | K47: #N/A | L47: 149 | M47: 142.86452 | N47: 128.50676 | O47: 122.03676 | P47: 99.383707 | Q47: 100.71087 | R47: 85.6 | S47: #N/A | T47: 69.652024 | U47: 60 | V47: 58.297716 | W47: 51.651356 | X47: 52.022032 | Y47: 44.453278 | Z47: 40.060758 | AA47: 44.652919 | AB47: 45.454075
B48: Tracking PV | C48: 291.46 | D48: 283.08 | E48: 241.245 | F48: 224.175 | G48: 164.74 | H48: 154.775 | I48: 133.645 | J48: 123.67 | K48: #N/A | L48: 147.92 | M48: 142.2 | N48: 138.79148 | O48: 133.03751 | P48: 106.12507 | Q48: 83.181289 | R48: 55.5 | S48: #N/A | T48: 49 | U48: 46 | V48: 51.736311 | W48: 47.183326 | X48: 40.868281 | Y48: 40.555389 | Z48: 38.697029 | AA48: 41.402367 | AB48: 40.118476
B49: Battery storage (4 hours) | T49: 288.17458 | U49: 193.25677 | V49: 190.99739 | W49: 194.44511 | X49: 157.5803 | Y49: 139.03601 | Z49: 141.18206 | AA49: 141.15952 | AB49: 153
B50: Battery storage (4 hours, implied by historic battery pack prices) | I50: 720.89288 | J50: 706.11527 | K50: 691.33765 | L50: 607.04555 | M50: 522.75345 | N50: 531.39315 | O50: 540.03285 | P50: 501.62833 | Q50: 463.22381 | R50: 383.39901 | S50: 303.57422 | T50: 288.17458
B51: Coal | L51: 84.705638 | M51: 77.019444 | N51: 77.114352 | O51: 86.593863 | P51: 70.672659 | Q51: 69.374037 | R51: 71.32419 | S51: 69.195069 | T51: 60.460641 | U51: 62.309705 | V51: 69.724707 | W51: 69.924135 | X51: 75.055211 | Y51: 76.600519 | Z51: 67.477761 | AA51: 67.792696 | AB51: 73.718419
B52: Gas | L52: 68.560469 | M52: 48.452659 | N52: 42.503103 | O52: 47.973337 | P52: 46.289953 | Q52: 51.586443 | R52: 50.504901 | S52: 53.015845 | T52: 56.834729 | U52: 58.463014 | V52: 60.782486 | W52: 61.13457 | X52: 65.457232 | Y52: 64.732833 | Z52: 74.020084 | AA52: 77.28105 | AB52: 80.935848
B53: The global benchmark is a country weighted-average using the latest annual capacity additions. The storage LCOE is reflective of a utility-scale Li-ion battery storage system with four-hour duration running at a daily cycle and includes charging costs assumed to be 60% of wholesale average power price.
B54: All LCOEs calculations are unsubsidized. In 2H 2017, BNEF did not publish any update. Dashed pink lines reflects derived LCOEs based on historic battery pack prices. Continuous pink line reflects collected project data from 2018.
B55: For hydrogen-fired power, coal- and gas-fired power with carbon capture and storage (CCS), the global LCOE benchmark is a simple country average including China, Europe, U.S., Japan and India

Sheet Key messages -->
F1: Key messages

Sheet Global LCOEs by tech
F1: Global LCOEs by technology
A3: Dataset | B3: Global LCOEs by technology
A4: Units | B4: $/MWh (nominal)
A5: Source | B5: BNEF LCOE analysis
A6: Subject to terms and conditions
B28: Global LCOEs
B29: $/MWh (nominal at COD)
B30: Technology | D30: Wind onshore | F30: Wind offshore | H30: PV fixed-axis | J30: PV tracking | L30: Utility-scale battery (4h) | N30: CCGT | P30: Coal
B31: Metric | C31: LCOE Scenario | D31: 2021 | E31: 2022 | F31: =D31 -> 2021 | G31: =E31 -> 2022 | H31: =F31 -> 2021 | I31: =G31 -> 2022 | J31: =H31 -> 2021 | K31: =I31 -> 2022 | L31: =J31 -> 2021 | M31: =K31 -> 2022 | ... Q31: =O31 -> 2022
B32: Min | C32: Low | D32: 17.593589 | E32: 18.922491 | F32: 53.329309 | G32: 57.154351 | H32: 22.41187 | I32: 25.299621 | J32: 22.696487 | K32: 21.282783 | L32: 119.89393 | M32: 108.36698 | N32: 33.699347 | O32: 43.466924 | P32: 40.759872 | Q32: 40.378554
B33: Simple average | C33: Low | D33: 47.306838 | E33: 49.041682 | F33: 81.210233 | G33: 86.345804 | H33: 57.901679 | I33: 57.106946 | J33: 35.041232 | K33: 36.118683 | L33: 135.85286 | M33: 144.36641 | N33: 70.532537 | O33: 84.339597 | P33: 83.901587 | Q33: 107.45067
B34: Median | C34: Low | D34: 39.585223 | E34: 40.902154 | F34: 76.723956 | G34: 77.612333 | H34: 51.532683 | I34: 48.774367 | J34: 32.034375 | K34: 34.256131 | L34: 133.97924 | M34: 124.59196 | N34: 72.712819 | O34: 83.847824 | P34: 62.446955 | Q34: 72.014091
B35: Max | C35: Low | D35: 93.204692 | E35: 102.06594 | F35: 139.68705 | G35: 142.12143 | H35: 129.35469 | I35: 141.15859 | J35: 46.025423 | K35: 46.404411 | L35: 154.79473 | M35: 283.62186 | N35: 102.84608 | O35: 134.94218 | P35: 185.09707 | Q35: 288.00888
B36: Min | C36: Mid | D36: 22.584514 | E36: 26.958404 | F36: 72.248758 | G36: 72.763221 | H36: 26.967734 | I36: 33.39796 | J36: 34.794014 | K36: 31.220805 | L36: 124.97653 | M36: 114.60423 | N36: 39.788132 | O36: 51.943866 | P36: 58.431315 | Q36: 58.511562
B37: Simple average | C37: Mid | D37: 63.439389 | E37: 67.873123 | F37: 102.05275 | G37: 106.06245 | H37: 77.227838 | I37: 75.541265 | J37: 44.035811 | K37: 45.688068 | L37: 147.43981 | M37: 164.56094 | N37: 78.844632 | O37: 93.205792 | P37: 96.485302 | Q37: 121.5687
B38: Median | C38: Mid | D38: 52.994482 | E38: 55.283492 | F38: 96.345351 | G38: 93.037533 | H38: 69.430475 | I38: 65.37159 | J38: 43.136494 | K38: 44.849185 | L38: 147.68108 | M38: 139.83523 | N38: 83.11176 | O38: 90.571553 | P38: 74.304999 | Q38: 86.532603
B39: Max | C39: Mid | D39: 131.33515 | E39: 135.57757 | F39: 185.12159 | G39: 178.80894 | H39: 163.91466 | I39: 169.34483 | J39: 58.223872 | K39: 62.796677 | L39: 168.81713 | M39: 344.23484 | N39: 109.06836 | O39: 140.83799 | P39: 196.64769 | Q39: 294.9857
B40: Min | C40: High | D40: 32.836234 | E40: 40.057177 | F40: 79.432097 | G40: 76.518422 | H40: 37.314825 | I40: 46.642706 | J40: 38.290833 | K40: 42.594219 | L40: 129.44149 | M40: 135.69561 | N40: 56.102944 | O40: 74.490674 | P40: 70.682451 | Q40: 71.059256
B41: Simple average | C41: High | D41: 87.502403 | E41: 95.369567 | F41: 123.19217 | G41: 128.07264 | H41: 103.03873 | I41: 99.782823 | J41: 55.505969 | K41: 57.474429 | L41: 165.52231 | M41: 222.1413 | N41: 90.817847 | O41: 109.17748 | P41: 122.48334 | Q41: 149.63248
B42: Median | C42: High | D42: 70.721285 | E42: 72.44604 | F42: 111.46328 | G42: 110.39099 | H42: 99.666898 | I42: 96.6114 | J42: 54.288122 | K42: 53.294717 | L42: 163.02868 | M42: 162.21479 | N42: 94.859066 | O42: 104.35774 | P42: 99.789515 | Q42: 122.03913
B43: Max | C43: High | D43: 200.30183 | E43: 205.17723 | F43: 237.4241 | G43: 220.96386 | H43: 218.05711 | I43: 221.98864 | J43: 75.343357 | K43: 83.333923 | L43: 216.91337 | M43: 632.55055 | N43: 119.7984 | O43: 160.24977 | P43: 215.10723 | Q43: 303.23103
B44: Global weighted average | D44: 43.044772 | E44: 45.921197 | F44: 89.630816 | G44: 86.466617 | H44: 40.060758 | I44: 45.454075 | J44: 38.697029 | K44: 40.118476 | L44: 141.18206 | M44: 153 | N44: 74.020084 | O44: 80.935848 | P44: 67.477761 | Q44: 73.718419
B47: For charting purposes
D48: Onshore wind | F48: Offshore wind | H48: Fixed-axis PV | J48: Tracking PV | L48: Battery storage | N48: Gas | P48: Coal
D49: 2021 | E49: 2022 | F49: 2021 | G49: 2022 | H49: =F49 -> 2021 | I49: =G49 -> 2022 | J49: =H49 -> 2021 | K49: =I49 -> 2022 | L49: 2021 | M49: =K49 -> 2022 | N49: =L49 -> 2021 | O49: =M49 -> 2022 | P49: =N49 -> 2021 | Q49: =O49 -> 2022
B50: Low | D50: 17.593589 | E50: 18.922491 | F50: 53.329309 | G50: 57.154351 | H50: 22.41187 | I50: 25.299621 | J50: 22.696487 | K50: 22.696487 | L50: 119.89393 | M50: 108.36698 | N50: 33.699347 | O50: 43.466924 | P50: 40.759872 | Q50: 40.378554
B51: Low - Min Mid | D51: 4.9909252 | E51: 8.035913 | F51: 18.919449 | G51: 15.60887 | H51: 4.5558636 | I51: 8.0983383 | J51: 12.097527 | K51: 12.097527 | L51: 5.0826075 | M51: 6.2372532 | N51: 6.0887847 | O51: 8.4769419 | P51: 17.671444 | Q51: 18.133008
B52: Min Mid - Max Mid | D52: 108.75063 | E52: 108.61917 | F52: 112.87283 | G52: 106.04572 | H52: 136.94693 | I52: 135.94687 | J52: 23.429858 | K52: 23.429858 | L52: 43.840593 | M52: 229.6306 | N52: 69.280226 | O52: 88.894125 | P52: 138.21638 | Q52: 236.47413
B53: Max Mid - Max High | D53: 68.966683 | E53: 69.599652 | F53: 52.302518 | G53: 42.154924 | H53: 54.142441 | I53: 52.643819 | J53: 17.119485 | K53: 17.119485 | L53: 48.096247 | M53: 288.31572 | N53: 10.730046 | O53: 19.411778 | P53: 18.45954 | Q53: 8.2453299
B54: Global weighted average | D54: 43.044772 | E54: 45.921197 | F54: 89.630816 | G54: 86.466617 | H54: 40.060758 | I54: 45.454075 | J54: 38.697029 | K54: 40.118476 | L54: 141.18206 | M54: 153 | N54: 74.020084 | O54: 80.935848 | P54: 67.477761 | Q54: 73.718419
B55: Median mid | D55: 52.994482 | E55: 55.283492 | F55: 96.345351 | G55: 93.037533 | H55: 69.430475 | I55: 65.37159 | J55: 43.136494 | K55: 43.136494 | L55: 147.68108 | M55: 139.83523 | N55: 83.11176 | O55: 90.571553 | P55: 74.304999 | Q55: 86.532603
B56: Label top | D56: 50 | E56: 50 | F56: 50 | G56: 50 | H56: 50 | I56: 50 | J56: 50 | K56: 50 | L56: 50 | M56: 50 | N56: 50 | O56: 50 | P56: 50 | Q56: 50

Sheet Turbine prices
F1: Regional turbine prices (signing date-USD)
A3: Dataset | B3: Regional onshore wind turbine prices by signing date (USD)
A4: Units | B4: $m/MW (nominal)
A5: Source | B5: BloombergNEF
A6: Subject to terms and conditions
B29: Regional pricing by signing date
B30: $m/MW (nominal) | C30: 2008 | E30: 2009 | G30: 2010 | I30: 2011 | K30: 2012 | M30: 2013 | O30: 2014 | Q30: 2015 | S30: 2016 | U30: 2017 | W30: 2018 | Y30: 2019 | AA30: 2020 | AC30: 2021
C31: 1H | D31: 2H | E31: 1H | F31: 2H | G31: 1H | H31: 2H | I31: 1H | J31: 2H | K31: 1H | L31: 2H | M31: 1H | N31: 2H | O31: 1H | P31: 2H | Q31: 1H | R31: 2H | S31: 1H | T31: 2H | U31: 1H | V31: 2H | W31: 1H | X31: 2H | Y31: 1H | Z31: 2H | AA31: 1H | AB31: 2H | AC31: 1H | AD31: 2H
B32: AMER | C32: 1.9498981 | D32: 1.9346063 | E32: #N/A | F32: 1.3894109 | G32: 1.4099183 | H32: 1.2178937 | I32: 1.34274 | J32: 1.0813504 | K32: 1.0629152 | L32: 1.1412846 | M32: 1.1142587 | N32: 1.0624285 | O32: 1.378459 | P32: 1.2553159 | Q32: 1.0257398 | R32: 1.0953395 | S32: 1.0509426 | T32: 0.88670301 | U32: 0.78273962 | V32: 1.021752 | W32: 0.73869956 | X32: 0.66167737 | Y32: 0.7623967 | Z32: 0.67855264 | AA32: 0.61926064 | AB32: 0.63386288 | AC32: 0.6292304 | AD32: 0.77048914
B33: EMEA | C33: 1.7459447 | D33: 1.6707643 | E33: 1.5273692 | F33: 1.5182688 | G33: 1.385131 | H33: 1.2967784 | I33: 1.3285733 | J33: 1.3155268 | K33: 1.1563285 | L33: 1.201144 | M33: 1.1051631 | N33: 1.1569821 | O33: 1.1738606 | P33: 1.1251409 | Q33: 0.96460524 | R33: 0.87643068 | S33: 0.88077838 | T33: 0.9114014 | U33: 0.91225546 | V33: 0.79636404 | W33: 0.78887567 | X33: 0.79016106 | Y33: 0.76294586 | Z33: 0.74329817 | AA33: 0.80786727 | AB33: 0.88351499 | AC33: 0.90216994 | AD33: 1.047693
B34: China | C34: 1.1583478 | D34: 1.1583478 | E34: 0.96110997 | F34: 0.96110997 | G34: 0.88950114 | H34: 0.78549217 | I34: 0.7369429 | J34: 0.74477439 | K34: 0.78550876 | L34: 0.79032414 | M34: 0.8086732 | N34: 0.84513146 | O34: 0.85520518 | P34: 0.83076488 | Q34: 0.8466611 | R34: 0.83819449 | S34: 0.78069037 | T34: 0.78069037 | U34: 0.73083374 | V34: 0.70272475 | W34: 0.64045345 | X34: 0.65001246 | Y34: 0.6329407 | Z34: 0.66684311 | AA34: 0.69877905 | AB34: 0.61022024 | AC34: 0.52187291 | AD34: 0.47051332
B35: Global average | C35: 1.7544428 | D35: 1.6800254 | E35: 1.5211911 | F35: 1.4683883 | G35: 1.3335079 | H35: 1.2633795 | I35: 1.3629074 | J35: 1.2407897 | K35: 1.1190139 | L35: 1.1860689 | M35: 1.1078382 | N35: 1.107454 | O35: 1.2633724 | P35: 1.1685326 | Q35: 0.99517251 | R35: 0.99430467 | S35: 0.92331944 | T35: 0.90570177 | U35: 0.81667063 | V35: 0.89376207 | W35: 0.77940623 | X35: 0.74651455 | Y35: 0.76278896 | Z35: 0.7187478 | AA35: 0.78271972 | AB35: 0.8169411 | AC35: 0.85162558 | AD35: 0.93355025

Sheet Commodity & Labor prices
F1: Commodity, labor and freight prices
A3: Dataset | B3: Commodity, labor and freight price index, 2019-2022
A4: Units | B4: January 2019 = 100%
A5: Source | B5: Bloomberg Terminal, Third Party Data Providers
A6: Subject to terms and conditions
B39: Commodity, labor and freight price indexes (100% = January 2019)
D40: Date | E40: Copper | F40: Cobalt | G40: Lithium | H40: Nickel | I40: Zinc | J40: Chromium | K40: Molybdene | L40: Aluminum | M40: Steel | N40: Cement | O40: Coal | P40: Natural gas | Q40: Freight from Asia | R40: Oil | S40: Labor (US)
B41: 2019 | C41: J | D41: 43480 | E41: 1 | F41: 1 | G41: 1 | H41: 1 | I41: 1 | J41: 1 | K41: 1 | L41: 1 | M41: 1 | N41: 1 | O41: 1 | P41: 1 | Q41: 1 | R41: 1 | S41: 1
D42: 43511 | E42: 1.123877 | F42: 0.78860972 | G42: 1.0031579 | H42: 1.1017049 | I42: 1.0583304 | J42: 1.0222698 | K42: 1.0186154 | L42: 1.0111459 | M42: 1.015873 | N42: 0.99762564 | O42: 0.96967375 | P42: 0.83492418 | Q42: 0.88845406 | R42: 1.0695639 | S42: 1
C43: M | D43: 43539 | E43: 1.226528 | F43: 0.7697748 | G43: 0.99157895 | H43: 1.1321233 | I43: 1.1041615 | J43: 1.0204752 | K43: 1.0393894 | L43: 1.0148383 | M43: 1.0335097 | N43: 0.99406411 | O43: 0.9565719 | P43: 0.7250822 | Q43: 0.76478412 | R43: 1.1126595 | S43: 1.043106
D44: 43570 | E44: 1.3030545 | F44: 0.82300391 | G44: 0.96842105 | H44: 1.1095907 | I44: 1.1162381 | J44: 1.0167024 | K44: 1.0389128 | L44: 0.9987087 | M44: 1.0186949 | N44: 1.0114761 | O44: 0.83997483 | P44: 0.6942386 | Q44: 0.68127174 | R44: 1.1890354 | S44: 1.043106
C45: M | D45: 43600 | E45: 1.1610136 | F45: 0.8393821 | G45: 0.95368421 | H45: 1.0393195 | I45: 1.024875 | J45: 0.98255674 | K45: 1.0118998 | L45: 0.96911615 | M45: 0.89770723 | N45: 1.0213692 | O45: 0.8580298 | P45: 0.60722465 | Q45: 0.75025578 | R45: 1.1670316 | S45: 1.043106
D46: 43631 | E46: 1.1737255 | F46: 0.70775879 | G46: 0.93684211 | H46: 1.0371725 | I46: 0.97497168 | J46: 0.82932041 | K46: 0.99347955 | L46: 0.9547435 | M46: 0.7989418 | N46: 1.0197863 | O46: 0.7252237 | P46: 0.48603409 | Q46: 0.75864539 | R46: 1.0464318 | S46: 1.043106
C47: J | D47: 43661 | E47: 1.2153748 | F47: 0.67167747 | G47: 0.84421053 | H47: 1.1740052 | I47: 0.95698245 | J47: 0.76734754 | K47: 0.99643845 | L47: 0.97429827 | M47: 0.8042328 | N47: 1.0110803 | O47: 0.74217888 | P47: 0.50154177 | Q47: 0.69431655 | R47: 1.0659664 | S47: 1.043106
D48: 43692 | E48: 1.1530806 | F48: 0.74037361 | G48: 0.75157895 | H48: 1.3574652 | I48: 0.89395181 | J48: 0.7490364 | K48: 0.99581357 | L48: 0.94795084 | M48: 0.86243386 | N48: 1.0106846 | O48: 0.67432203 | P48: 0.45764015 | Q48: 0.82259055 | R48: 0.98773108 | S48: 1.043106
C49: S | D49: 43723 | E49: 1.1957461 | F49: 0.8775538 | G49: 0.71578947 | H49: 1.515646 | I49: 0.91032305 | J49: 0.73787895 | K49: 0.98815205 | L49: 0.95268116 | M49: 0.81128748 | N49: 1.0110803 | O49: 0.66518738 | P49: 0.43181446 | Q49: 0.71196542 | R49: 1.0339675 | S49: 1.043106
D50: 43753 | E50: 1.1992344 | F50: 0.86631816 | G50: 0.69894737 | H50: 1.4643959 | I50: 0.94860426 | J50: 0.73192832 | K50: 0.98894734 | L50: 0.92841922 | M50: 0.73015873 | N50: 1.0106846 | O50: 0.67531936 | P50: 0.46276848 | Q50: 0.64927358 | R50: 0.98989499 | S50: 1.043106
C51: N | D51: 43784 | E51: 1.2157648 | F51: 0.87238824 | G51: 0.66947368 | H51: 1.3111167 | I51: 0.93803828 | J51: 0.72570613 | K51: 0.94986169 | L51: 0.94653557 | M51: 0.75132275 | N51: 1.0094974 | O51: 0.67809454 | P51: 0.66086764 | Q51: 0.82796194 | R51: 1.040979 | S51: 1.043106
D52: 43814 | E52: 1.2321495 | F52: 0.82416993 | G52: 0.63157895 | H52: 1.1990151 | I52: 0.89000384 | J52: 0.71948608 | K52: 0.94910344 | L52: 0.95419461 | M52: 0.80987654 | N52: 1.0091017 | O52: 0.67201351 | P52: 0.59969982 | Q52: 0.94604732 | R52: 1.0818862 | S52: 1.043106
B53: 2020 | C53: J | D53: 43845 | E53: 1.3073843 | F53: 0.79138638 | G53: 0.59789474 | H53: 1.1728272 | I53: 0.91857323 | J53: 0.70255532 | K53: 0.96406096 | L53: 0.96006816 | M53: 0.86772487 | N53: 1.0059359 | O53: 0.6970128 | P53: 0.50444537 | Q53: 1.1314713 | R53: 1.0569682 | S53: 1.043106
D54: 43876 | E54: 1.2423566 | F54: 0.82403758 | G54: #VALUE! | H54: 1.1047911 | I54: 0.83315583 | J54: 0.69321199 | K54: 0.95362824 | L54: 0.91741861 | M54: 0.86772487 | N54: 1.0053423 | O54: 0.69049695 | P54: 0.41791808 | Q54: 1.0043227 | R54: 0.92092734 | S54: 1.043106
C55: M | D55: 43905 | E55: 1.1938166 | F55: 0.76451033 | G55: 0.57263158 | H55: 1.0283579 | I55: 0.75245511 | J55: 0.6875803 | K55: 0.92691415 | L55: 0.87477636 | M55: 0.87195767 | N55: 1.0047487 | O55: 0.66854036 | P55: 0.38873485 | Q55: 0.88615204 | R55: 0.55990342 | S55: 1.0818251
D56: 43936 | E56: 1.1726584 | F56: 0.72633166 | G56: 0.54947368 | H56: 1.0247071 | I56: 0.75102352 | J56: 0.67922912 | K56: 0.87318218 | L56: 0.80169537 | M56: 0.76190476 | N56: 1.0178077 | O56: 0.61384717 | P56: 0.28769364 | Q56: 0.76253325 | R56: 0.44208212 | S56: 1.0818251
C57: M | D57: 43966 | E57: 1.198862 | F57: 0.7262725 | G57: 0.52631579 | H57: 1.057194 | I57: 0.7751005 | J57: 0.67192606 | K57: 0.86863021 | L57: 0.80237391 | M57: 0.68289242 | N57: 1.0138504 | O57: 0.5215021 | P57: 0.20213967 | Q57: 0.81811439 | R57: 0.53803811 | S57: 1.0818251
D58: 43997 | E58: 1.2435698 | F58: 0.7142775 | G58: 0.50947368 | H58: 1.1040377 | I58: 0.79750787 | J58: 0.65728561 | K58: 0.87170767 | L58: 0.85178604 | M58: 0.73368607 | N58: 1.0225564 | O58: 0.54237599 | P58: 0.22994062 | Q58: 0.88640782 | R58: 0.67682789 | S58: 1.0818251
C59: J | D59: 44027 | E59: 1.4426973 | F59: 0.70058568 | G59: 0.49263158 | H59: 1.1609062 | I59: 0.85815049 | J59: 0.6169258 | K59: 0.88099437 | L59: 0.89824452 | M59: 0.68994709 | N59: 1.0277008 | O59: 0.52726544 | P59: 0.22738463 | Q59: 0.93083691 | R59: 0.71748874 | S59: 1.0818251
D60: 44058 | E60: 1.4923125 | F60: 0.80849447 | G60: 0.50105263 | H60: 1.2588472 | I60: 0.9533765 | J60: 0.60972775 | K60: 0.90397649 | L60: 0.95027201 | M60: 0.68606702 | N60: 1.0273051 | O60: 0.50953233 | P60: 0.36626671 | Q60: 0.95316656 | R60: 0.74733268 | S60: 1.0818251
C61: S | D61: 44089 | E61: 1.4936167 | F61: 0.82256421 | G61: 0.50105263 | H61: 1.2863096 | I61: 0.96693515 | J61: 0.60513919 | K61: 0.9243282 | L61: 0.95388547 | M61: 0.75485009 | N61: 1.0280966 | O61: 0.52503097 | P61: 0.53947261 | Q61: 1.1341314 | R61: 0.695103 | S61: 1.0818251
D62: 44119 | E62: 1.5485082 | F62: 0.81631854 | G62: 0.50526316 | H62: 1.3189523 | I62: 0.96382222 | J62: 0.60519628 | K62: 0.93939192 | L62: 0.97601168 | M62: 0.92416226 | N62: 1.0277008 | O62: 0.58014041 | P62: 0.67374573 | Q62: 1.1285042 | R62: 0.68930054 | S62: 1.0818251
C63: N | D63: 44150 | E63: 1.6196411 | F63: 0.79202164 | G63: 0.51368421 | H63: 1.3683381 | I63: 1.053506 | J63: 0.60770878 | K63: 0.95320589 | L63: 1.0435262 | M63: 1.021164 | N63: 1.0269094 | O63: 0.63319589 | P63: 0.66818799 | Q63: 1.424954 | R63: 0.73006866 | S63: 1.0818251
D64: 44180 | E64: 1.6728243 | F64: 0.78326107 | G64: 0.56421053 | H64: 1.4571216 | I64: 1.1010125 | J64: 0.61917884 | K64: 0.96289765 | L64: 1.0852703 | M64: 1.2380952 | N64: 1.0273051 | O64: 0.78993255 | P64: 0.81098788 | Q64: 2.9480254 | R64: 0.83362258 | S64: 1.0818251
B65: 2021 | C65: J | D65: 44211 | E65: 1.8463988 | F65: 0.93070134 | G65: 0.79578947 | H65: 1.5461982 | I65: 1.0710167 | J65: 0.64704497 | K65: 0.98583284 | L65: 1.0737333 | M65: 1.4998236 | N65: 1.0306688 | O65: 0.85719038 | P65: 1.01963 | Q65: 4.5404901 | R65: 0.91833773 | S65: 1.0818251
D66: 44242 | E66: 1.875815 | F66: 1.16735 | G66: 0.94736842 | H66: 1.6079596 | I66: 1.0841249 | J66: 0.66329764 | K66: 1.0115936 | L66: 1.1164133 | M66: 1.6666667 | N66: 1.0340324 | O66: 0.86887533 | P66: 0.86188268 | Q66: 4.3595253 | R66: 1.0338738 | S66: 1.0818251
C67: M | D67: 44270 | E67: 1.7123762 | F67: 1.287686 | G67: 1.0821053 | H67: 1.4202349 | I67: 1.1025685 | J67: 0.68779443 | K67: 1.0579604 | L67: 1.1841475 | M67: 1.8077601 | N67: 1.0472893 | O67: 0.91769994 | P67: 0.8650153 | Q67: 4.02522 | R67: 1.0906571 | S67: 1.1492812
D68: 44301 | E68: 1.6969876 | F68: 1.2043053 | G68: 1.1536842 | H68: 1.4297669 | I68: 1.1176608 | J68: 0.71156316 | K68: 1.0418396 | L68: 1.2471174 | M68: 1.9611993 | N68: 1.0605461 | O68: 0.94784695 | P68: 1.0210777 | Q68: 3.9615306 | R68: 1.0844553 | S68: 1.1492812
C69: M | D69: 44331 | E69: 1.7518954 | F69: 1.0870143 | G69: 1.1768421 | H69: 1.5199748 | I69: 1.1701127 | J69: 0.77135129 | K69: 1.0946626 | L69: 1.3142771 | M69: 2.1287478 | N69: 1.0613376 | O69: 1.013897 | P69: 1.2537992 | Q69: 4.7813076 | R69: 1.1339312 | S69: 1.1492812
D70: 44362 | E70: 1.7655885 | F70: 1.0846298 | G70: 1.1494737 | H70: 1.5539023 | I70: 1.1647623 | J70: 0.79906189 | K70: 1.1991553 | L70: 1.3150368 | M70: 2.3236332 | N70: 1.062129 | O70: 1.2649704 | P70: 1.438824 | Q70: 5.6469971 | R70: 1.2185769 | S70: 1.1492812
C71: J | D71: 44392 | E71: 1.7000464 | F71: 1.268876 | G71: 1.1557895 | H71: 1.62505 | I71: 1.1625949 | J71: 0.85738758 | K71: 1.2813426 | L71: 1.3440516 | M71: 2.5283951 | N71: 1.0676553 | O71: 1.4728124 | P71: 1.7505153 | Q71: 6.58584 | R71: 1.2332755 | S71: 1.1492812
D72: 44423 | E72: 1.6502692 | F72: 1.2686667 | G72: 1.3431579 | H72: 1.652562 | I72: 1.1758511 | J72: 0.85995717 | K72: 1.3807177 | L72: 1.3896428 | M72: 2.6358025 | N72: 1.0731816 | O72: 1.6878126 | P72: 2.1382523 | Q72: 7.0040413 | R72: 1.1705274 | S72: 1.1492812
C73: S | D73: 44454 | E73: 1.6529787 | F73: 1.2725338 | G73: 2.0884211 | H73: 1.670775 | I73: 1.196516 | J73: 0.8878964 | K73: 1.4153774 | L73: 1.5260026 | M73: 2.7619048 | N73: 1.0751642 | O73: 1.8586473 | P73: 3.0826872 | Q73: 7.3223859 | R73: 1.2429488 | S73: 1.1492812
...

Sheet Global wind LCOE benchmarks
F1: Global wind LCOE benchmarks
A3: Dataset | B3: Global onshore and offshore wind LCOE benchmarks with and without China, 1H 2021-2022
A4: Units | B4: $/MWh (nominal)
A5: Source | B5: BloombergNEF
A6: Subject to terms and conditions
B9: Onshore wind | E9: Offshore wind
B35: LCOE
B36: $/MWh (nominal)
B37: Type | C37: 1H 2021 | D37: 1H 2022
B38: ex. China | C38: 42.263863 | D38: 49.369979
B39: incl. China | C39: 43.044772 | D39: 45.921197
B40: ex. China | C40: 89.163562 | D40: 94.384056
B41: incl. China | C41: 89.630816 | D41: 86.466617
B42: All LCOEs calculations are unsubsidized.
B43: The global benchmark is a country weighted-average using the latest annual capacity additions.
B44: The storage LCOE is reflective of a utility-scale Li-ion battery storage system with four-hour duration running at a daily cycle and includes charging costs assumed to be 60% of wholesale average power price.

Sheet PV cost inflation
E1: PV cost inflation
A3: Dataset | B3: PV cost inflation
A4: Units | B4: %
A5: Source | B5: BloombergNEF
A6: Subject to terms and conditions
B28: Year-on-year USD nominal cost change, fixed-axis PV
B29: %
B30: Short name | C30: Long name | D30: LCOE | E30: Capex
B31: Chile | C31: Chile | D31: -0.16569364 | E31: -0.097331862
B32: Japan | C32: Japan | D32: -0.12774826 | E32: -0.034782609
B33: Mex. | C33: Mexico | D33: -0.086659478 | E33: -0.1
B34: Canada | C34: Canada | D34: -0.0021564253 | E34: -0.0058059197
B35: South Korea | C35: South Korea | D35: 0.040605705 | E35: 0.082646712
B36: South Africa | C36: South Africa | D36: 0.046330553 | E36: 0.062973918
B37: Thai. | C37: Thailand | D37: 0.058780191 | E37: 0.074603659
B38: UK | C38: UK | D38: 0.059134817 | E38: 0.076485107
B39: France | C39: France | D39: 0.093900993 | E39: 0.12985557
B40: Austr. | C40: Australia | D40: 0.097139024 | E40: 0.11746657
B41: Ger. | C41: Germany | D41: 0.098973377 | E41: 0.12985557
B42: Italy | C42: Italy | D42: 0.10481379 | E42: 0.12985557
... B47: India | C47: India | D47: 0.2471736 | E47: 0.2894103
B48: Global | C48: Global | D48: 0.135

Sheet Onshore wind cost inflation
E1: Onshore wind cost inflation
A3: Dataset | B3: Onshore wind cost inflation
A4: Units | B4: %
A5: Source | B5: BloombergNEF
A6: Subject to terms and conditions
B28: Year-on-year USD nominal cost change, onshore wind
B29: %
B30: Short name | C30: Long name | D30: LCOE | E30: Capex
B31: China | C31: China | D31: -0.04540514 | E31: -0.13
B32: Chile | C32: Chile | D32: 0.038350563 | E32: 0
B33: Thai. | C33: Thailand | D33: 0.075803788 | E33: 0.04
B34: India | C34: India | D34: 0.08241019 | E34: 0.046882795
B35: Italy | C35: Italy | D35: 0.082631095 | E35: 0.12985557
B36: South Korea | C36: South Korea | D36: 0.10462775 | E36: 0.11
B37: Mexico | C37: Mexico | D37: 0.10654498 | E37: 0.06
B38: Ger. | C38: Germany | D38: 0.1147974 | E38: 0.12985557
B39: France | C39: France | D39: 0.12302557 | E39: 0.12985557
B40: US | C40: US | D40: 0.14073003 | E40: 0.12
B41: Canada | C41: Canada | D41: 0.14341743 | E41: 0.12
B42: UK | C42: UK | D42: 0.15178713 | E42: 0.12
... B47: Japan | C47: Japan | D47: 0.27508791 | E47: 0.18
B48: Global | C48: Global | D48: 0.067

Sheet Battery costs
F1: Battery costs
A3: Dataset | B3: Energy storage project costs 2021, based on usable capacity
A4: Units | B4: $/kWh, based on usable capacity
A5: Source | B5: BloombergNEF
A6: Subject to terms and conditions
B37: 4-hour duration battery nergy storage project costs 2021 vs 2022
B38: $/kWh
C39: 2021 survey | D39: 44256 | E39: 44287 | F39: 44317 | G39: 44348 | H39: 44378 | I39: 44409 | J39: 44440 | K39: 44470 | L39: 44501 | M39: 44531 | N39: 44562 | O39: 44593 | P39: 44621 | Q39: 44652 | R39: 44682 | S39: 44713
B40: Cell | C40: 103 | D40: 82.221384 | E40: 83.156897 | F40: 83.46201 | G40: 83.407392 | H40: 83.643658 | I40: 86.048677 | J40: 91.715209 | K40: 99.919911 | L40: 103.13706 | M40: 109.25416 | N40: 123.2722 | O40: 139.14686 | P40: 153.22997 | Q40: 150.4984 | R40: 140.20605 | S40: 142.68032
B41: Pack | C41: 49 | D41: 49 | E41: 49 | F41: 49 | G41: 49 | H41: 49 | I41: 49 | J41: 49 | K41: 49 | L41: 49 | M41: 49 | N41: 49 | O41: 49 | P41: 49 | Q41: 49 | R41: 49 | S41: 49
B42: Battery rack | C42: 152 | D42: 131.22138 | E42: 132.1569 | F42: 132.46201 | G42: 132.40739 | H42: 132.64366 | I42: 135.04868 | J42: 140.71521 | K42: 148.91991 | L42: 152.13706 | M42: 158.25416 | N42: 172.2722 | O42: 188.14686 | P42: 202.22997 | Q42: 199.4984 | R42: 189.20605 | S42: 191.68032
B43: Balance of system | C43: 35.371958 | D43: 35.371958 | E43: 35.371958 | F43: 35.371958 | G43: 35.371958 | H43: 35.371958 | I43: 35.371958 | J43: 35.371958 | K43: 35.371958 | L43: 35.371958 | M43: 35.371958 | N43: 35.371958 | O43: 35.371958 | P43: 35.371958 | Q43: 35.371958 | R43: 35.371958 | S43: 35.371958
B44: PCS | C44: 12.289209 | D44: 12.289209 | E44: 12.289209 | F44: 12.289209 | G44: 12.289209 | H44: 12.289209 | I44: 12.289209 | J44: 12.289209 | K44: 12.289209 | L44: 12.289209 | M44: 12.289209 | N44: 12.289209 | O44: 12.289209 | P44: 12.289209 | Q44: 12.289209 | R44: 12.289209 | S44: 12.289209
B45: EMS | C45: 5.5363225 | D45: 5.5363225 | E45: 5.5363225 | F45: 5.5363225 | G45: 5.5363225 | H45: 5.5363225 | I45: 5.5363225 | J45: 5.5363225 | K45: 5.5363225 | L45: 5.5363225 | M45: 5.5363225 | N45: 5.5363225 | O45: 5.5363225 | P45: 5.5363225 | Q45: 5.5363225 | R45: 5.5363225 | S45: 5.5363225
B46: Transformer | C46: 4.3972727 | D46: 4.3972727 | E46: 4.3972727 | F46: 4.3972727 | G46: 4.3972727 | H46: 4.3972727 | I46: 4.3972727 | J46: 4.3972727 | K46: 4.3972727 | L46: 4.3972727 | M46: 4.3972727 | N46: 4.3972727 | O46: 4.3972727 | P46: 4.3972727 | Q46: 4.3972727 | R46: 4.3972727 | S46: 4.3972727
B47: Margin & expenses | C47: 24.083902 | D47: 24.083902 | E47: 24.083902 | F47: 24.083902 | G47: 24.083902 | H47: 24.083902 | I47: 24.083902 | J47: 24.083902 | K47: 24.083902 | L47: 24.083902 | M47: 24.083902 | N47: 24.083902 | O47: 24.083902 | P47: 24.083902 | Q47: 24.083902 | R47: 24.083902 | S47: 24.083902
B48: EPC & grid connection addition | C48: 25.292244 | D48: 25.292244 | E48: 25.292244 | F48: 25.292244 | G48: 25.292244 | H48: 25.292244 | I48: 25.292244 | J48: 25.292244 | K48: 25.292244 | L48: 25.292244 | M48: 25.292244 | N48: 25.292244 | O48: 25.292244 | P48: 25.292244 | Q48: 25.292244 | R48: 25.292244 | S48: 25.292244
B49: Developer overhead & margin | C49: 24.535714 | D49: 24.535714 | E49: 24.535714 | F49: 24.535714 | G49: 24.535714 | H49: 24.535714 | I49: 24.535714 | J49: 24.535714 | K49: 24.535714 | L49: 24.535714 | M49: 24.535714 | N49: 24.535714 | O49: 24.535714 | P49: 24.535714 | Q49: 24.535714 | R49: 24.535714 | S49: 24.535714
B50: Fully-installed system | C50: 283.50662 | D50: 262.72801 | E50: 263.66352 | F50: 263.96863 | G50: 263.91402 | H50: 264.15028 | I50: 266.5553 | J50: 272.22183 | K50: 280.42653 | L50: 283.64369 | M50: 289.76079 | N50: 303.77882 | O50: 319.65348 | P50: 333.73659 | Q50: 331.00502 | R50: 320.71267 | S50: 323.18695

Sheet Storage LCOE
F1: Storage LCOE
A3: Dataset | B3: Storage LCOE 1H 2021 versus 1H 2022
A4: Units | B4: $/MWh (nominal)
A5: Source | B5: BloombergNEF
A6: Subject to terms and conditions
B37: Utility-scale battery (4h) LCOE
B38: $/MWh (nominal)
C39: Scenario | D39: Low | E39: Mid | F39: High | G39: Range | H39: % increase
B40: Germany | C40: 2021 | D40: 126.5686 | E40: 131.19855 | F40: 135.81634 | G40: 9.2477407
C41: 2022 | D41: 163.68616 | E41: 184.71611 | F41: 210.6893 | G41: 47.003138 | H41: 0.40791272
B42: UK | C42: 21 | D42: 127.52727 | E42: 134.11597 | F42: 140.70872 | G42: 13.181443
C43: 22 | D43: 162.34602 | E43: 182.82724 | F43: 208.45914 | G43: 46.113121 | H43: 0.36320257
B44: US | C44: 21 | D44: 119.20035 | E44: 123.64453 | F44: 128.0887 | G44: 8.888346
C45: 22 | D45: 116.38064 | E45: 131.63625 | F45: 163.71527 | G45: 47.334636 | H45: 0.064634654
B46: Japan | C46: 21 | D46: 422.13124 | E46: 438.20253 | F46: 454.27381 | G46: 32.142576
C47: 22 | D47: 283.62186 | E47: 344.23484 | F47: 632.55055 | G47: 348.9287 | H47: -0.21443895

Sheet Coal & gas cost inflation
F1: Coal & gas cost inflation
A3: Dataset | B3: Coal & gas cost inflation
A4: Units | B4: %
A5: Source | B5: BloombergNEF
A6: Subject to terms and conditions
B8: CCGT | L8: Coal-fired power plants
B34: Year-on-year USD nominal cost change | L34: Year-on-year USD nominal cost change
B35: % | L35: %
C36: Gas prices (15-year offtake) | D36: CCGT LCOE | M36: Coal prices (15-year offtake) | N36: Coal LCOE
B37: China | C37: 0.014152943 | D37: -0.11197791 | L37: Indonesia | M37: 0.11407863 | N37: 0.0052084115
B38: Indon. | C38: 0.072372699 | D38: 0.058167814 | L38: South Korea | M38: -0.0086697533 | N38: 0.008980413
B39: Thai. | C39: 0.065252727 | D39: 0.13202148 | L39: Thailand | M39: 0.078329007 | N39: 0.039335441
B40: Viet. | C40: 0.23184717 | D40: 0.14453318 | L40: Australia | M40: 0.096520304 | N40: 0.056336549
B41: India | C41: 0.17628815 | D41: 0.15117734 | L41: India | M41: 0.082222387 | N41: 0.071962032
B42: Brazil | C42: 0.11359212 | D42: 0.15195097 | L42: Japan | M42: 0.064024262 | N42: 0.098319087
B43: South Korea | C43: 0.13723271 | D43: 0.16540982 | L43: China | M43: 0.19078621 | N43: 0.2389588
B44: Canada | C44: 0.41307844 | D44: 0.17685997 | L44: Poland | M44: 0.096520304 | N44: 0.24239687
B45: Japan | C45: 0.10862531 | D45: 0.19769139
B46: EU | C46: 0.20783108 | D46: 0.2154059
B47: US | C47: 0.4605397 | D47: 0.21809207
B48: Austr. | C48: 0.23849816 | D48: 0.21810293
B49: Mexico | C49: 0.47379258 | D49: 0.25080806
B50: UK | C50: 0.20185172 | D50: 0.30491226

Sheet LCOE map
F1: LCOE map
A3: Dataset | B3: Cheapest source of new-build bulk generation, 1H 2022
A4: Units | B4: $/MWh, nominal
A5: Source | B5: BloombergNEF
A6: Subject to terms and conditions
B8: Cheapest source of bulk generation, 1H 2022
B9: New-build solar, wind, coal and gas
B43: List of countries with lowest-cost new build technology
B44: Country | C44: Technology
B45: Belgium | C45: Offshore wind
B46: Denmark | C46: Offshore wind
B47: France | C47: Fixed-axis PV
B48: Germany | C48: Fixed-axis PV
B49: Greece | C49: Fixed-axis PV
B50: Ireland | C50: Fixed-axis PV
B51: Italy | C51: Fixed-axis PV
B52: Netherlands | C52: Onshore wind
B53: Poland | C53: Onshore wind
B54: Portugal | C54: Fixed-axis PV
B55: Russian Federation | C55: CCGT
... B87: Zambia | C87: Fixed-axis PV

Sheet LCOE vs marginal cost map
F1: LCOE versus marginal cost map
A3: Dataset | B3: Cheapest source of new-build PV, wind versus existing coal and gas, 1H 2022
A4: Units | B4: $/MWh, nominal
A5: Source | B5: BloombergNEF
A6: Subject to terms and conditions
B8: Cheapest source of bulk generation, 1H 2022
B9: New-build solar and wind versus existing coal and gas
B44: List of countries with lowest-cost technology, new solar, wind versus existing gas, coal
B45: Country | C45: Technology
B46: Belgium | C46: Offshore wind
B47: Denmark | C47: Offshore wind
B48: France | C48: Fixed-axis PV
B49: Germany | C49: Fixed-axis PV
B50: Greece | C50: Fixed-axis PV
B51: Ireland | C51: Fixed-axis PV
B52: Italy | C52: Fixed-axis PV
B53: Netherlands | C53: Onshore wind
B54: Poland | C54: Onshore wind
B55: Portugal | C55: Fixed-axis PV
B56: Russian Federation | C56: CCGT
... B87: South Africa | C87: Tracking PV

Sheet Key long-term trends ->
F1: Key long-term trends

Sheet PV mono vs multi panels
F1: PV mono vs multi panels
A3: Dataset | B3: Mono vs multi share
A4: Units | B4: %
A5: Source | B5: BloombergNEF
A6: Subject to terms and conditions
B28: Share of market
B29: %
C30: Multi c-Si | D30: Mono c-Si
B31: 2016 | C31: 0.8 | D31: 0.2
B32: 2017 | C32: 0.72 | D32: 0.28
B33: 2018 | C33: 0.58461538 | D33: 0.41538462
B34: 2019 | C34: 0.41120028 | D34: 0.58879972
B35: 2020 | C35: 0.17085961 | D35: 0.82914039
B36: 2021 | C36: 0.071064283 | D36: 0.92893572
B37: Note: Multi after 2019 including mono-like wafer made of the casting process which is supposedly less than 1%

Sheet PV bifacial vs monofacial
F1: PV bifacial vs monofacial
A3: Dataset | B3: Share of bifacial module among all silicon PV
A4: Units | B4: %
A5: Source | B5: BloombegNEF, CPIA 2021
A6: Subject to terms and conditions
B28: Share of bifacial module among all silicon PV
B29: %
B30: Year | C30: Bifacial modules | D30: Other
B31: 2018 | C31: 0.03 | D31: =1-C31 -> 0.97
B32: 2019 | C32: 0.18 | D32: =1-C32 -> 0.82
B33: 2020 | C33: 0.3 | D33: =1-C33 -> 0.7
B34: 2021 | C34: 0.374 | D34: =1-C34 -> 0.626

Sheet Project size, Utility-scale PV
F1: Project size, Utility-scale PV
A3: Dataset | B3: Project size, Utility-scale PV
A4: Units | B4: MW
A5: Source | B5: BNEF Renewable Asset Database
A6: Subject to terms and conditions
B41: Distribution of utility-scale PV project size, global
B42: MW | E42: Financing date ->
B43: Technology | D43: Metric | E43: 2010 | F43: 2011 | G43: 2012 | H43: 2013 | I43: 2014 | J43: 2015 | K43: 2016 | L43: 2017 | M43: 2018 | N43: 2019 | O43: 2020 | P43: 2021 | Q43: 2022
B44: Solar PV | D44: Min | E44: 1 | F44: 1 | G44: 1 | H44: 1 | I44: 1 | J44: 1 | K44: 1 | L44: 1 | M44: 1 | N44: 1 | O44: 1 | P44: 1 | Q44: 1
B45: Solar PV | D45: Decile 1 | E45: 1 | F45: 1.1 | G45: 1.2 | H45: 1.2 | I45: 1.246 | J45: 1.553 | K45: 1.8 | L45: 1.8 | M45: 1.69 | N45: 1.8 | O45: 2 | P45: 2.4 | Q45: 2.5
B46: Solar PV | D46: Quartile 1 | E46: 1.7 | F46: 2 | G46: 1.9 | H46: 1.82 | I46: 2 | J46: 2.6 | K46: 3 | L46: 3 | M46: 2.7 | N46: 2.68 | O46: 3.22 | P46: 4.005 | Q46: 5.5
B47: Solar PV | D47: Median | E47: 3.2 | F47: 4.4 | G47: 4 | H47: 3.75 | I47: 5 | J47: 6.95 | K47: 8 | L47: 7.8 | M47: 7.2 | N47: 5.2 | O47: 10 | P47: 12.665 | Q47: 30
B48: Solar PV | D48: Average | E48: 6.3857764 | F48: 8.9529694 | G48: 10.391537 | H48: 10.647682 | I48: 14.590711 | J48: 17.388827 | K48: 19.205588 | L48: 19.562342 | M48: 22.663368 | N48: 25.26508 | O48: 45.40539 | P48: 65.20469 | Q48: 91.192324
B49: Solar PV | D49: Quartile 3 | E49: 7.2 | F49: 9.8 | G49: 10 | H49: 11.5 | I49: 17.75 | J49: 20 | K49: 20 | L49: 20 | M49: 25 | N49: 20.88 | O49: 50 | P49: 68 | Q49: 100
B50: Solar PV | D50: Decile 9 | E50: 13.77 | F50: 20 | G50: 22.3 | H50: 22.776 | I50: 32.13 | J50: 49.74 | K50: 50 | L50: 50 | M50: 50 | N50: 70 | O50: 117.65 | P50: 158.875 | Q50: 232.791
B51: Solar PV | D51: Max | E51: 83.5 | F51: 390 | G51: 715 | H51: 376.4 | I51: 530 | J51: 380 | K51: 1000 | L51: 1177.4 | M51: 709 | N51: 600 | O51: 2101 | P51: 3000 | Q51: 1745
B52: Solar PV | D52: Number | E52: 810 | F52: 1533 | G52: 1795 | H52: 2651 | I52: 2785 | J52: 3582 | K52: 3532 | L52: 4746 | M52: 3275 | N52: 3099 | O52: 2350 | P52: 2572 | Q52: 658
B53: Solar PV | D53: Min-Max range | E53: 82.5 | F53: 389 | G53: 714 | H53: 375.4 | I53: 529 | J53: 379 | K53: 999 | L53: 1176.4 | M53: 708 | N53: 599 | O53: 2100 | P53: 2999 | Q53: 1744
B54: Solar PV | D54: Quartile range | E54: 5.5 | F54: 7.8 | G54: 8.1 | H54: 9.68 | I54: 15.75 | J54: 17.4 | K54: 17 | L54: 17 | M54: 22.3 | N54: 18.2 | O54: 46.78 | P54: 63.995 | Q54: 94.5
B57: For Chart | D57: Metric | E57: 2010 | G57: 12 | I57: 14 | K57: 16 | M57: 18 | O57: 20 | Q57: 22 ytd
D58: Min | E58: =E44 -> 1 | F58: =F44 -> 1 | G58: =G44 -> 1 | H58: =H44 -> 1 | I58: =I44 -> 1 | J58: =J44 -> 1 | K58: =K44 -> 1 | L58: =L44 -> 1 | ... Q58: =Q44 -> 1
B59: Min to Q1 | D59: 25% smallest | E59: =E46-E44 -> 0.7 | F59: =F46-F44 -> 1 | G59: =G46-G44 -> 0.9 | H59: =H46-H44 -> 0.82 | I59: =I46-I44 -> 1 | J59: =J46-J44 -> 1.6 | K59: =K46-K44 -> 2 | L59: =L46-L44 -> 2 | ... Q59: =Q46-Q44 -> 4.5
B60: Q1 tp Q3 | D60: 50% of projects | E60: =E49-E45 -> 6.2 | F60: =F49-F45 -> 8.7 | G60: =G49-G45 -> 8.8 | H60: =H49-H45 -> 10.3 | I60: =I49-I45 -> 16.504 | J60: =J49-J45 -> 18.447 | K60: =K49-K45 -> 18.2 | L60: =L49-L45 -> 18.2 | ... Q60: =Q49-Q45 -> 97.5
B61: Q3 to max | D61: 25% largest | E61: =E51-E49 -> 76.3 | F61: =F51-F49 -> 380.2 | G61: =G51-G49 -> 705 | H61: =H51-H49 -> 364.9 | I61: =I51-I49 -> 512.25 | J61: =J51-J49 -> 360 | K61: =K51-K49 -> 980 | L61: =L51-L49 -> 1157.4 | ... Q61: =Q51-Q49 -> 1645
B65: Median project size, by country
B66: MW
B67: Technology | D67: Metric | E67: 2010 | F67: 2011 | G67: 2012 | H67: 2013 | I67: 2014 | J67: 2015 | K67: 2016 | L67: 2017 | M67: 2018 | N67: 2019 | O67: 2020 | P67: 2021 | Q67: 2022
B68: Solar PV | C68: Australia | E68: 1.35 | F68: #N/A | G68: 1.125 | H68: 43.2 | I68: 3.1 | J68: 8.25 | K68: 4.885 | L68: 30 | M68: 5.73 | N68: 5.8 | O68: 5.88 | P68: 5.88 | Q68: 5.88
B69: Solar PV | C69: China | E69: 5 | F69: 9.8 | G69: 10 | H69: 20 | I69: 20 | J69: 20 | K69: 20 | L69: 10 | M69: 10 | N69: 6.27 | O69: 50 | P69: 50 | Q69: 49.765
B70: Solar PV | C70: Germany | E70: 4.5 | F70: 6.5 | G70: 4.1 | H70: 3.8 | I70: 4.2 | J70: 3.2 | K70: 3.7 | L70: 4.6 | M70: 2.9 | N70: 6.5 | O70: 7.85 | P70: 9.035 | Q70: 4.775
B71: Solar PV | C71: India | E71: 2 | F71: 5 | G71: 5 | H71: 2.5 | I71: 5.1 | J71: 6 | K71: 5 | L71: 20 | M71: 9.15 | N71: 13.5 | O71: 8 | P71: 15.725 | Q71: 75
B72: Solar PV | C72: Japan | E72: 1.16 | F72: 1.5 | G72: 1.83 | H72: 1.89 | I72: 1.99 | J72: 2.06 | K72: 2.32 | L72: 2.43 | M72: 2.43 | N72: 2.68 | O72: 2.39 | P72: 3.2 | Q72: 2.425
B73: Solar PV | C73: United Kingdom | E73: 5 | F73: 4.6 | G73: 5 | H73: 7 | I73: 10 | J73: 5 | K73: 5 | L73: 5 | M73: 4.75 | N73: 5.2 | O73: 8.295 | P73: 19.2 | Q73: 49.95
B74: Solar PV | C74: United States | E74: 2 | F74: 2.9 | G74: 3.06 | H74: 5 | I74: 5.52 | J74: 6.5 | K74: 6.9 | L74: 6.8 | M74: 5.9 | N74: 6.5 | O74: 7.49 | P74: 6.7 | Q74: 11.66
B75: Solar PV | C75: Spain | E75: 3.3 | F75: 2.85 | G75: 2.3 | H75: 4.5 | I75: 2.95 | J75: #N/A | K75: #N/A | L75: 3.9 | M75: 42 | N75: 49.88 | O75: 30.4 | P75: 22 | Q75: 49.75
B76: Solar PV | C76: France | E76: 5.85 | F76: 4 | G76: 6.2 | H76: 4.885 | I76: 7.025 | J76: 4.6 | K76: 4.4 | L76: 5 | M76: 4.32 | N76: 4.41 | O76: 4.99 | P76: 5 | Q76: 5
B77: Solar PV | C77: Brazil | E77: 1 | F77: 1 | G77: 1.5 | H77: 3.068 | I77: 1.1 | J77: 37.2 | K77: 38.4225 | L77: 35.162 | M77: 34.629 | N77: 5.3 | O77: 41.796 | P77: 50 | Q77: 49.5
B78: Solar PV | C78: South Africa | E78: #N/A | F78: 1.2 | G78: 32.5 | H78: 44 | I78: 82.5 | J78: 41.797 | K78: 84.25 | L78: #N/A | M78: 78 | N78: 55 | O78: 35 | P78: 10 | Q78: 49.685

Sheet Turbine size, Onshore wind
F1: Turbine size, Onshore wind
A3: Dataset | B3: Turbine size, Onshore wind
A4: Units | B4: MW
A5: Source | B5: BloombergNEF
A6: Subject to terms and conditions
B41: Statistics on onshore wind turbine size, global
B42: MW | C42: 2002 | F42: 05 | K42: 2010 | M42: 12 | O42: 14 | Q42: 16 | S42: 18 | V42: 21
B43: Closing year | C43: 2002 | D43: 2003 | E43: 2004 | F43: 2005 | G43: 2006 | H43: 2007 | I43: 2008 | J43: 2009 | K43: 2010 | L43: 2011 | M43: 2012 | N43: 2013 | O43: 2014 | P43: 2015 | Q43: 2016 | R43: 2017 | S43: 2018 | T43: 2019 | U43: 2020 | V43: 2021
B44: Min | C44: 1.3 | D44: 1.3 | E44: 1.2972973 | F44: 1 | G44: 0.85 | H44: 0.037096774 | I44: 0.33333333 | J44: 1 | K44: 1 | L44: 1 | M44: 1 | N44: 0.2 | O44: 1.25 | P44: 1 | Q44: 0.25641026 | R44: 1.5 | S44: 1.6666667 | T44: 0.12592593 | U44: 2 | V44: 1.345
B45: Quartile 1 | C45: 1.35 | D45: 1.4960317 | E45: 1.65 | F45: 1.65 | G45: 1.8 | H45: 1.6632231 | I45: 1.5 | J45: 1.5 | K45: 1.65 | L45: 1.803834 | M45: 2 | N45: 2 | O45: 2 | P45: 2 | Q45: 2 | R45: 2.1 | S45: 2.475 | T45: 2.7625 | U45: 3.3 | V45: 3.4650431
B46: Average | C46: 1.9711187 | D46: 1.7914017 | E46: 1.8856764 | F46: 1.907332 | G46: 2.0904434 | H46: 2.0710742 | I46: 1.9844396 | J46: 1.9466171 | K46: 2.0226873 | L46: 2.1506747 | M46: 2.2604466 | N46: 2.4019892 | O46: 2.4989702 | P46: 2.4991072 | Q46: 2.4835679 | R46: 2.838449 | S46: 3.2177053 | T46: 3.6295206 | U46: 3.9557077 | V46: 4.1635798
B47: Median | C47: 2 | D47: 1.5 | E47: 1.9036145 | F47: 2 | G47: 2 | H47: 2 | I47: 2 | J47: 2 | K47: 2 | L47: 2.05 | M47: 2.1 | N47: 2.3 | O47: 2.4 | P47: 2.3 | Q47: 2.2075472 | R47: 3 | S47: 3.4491379 | T47: 3.625 | U47: 4.1666667 | V47: 4.2
B48: Quartile 3 | C48: 2.5 | D48: 2.15 | E48: 2 | F48: 2 | G48: 2.5 | H48: 2.3 | I48: 2.2513158 | J48: 2.1 | K48: 2.3 | L48: 2.5 | M48: 2.5 | N48: 3 | O48: 3 | P48: 3 | Q48: 3 | R48: 3.4597902 | S48: 3.6 | T48: 4.2 | U48: 4.5 | V48: 5.025
B49: Max | C49: 2.5 | D49: 3.4117647 | E49: 3 | F49: 3 | G49: 3.2 | H49: 7.58 | I49: 3 | J49: 5 | K49: 3.4 | L49: 3.4 | M49: 4.5 | N49: 5 | O49: 6 | P49: 8 | Q49: 4.5 | R49: 4.5 | S49: 4.5 | T49: 6.6 | U49: 7.58 | V49: 6.2
B50: Quartiles | C50: 1.15 | D50: 0.65396825 | E50: 0.35 | F50: 0.35 | G50: 0.7 | H50: 0.63677686 | I50: 0.75131579 | J50: 0.6 | K50: 0.65 | L50: 0.69616597 | M50: 0.5 | N50: 1 | O50: 1 | P50: 1 | Q50: 1 | R50: 1.3597902 | S50: 1.125 | T50: 1.4375 | U50: 1.2 | V50: 1.5599569
B51: Reset | C51: -2.5 | D51: -2.15 | E51: -2 | F51: -2 | G51: -2.5 | H51: -2.3 | I51: -2.2513158 | J51: -2.1 | K51: -2.3 | L51: -2.5 | M51: -2.5 | N51: -3 | O51: -3 | P51: -3 | Q51: -3 | R51: -3.4597902 | S51: -3.6 | T51: -4.2 | U51: -4.5 | V51: -5.025
B52: Min-max | C52: 1.2 | D52: 2.1117647 | E52: 1.7027027 | F52: 2 | G52: 2.35 | H52: 7.5429032 | I52: 2.6666667 | J52: 4 | K52: 2.4 | L52: 2.4 | M52: 3.5 | N52: 4.8 | O52: 4.75 | P52: 7 | Q52: 4.2435897 | R52: 3 | S52: 2.8333333 | T52: 6.4740741 | U52: 5.58 | V52: 4.855
B53: MW of contracts | C53: 449.8 | D53: 1244.1 | E53: 1926.9 | F53: 5099.87 | G53: 5186.5 | H53: 17123.25 | I53: 13624.62 | J53: 9500.02 | K53: 12754.2 | L53: 9252.85 | M53: 8763.15 | N53: 11379.58 | O53: 12848.01 | P53: 17315.18 | Q53: 19406.55 | R53: 20728.61 | S53: 23297.9 | T53: 24284.84 | U53: 23327.02 | V53: 18020.07
B54: Turbine number | C54: 230 | D54: 764 | E54: 1072 | F54: 2561 | G54: 2514 | H54: 8778 | I54: 7575 | J54: 4890 | K54: 6343 | L54: 4180 | M54: 3973 | N54: 5022 | O54: 5465 | P54: 7436 | Q54: 8218 | R54: 7765 | S54: 7751 | T54: 7341 | U54: 5516 | V54: 4260
B55: Count deals | C55: 12 | D55: 17 | E55: 30 | F55: 43 | G55: 52 | H55: 126 | I55: 132 | J55: 111 | K55: 161 | L55: 126 | M55: 133 | N55: 139 | O55: 221 | P55: 217 | Q55: 265 | R55: 228 | S55: 246 | T55: 188 | U55: 221 | V55: 158

Sheet Project size, Onshore wind
F1: Project size, Onshore wind
A3: Dataset | B3: Project size, Onshore wind
A4: Units | B4: MW
A5: Source | B5: BNEF Renewable Asset Database
A6: Subject to terms and conditions
B41: Distribution of onshore wind project size, global
B42: MW | E42: Financing date ->
B43: Technology | D43: Metric | E43: 2010 | F43: 2011 | G43: 2012 | H43: 2013 | I43: 2014 | J43: 2015 | K43: 2016 | L43: 2017 | M43: 2018 | N43: 2019 | O43: 2020 | P43: 2021 | Q43: 2022
B44: Wind Onshore | D44: Min | E44: 1 | F44: 1 | G44: 1 | H44: 1.25 | I44: 1.5 | J44: 1 | K44: 1.1 | L44: 1 | M44: 1.2 | N44: 1 | O44: 1.5 | P44: 1.98 | Q44: 3.6
B45: Wind Onshore | D45: Decile 1 | E45: 2.1 | F45: 1.6 | G45: 3.155 | H45: 3.2 | I45: 3.2 | J45: 3 | K45: 2.782 | L45: 2.4 | M45: 3.1 | N45: 6 | O45: 4.5 | P45: 8.4 | Q45: 18
B46: Wind Onshore | D46: Quartile 1 | E46: 5 | F46: 4.2 | G46: 9 | H46: 10 | I46: 9 | J46: 7 | K46: 6.6 | L46: 7.05 | M46: 9.6 | N46: 13.8 | O46: 11.2 | P46: 19.5 | Q46: 31.5
B47: Wind Onshore | D47: Median | E47: 15.65 | F47: 15 | G47: 25.8 | H47: 25.85 | I47: 23.1 | J47: 18.9 | K47: 17 | L47: 20.845 | M47: 28.8 | N47: 42 | O47: 39 | P47: 39.6 | Q47: 52.825
B48: Wind Onshore | D48: Average | E48: 30.909953 | F48: 26.643944 | G48: 35.898325 | H48: 39.138586 | I48: 35.877882 | J48: 34.953982 | K48: 33.658694 | L48: 39.036306 | M48: 48.668 | N48: 61.675723 | O48: 54.607356 | P48: 72.976724 | Q48: 139.74448
B49: Wind Onshore | D49: Quartile 3 | E49: 49.5 | F49: 49.075 | G49: 49.5 | H49: 49.5 | I49: 49.5 | J49: 49.5 | K49: 48.3 | L49: 50 | M49: 50.6 | N49: 72.72375 | O49: 50.6 | P49: 70 | Q49: 194
B50: Wind Onshore | D50: Decile 9 | E50: 50 | F50: 50 | G50: 63.3 | H50: 69.72 | I50: 57.7 | J50: 76 | K50: 75 | L50: 99.5 | M50: 105.4 | N50: 150 | O50: 103.66 | P50: 166.88 | Q50: 348
B51: Wind Onshore | D51: Max | E51: 845 | F51: 300 | G51: 470 | H51: 502 | I51: 402 | J51: 300.3 | K51: 400 | L51: 644.4 | M51: 600 | N51: 1001.85 | O51: 1000 | P51: 2267.1 | Q51: 1750
B52: Wind Onshore | D52: Number | E52: 1476 | F52: 1458 | G52: 1176 | H52: 1043 | I52: 1525 | J52: 1793 | K52: 1750 | L52: 1600 | M52: 1325 | N52: 1556 | O52: 1441 | P52: 1227 | Q52: 210
B53: Wind Onshore | D53: Min-Max range | E53: 844 | F53: 299 | G53: 469 | H53: 500.75 | I53: 400.5 | J53: 299.3 | K53: 398.9 | L53: 643.4 | M53: 598.8 | N53: 1000.85 | O53: 998.5 | P53: 2265.12 | Q53: 1746.4
B54: Wind Onshore | D54: Quartile range | E54: 44.5 | F54: 44.875 | G54: 40.5 | H54: 39.5 | I54: 40.5 | J54: 42.5 | K54: 41.7 | L54: 42.95 | M54: 41 | N54: 58.92375 | O54: 39.4 | P54: 50.5 | Q54: 162.5
B57: For Chart | D57: Metric | E57: 2010 | G57: 12 | I57: 14 | K57: 16 | M57: 18 | O57: 20 | Q57: 22 ytd
D58: Min | E58: =E44 -> 1 | F58: =F44 -> 1 | G58: =G44 -> 1 | H58: =H44 -> 1.25 | I58: =I44 -> 1.5 | J58: =J44 -> 1 | K58: =K44 -> 1.1 | L58: =L44 -> 1 | ... Q58: =Q44 -> 3.6
B59: Min to Q1 | D59: 25% smallest | E59: =E46-E44 -> 4 | F59: =F46-F44 -> 3.2 | G59: =G46-G44 -> 8 | H59: =H46-H44 -> 8.75 | I59: =I46-I44 -> 7.5 | J59: =J46-J44 -> 6 | K59: =K46-K44 -> 5.5 | L59: =L46-L44 -> 6.05 | ... Q59: =Q46-Q44 -> 27.9
B60: Q1 tp Q3 | D60: 50% of projects | E60: =E49-E45 -> 47.4 | F60: =F49-F45 -> 47.475 | G60: =G49-G45 -> 46.345 | H60: =H49-H45 -> 46.3 | I60: =I49-I45 -> 46.3 | J60: =J49-J45 -> 46.5 | K60: =K49-K45 -> 45.518 | L60: =L49-L45 -> 47.6 | ... Q60: =Q49-Q45 -> 176
B61: Q3 to max | D61: 25% largest | E61: =E51-E49 -> 795.5 | F61: =F51-F49 -> 250.925 | G61: =G51-G49 -> 420.5 | H61: =H51-H49 -> 452.5 | I61: =I51-I49 -> 352.5 | J61: =J51-J49 -> 250.8 | K61: =K51-K49 -> 351.7 | L61: =L51-L49 -> 594.4 | ... Q61: =Q51-Q49 -> 1556
B65: Median project size, by country
B66: MW
B67: Technology | D67: Metric | E67: 2010 | F67: 2011 | G67: 2012 | H67: 2013 | I67: 2014 | J67: 2015 | K67: 2016 | L67: 2017 | M67: 2018 | N67: 2019 | O67: 2020 | P67: 2021 | Q67: 2022
B68: Wind Onshore | C68: Australia | E68: 48.3 | F68: 55 | G68: 131.2 | H68: 106.8 | I68: 6.15 | J68: 102.4 | K68: 100.8 | L68: 116.1 | M68: 133.2 | N68: 152.95 | O68: 12 | P68: 180.6 | Q68: 686.7
B69: Wind Onshore | C69: China | E69: 49.5 | F69: 49.5 | G69: 49.5 | H69: 49.5 | I69: 49.5 | J69: 49.5 | K69: 49.8 | L69: 50 | M69: 50 | N69: 50 | O69: 50 | P69: 49.5 | Q69: 124.45
B70: Wind Onshore | C70: Germany | E70: 6 | F70: 6.9 | G70: 9.2 | H70: 9.6 | I70: 9.4 | J70: 9.2 | K70: 8.3 | L70: 9 | M70: 7.2 | N70: 9 | O70: 8.4 | P70: 8.45 | Q70: 16.95
B71: Wind Onshore | C71: India | E71: 4.5 | F71: 2.1 | G71: 6.8 | H71: 13 | I71: 8.2 | J71: 4 | K71: 6 | L71: 2.1 | M71: 2.1 | N71: 18.9 | O71: 2.775 | P71: 132.25 | Q71: 99.9
B72: Wind Onshore | C72: Japan | E72: 10 | F72: 2 | G72: 6 | H72: 4 | I72: 7.48 | J72: 2 | K72: 16 | L72: 20.4 | M72: 7.485 | N72: 6.9 | O72: 17.1 | P72: 14.46 | Q72: 42
B73: Wind Onshore | C73: United Kingdom | E73: 9.1 | F73: 10.1 | G73: 10 | H73: 12 | I73: 9 | J73: 15 | K73: 8.3 | L73: 12.85 | M73: 9 | N73: 23.75 | O73: 43.2 | P73: 40.04 | Q73: 27.4
B74: Wind Onshore | C74: United States | E74: 72 | F74: 25.15 | G74: 62.1 | H74: 115.8 | I74: 124.55 | J74: 107.5 | K74: 104 | L74: 114 | M74: 103.5 | N74: 162 | O74: 160.8 | P74: 145 | Q74: 301.5
B75: Wind Onshore | C75: Spain | E75: 30 | F75: 30.3 | G75: 18 | H75: 9 | I75: #N/A | J75: 35 | K75: 4.5 | L75: 9.6 | M75: 25.3 | N75: 26.15 | O75: 31.5 | P75: 49 | Q75: 38.3
B76: Wind Onshore | C76: France | E76: 12 | F76: 11.75 | G76: 12 | H76: 12 | I76: 12 | J76: 12 | K76: 12 | L76: 12.5 | M76: 14.1 | N76: 13.2 | O76: 12 | P76: 14 | Q76: 23.4
B77: Wind Onshore | C77: Brazil | E77: 30 | F77: 27.45 | G77: 29.65 | H77: 27.975 | I77: 28.9 | J77: 22.295 | K77: 27.3 | L77: 27.6 | M77: 25 | N77: 34.125 | O77: 42 | P77: 37.2 | Q77: 39.2
B78: Wind Onshore | C78: South Africa | E78: 1.8 | F78: #N/A | G78: 76.9 | H78: 94.5 | I78: 88 | J78: 125.65 | K78: #N/A | L78: #N/A | M78: 142.6 | N78: #N/A | O78: #N/A | P78: #N/A | Q78: #N/A

Sheet Onshore wind capacity factors
D1: Onshore wind capacity factors
A3: Dataset | B3: Onshore wind capacity factors, global
A4: Units | B4: %
A5: Source | B5: BloombergNEF
A6: Subject to terms and conditions
B30: Historic onshore wind capacity factors
B31: % | C31: 2000 | D31: =C31+1 -> 2001 | E31: =D31+1 -> 2002 | F31: =E31+1 -> 2003 | G31: =F31+1 -> 2004 | H31: =G31+1 -> 2005 | I31: =H31+1 -> 2006 | J31: =I31+1 -> 2007 | K31: =J31+1 -> 2008 | ... W31: =V31+1 -> 2020 | X31: 2021 | Y31: 2022
B32: Metric | C32: 2000 | H32: 05 | M32: 2010 | R32: 2015 | W32: 2020 | Y32: 22e
B33: Average | C33: 0.24402003 | D33: 0.23743326 | E33: 0.20201359 | F33: 0.24025931 | G33: 0.22413255 | H33: 0.24535077 | I33: 0.25398772 | J33: 0.26282345 | K33: 0.25543425 | L33: 0.2692925 | M33: 0.26464488 | N33: 0.27156429 | O33: 0.28680344 | P33: 0.27859975 | Q33: 0.30357821 | R33: 0.3051872 | S33: 0.32965487 | T33: 0.32579091 | U33: 0.333031 | V33: 0.33455556 | W33: 0.32596386 | X33: 0.34265241 | Y33: 0.34678663
B34: Median | C34: 0.22186542 | D34: 0.21442863 | E34: 0.20241749 | F34: 0.21346807 | G34: 0.20971918 | H34: 0.21025424 | I34: 0.22865558 | J34: 0.231389 | K34: 0.23814942 | L34: 0.24455651 | M34: 0.2466323 | N34: 0.25113411 | O34: 0.2607714 | P34: 0.26598415 | Q34: 0.28142027 | R34: 0.28734809 | S34: 0.29118149 | T34: 0.29373881 | U34: 0.30211771 | V34: 0.30160873 | W34: 0.33339963 | X34: 0.34579633 | Y34: 0.34977966
B35: First quartile | C35: 0.17268308 | D35: 0.16756671 | E35: 0.15830452 | F35: 0.16883988 | G35: 0.16507535 | H35: 0.16622139 | I35: 0.17609526 | J35: 0.18017832 | K35: 0.18375302 | L35: 0.19509409 | M35: 0.19543589 | N35: 0.19583611 | O35: 0.2050759 | P35: 0.21618569 | Q35: 0.21985929 | R35: 0.22891107 | S35: 0.2397562 | T35: 0.24378788 | U35: 0.25773993 | V35: 0.25129924 | W35: 0.26615654 | X35: 0.28881052 | Y35: 0.29148884
B36: Last quartile | C36: 0.28584254 | D36: 0.25982114 | E36: 0.2494596 | F36: 0.27050206 | G36: 0.25867964 | H36: 0.27538676 | I36: 0.28667611 | J36: 0.28728899 | K36: 0.29798276 | L36: 0.30580143 | M36: 0.30240533 | N36: 0.31602719 | O36: 0.32305098 | P36: 0.31733565 | Q36: 0.33991224 | R36: 0.34493394 | S36: 0.3491288 | T36: 0.33938316 | U36: 0.35947183 | V36: 0.36850844 | W36: 0.39214841 | X36: 0.39734746 | Y36: 0.41125736
B37: Range quartile | C37: 0.11315946 | D37: 0.092254435 | E37: 0.091155077 | F37: 0.10166218 | G37: 0.09360429 | H37: 0.10916537 | I37: 0.11058085 | J37: 0.10711067 | K37: 0.11422974 | L37: 0.11070734 | M37: 0.10696944 | N37: 0.12019109 | O37: 0.11797508 | P37: 0.10114996 | Q37: 0.12005295 | R37: 0.11602286 | S37: 0.10937261 | T37: 0.095595283 | U37: 0.1017319 | V37: 0.1172092 | W37: 0.12599186 | X37: 0.10853695 | Y37: 0.11976852
B38: First decile | C38: 0.13105102 | D38: 0.13698956 | E38: 0.13011667 | F38: 0.13693481 | G38: 0.13360093 | H38: 0.13461337 | I38: 0.13427735 | J38: 0.13524367 | K38: 0.14056741 | L38: 0.15417242 | M38: 0.15799993 | N38: 0.15468788 | O38: 0.16119991 | P38: 0.17088535 | Q38: 0.18532887 | R38: 0.18258784 | S38: 0.19426934 | T38: 0.20687386 | U38: 0.21531428 | V38: 0.21661956 | W38: 0.21537316 | X38: 0.23746557 | Y38: 0.23721717
B39: Last decile | C39: 0.34428095 | D39: 0.31567568 | E39: 0.29360026 | F39: 0.34431153 | G39: 0.31802613 | H39: 0.34693575 | I39: 0.34687128 | J39: 0.34850008 | K39: 0.34668251 | L39: 0.36342063 | M39: 0.35760088 | N39: 0.37448153 | O39: 0.38620823 | P39: 0.36886005 | Q39: 0.4073199 | R39: 0.40782411 | S39: 0.42155096 | T39: 0.40052578 | U39: 0.44216073 | V39: 0.42750207 | W39: 0.43710045 | X39: 0.4433775 | Y39: 0.4465836
B40: Decile range | C40: 0.21322993 | D40: 0.17868612 | E40: 0.16348359 | F40: 0.20737672 | G40: 0.1844252 | H40: 0.21232238 | I40: 0.21259394 | J40: 0.2132564 | K40: 0.2061151 | L40: 0.20924821 | M40: 0.19960094 | N40: 0.21979365 | O40: 0.22500832 | P40: 0.1979747 | Q40: 0.22199102 | R40: 0.22523627 | S40: 0.22728162 | T40: 0.19365192 | U40: 0.22684644 | V40: 0.2108825 | W40: 0.22172729 | X40: 0.20591193 | Y40: 0.20936643
B41: Reset | C41: -0.34428095 | D41: -0.31567568 | E41: -0.29360026 | F41: -0.34431153 | G41: -0.31802613 | H41: -0.34693575 | I41: -0.34687128 | J41: -0.34850008 | K41: -0.34668251 | L41: -0.36342063 | M41: -0.35760088 | N41: -0.37448153 | O41: -0.38620823 | P41: -0.36886005 | Q41: -0.4073199 | R41: -0.40782411 | S41: -0.42155096 | T41: -0.40052578 | U41: -0.44216073 | V41: -0.42750207 | W41: -0.43710045 | X41: -0.4433775 | Y41: -0.4465836

Sheet Turbine Size, Offshore wind
F1: Turbine size, offshore wind
A3: Dataset | B3: Turbine size, offshore wind
A4: Units | B4: MW
A5: Source | B5: BloombergNEF
A6: Subject to terms and conditions
B36: Statistics on offshore wind turbine size, global
B37: MW | C37: 2002 | F37: 05 | K37: 2010 | M37: 12 | O37: 14 | Q37: 16 | S37: 18 | V37: 21
B38: Closing year | C38: 2002 | D38: 2003 | E38: 2004 | F38: 2005 | G38: 2006 | H38: 2007 | I38: 2008 | J38: 2009 | K38: 2010 | L38: 2011 | M38: 2012 | N38: 2013 | O38: 2014 | P38: 2015 | Q38: 2016 | R38: 2017 | S38: 2018 | T38: 2019 | U38: 2020 | V38: 2021
B39: Min | C39: 2 | D39: 2 | E39: 3 | F39: 3 | G39: 2.2916667 | H39: 2.2967033 | I39: 2.3 | J39: 2.3 | K39: 3.6 | L39: 1.5 | M39: 1.5 | N39: 1.6 | O39: 3 | P39: 3.4482759 | Q39: 4 | R39: 6 | S39: 2 | T39: 3 | U39: 3.8461538 | V39: 4
B40: Quartile 1 | C40: =NA() -> #N/A | D40: =NA() -> #N/A | E40: =NA() -> #N/A | F40: =NA() -> #N/A | G40: 2.2916667 | H40: 3.6 | I40: 2.475 | J40: 2.825 | K40: 3.6 | L40: 2.625 | M40: 2.625 | N40: 2.3 | O40: 4 | P40: 6 | Q40: 6.25 | R40: 6.34375 | S40: 6.5 | T40: 4.1115385 | U40: 4.140625 | V40: 7
B41: Average | C41: 2 | D41: 2 | E41: 3 | F41: 3.3 | G41: 2.6458333 | H41: 3.6138148 | I41: 3.825 | J41: 3.5166667 | K41: 4.4486111 | L41: 3.525 | M41: 3 | N41: 3.9866667 | O41: 5.5555556 | P41: 6.1069552 | Q41: 6.9853896 | R41: 7.3961118 | S41: 7.8978205 | T41: 6.228022 | U41: 7.4255655 | V41: 9.7142857
B42: Median | C42: 2 | D42: 2 | E42: 3 | F42: 3.3 | G42: 2.6458333 | H42: 3.6 | I42: 4 | J42: 3.6 | K42: 3.6 | L42: 3.6 | M42: 3 | N42: 3.3333333 | O42: 6 | P42: 6 | Q42: 7 | R42: 8 | S42: 8.4 | T42: 7 | U42: 7.5 | V42: 9.5
B43: Quartile 3 | C43: =NA() -> #N/A | D43: =NA() -> #N/A | E43: =NA() -> #N/A | F43: =NA() -> #N/A | G43: 3 | H43: 3.6 | I43: 5 | J43: 3.95 | K43: 6.1458333 | L43: 3.9 | M43: 3.9 | N43: 6 | O43: 7 | P43: 6.4053191 | Q43: 8.2964286 | R43: 8.1290323 | S43: 9.5 | T43: 8 | U43: 10.243902 | V43: 13
B44: Max | C44: 2 | D44: 2 | E44: 3 | F44: 3.6 | G44: 3 | H44: 5 | I44: 5 | J44: 5 | K44: 6.1458333 | L44: 6 | M44: 6 | N44: 6 | O44: 8 | P44: 8.25 | Q44: 8.4727273 | R44: 8.3 | S44: 9.5555556 | T44: 9.5 | U44: 13 | V44: 14
B45: Quartiles | C45: =NA() -> #N/A | D45: =NA() -> #N/A | E45: =NA() -> #N/A | F45: =NA() -> #N/A | G45: 0.70833333 | H45: 0 | I45: 2.525 | J45: 1.125 | K45: 2.5458333 | L45: 1.275 | M45: 1.275 | N45: 3.7 | O45: 3 | P45: 0.40531915 | Q45: 2.0464286 | R45: 1.7852823 | S45: 3 | T45: 3.8884615 | U45: 6.1032774 | V45: 6
